Workbook

Sheet Summary
A1: Distribution of Non-institution-based/Free-standing Ambulance Service Provider in the Philippines (as of June 30, 2026)
A2: REGION | B2: GOVERNMENT | F2: Number of ASP | G2: PRIVATE | K2: Nunber of ASP | L2: Total Number of Units | M2: Total Number of ASP
B4: Type I | C4: Type II | D4: Type I and II | E4: Number of Units | G4: Type I | H4: Type II | I4: Type I and II | J4: Number of Units
A5: NCR | B5: =SUMIFS(Government!J:J,Government!C:C, "NCR",Government!K:K, "Type I") -> 4 | C5: =SUMIFS(Government!J:J,Government!C:C, "NCR",Government!K:K, "Type II") -> 2 | D5: =SUMIFS(Government!J:J,Government!C:C, "NCR",Government!K:K, "Type I & II") -> 0 | E5: =SUMIFS(Government!J:J,Government!C:C, "NCR") -> 6 | F5: =countifs(Government!C:C,"NCR") -> 5 | G5: =SUMIFS(Private!J:J,Private!C:C, "NCR",Private!K:K, "Type I") -> 16 | H5: =SUMIFS(Private!J:J,Private!C:C, "NCR",Private!K:K, "Type II") -> 42 | I5: =SUMIFS(Private!J:J,Private!C:C, "NCR",Private!K:K, "Type I & II") -> 0 | J5: =SUMIFS(Private!J:J,Private!C:C, "NCR") -> 58 | K5: =countifs(Private!C:C,"NCR") -> 26 | L5: =sum(E5,J5) -> 64 | M5: =sum(F5,K5) -> 31
A6: ILOCOS REGION | B6: =SUMIFS(Government!J:J,Government!C:C, "Region 1",Government!K:K, "Type I") -> 15 | C6: =SUMIFS(Government!J:J,Government!C:C, "Region 1",Government!K:K, "Type II") -> 0 | D6: =SUMIFS(Government!J:J,Government!C:C, "Region 1",Government!K:K, "Type I & II") -> 0 | E6: =SUMIFS(Government!J:J,Government!C:C, "Region 1") -> 15 | F6: =countifs(Government!C:C,"Region 1") -> 8 | G6: =SUMIFS(Private!J:J,Private!C:C, "Region 1",Private!K:K, "Type I") -> 0 | H6: =SUMIFS(Private!J:J,Private!C:C, "Region 1",Private!K:K, "Type II") -> 0 | I6: =SUMIFS(Private!J:J,Private!C:C, "Region 1",Private!K:K, "Type I & II") -> 0 | J6: =SUMIFS(Private!J:J,Private!C:C, "Region 1") -> 0 | K6: =countifs(Private!C:C,"Region 1") -> 0 | L6: =sum(E6,J6) -> 15 | M6: =sum(F6,K6) -> 8
A7: CAGAYAN VALLEY | B7: =SUMIFS(Government!J:J,Government!C:C, "Region 2",Government!K:K, "Type I") -> 11 | C7: =SUMIFS(Government!J:J,Government!C:C, "Region 2",Government!K:K, "Type II") -> 0 | D7: =SUMIFS(Government!J:J,Government!C:C, "Region 2",Government!K:K, "Type I & II") -> 0 | E7: =SUMIFS(Government!J:J,Government!C:C, "Region 2") -> 11 | F7: =countifs(Government!C:C,"Region 2") -> 7 | G7: =SUMIFS(Private!J:J,Private!C:C, "Region 2",Private!K:K, "Type I") -> 0 | H7: =SUMIFS(Private!J:J,Private!C:C, "Region 2",Private!K:K, "Type II") -> 0 | I7: =SUMIFS(Private!J:J,Private!C:C, "Region 2",Private!K:K, "Type I & II") -> 0 | J7: =SUMIFS(Private!J:J,Private!C:C, "Region 2") -> 0 | K7: =countifs(Private!C:C,"Region 2") -> 0 | L7: =sum(E7,J7) -> 11 | M7: =sum(F7,K7) -> 7
A8: CENTRAL LUZON | B8: =SUMIFS(Government!J:J,Government!C:C, "Region 3",Government!K:K, "Type I") -> 19 | C8: =SUMIFS(Government!J:J,Government!C:C, "Region 3",Government!K:K, "Type II") -> 0 | D8: =SUMIFS(Government!J:J,Government!C:C, "Region 3",Government!K:K, "Type I & II") -> 0 | E8: =SUMIFS(Government!J:J,Government!C:C, "Region 3") -> 19 | F8: =countifs(Government!C:C,"Region 3") -> 12 | G8: =SUMIFS(Private!J:J,Private!C:C, "Region 3",Private!K:K, "Type I") -> 9 | H8: =SUMIFS(Private!J:J,Private!C:C, "Region 3",Private!K:K, "Type II") -> 1 | I8: =SUMIFS(Private!J:J,Private!C:C, "Region 3",Private!K:K, "Type I & II") -> 0 | J8: =SUMIFS(Private!J:J,Private!C:C, "Region 3") -> 10 | K8: =countifs(Private!C:C,"Region 3") -> 7 | L8: =sum(E8,J8) -> 29 | M8: =sum(F8,K8) -> 19
A9: CALABARZON | B9: =SUMIFS(Government!J:J,Government!C:C, "Region 4-A",Government!K:K, "Type I") -> 0 | C9: =SUMIFS(Government!J:J,Government!C:C, "Region 4-A",Government!K:K, "Type II") -> 0 | D9: =SUMIFS(Government!J:J,Government!C:C, "Region 4-A",Government!K:K, "Type I & II") -> 0 | E9: =SUMIFS(Government!J:J,Government!C:C, "Region 4-A") -> 0 | F9: =countifs(Government!C:C,"Region 4-A") -> 0 | G9: =SUMIFS(Private!J:J,Private!C:C, "Region 4-A",Private!K:K, "Type I") -> 3 | H9: =SUMIFS(Private!J:J,Private!C:C, "Region 4-A",Private!K:K, "Type II") -> 4 | I9: =SUMIFS(Private!J:J,Private!C:C, "Region 4-A",Private!K:K, "Type I & II") -> 0 | J9: =SUMIFS(Private!J:J,Private!C:C, "Region 4-A") -> 7 | K9: =countifs(Private!C:C,"Region 4-A") -> 6 | L9: =sum(E9,J9) -> 7 | M9: =sum(F9,K9) -> 6
A10: MIMAROPA | B10: =SUMIFS(Government!J:J,Government!C:C, "Region 4-B",Government!K:K, "Type I") -> 0 | C10: =SUMIFS(Government!J:J,Government!C:C, "Region 4-B",Government!K:K, "Type II") -> 0 | D10: =SUMIFS(Government!J:J,Government!C:C, "Region 4-B",Government!K:K, "Type I & II") -> 0 | E10: =SUMIFS(Government!J:J,Government!C:C, "Region 4-B") -> 0 | F10: =countifs(Government!C:C,"Region 4-B") -> 0 | G10: =SUMIFS(Private!J:J,Private!C:C, "Region 4-B",Private!K:K, "Type I") -> 0 | H10: =SUMIFS(Private!J:J,Private!C:C, "Region 4-B",Private!K:K, "Type II") -> 0 | I10: =SUMIFS(Private!J:J,Private!C:C, "Region 4-B",Private!K:K, "Type I & II") -> 0 | J10: =SUMIFS(Private!J:J,Private!C:C, "Region 4-B") -> 0 | K10: =countifs(Private!C:C,"Region IV-B") -> 0 | L10: =sum(E10,J10) -> 0 | M10: =sum(F10,K10) -> 0
A11: BICOL REGION | B11: =SUMIFS(Government!J:J,Government!C:C, "Region 5",Government!K:K, "Type I") -> 4 | C11: =SUMIFS(Government!J:J,Government!C:C, "Region 5",Government!K:K, "Type II") -> 0 | D11: =SUMIFS(Government!J:J,Government!C:C, "Region 5",Government!K:K, "Type I & II") -> 0 | E11: =SUMIFS(Government!J:J,Government!C:C, "Region 5") -> 4 | F11: =countifs(Government!C:C,"Region 5") -> 2 | G11: =SUMIFS(Private!J:J,Private!C:C, "Region 5",Private!K:K, "Type I") -> 1 | H11: =SUMIFS(Private!J:J,Private!C:C, "Region 5",Private!K:K, "Type II") -> 0 | I11: =SUMIFS(Private!J:J,Private!C:C, "Region 5",Private!K:K, "Type I & II") -> 0 | J11: =SUMIFS(Private!J:J,Private!C:C, "Region 5") -> 1 | K11: =countifs(Private!C:C,"Region 5") -> 1 | L11: =sum(E11,J11) -> 5 | M11: =sum(F11,K11) -> 3
A12: WESTERN VISAYAS | B12: =SUMIFS(Government!J:J,Government!C:C, "Region 6",Government!K:K, "Type I") -> 0 | C12: =SUMIFS(Government!J:J,Government!C:C, "Region 6",Government!K:K, "Type II") -> 0 | D12: =SUMIFS(Government!J:J,Government!C:C, "Region 6",Government!K:K, "Type I & II") -> 0 | E12: =SUMIFS(Government!J:J,Government!C:C, "Region 6") -> 0 | F12: =countifs(Government!C:C,"Region 6") -> 0 | G12: =SUMIFS(Private!J:J,Private!C:C, "Region 6",Private!K:K, "Type I") -> 2 | H12: =SUMIFS(Private!J:J,Private!C:C, "Region 6",Private!K:K, "Type II") -> 0 | I12: =SUMIFS(Private!J:J,Private!C:C, "Region 6",Private!K:K, "Type I & II") -> 0 | J12: =SUMIFS(Private!J:J,Private!C:C, "Region 6") -> 2 | K12: =countifs(Private!C:C,"Region 6") -> 2 | L12: =sum(E12,J12) -> 2 | M12: =sum(F12,K12) -> 2
A13: CENTRAL VISAYAS | B13: =SUMIFS(Government!J:J,Government!C:C, "Region 7",Government!K:K, "Type I") -> 1 | C13: =SUMIFS(Government!J:J,Government!C:C, "Region 7",Government!K:K, "Type II") -> 0 | D13: =SUMIFS(Government!J:J,Government!C:C, "Region 7",Government!K:K, "Type I & II") -> 0 | E13: =SUMIFS(Government!J:J,Government!C:C, "Region 7") -> 1 | F13: =countifs(Government!C:C,"Region 7") -> 1 | G13: =SUMIFS(Private!J:J,Private!C:C, "Region 7",Private!K:K, "Type I") -> 0 | H13: =SUMIFS(Private!J:J,Private!C:C, "Region 7",Private!K:K, "Type II") -> 4 | I13: =SUMIFS(Private!J:J,Private!C:C, "Region 7",Private!K:K, "Type I & II") -> 0 | J13: =SUMIFS(Private!J:J,Private!C:C, "Region 7") -> 4 | K13: =countifs(Private!C:C,"Region 7") -> 1 | L13: =sum(E13,J13) -> 5 | M13: =sum(F13,K13) -> 2
A14: EASTERN VISAYAS | B14: =SUMIFS(Government!J:J,Government!C:C, "Region 8",Government!K:K, "Type I") -> 15 | C14: =SUMIFS(Government!J:J,Government!C:C, "Region 8",Government!K:K, "Type II") -> 0 | D14: =SUMIFS(Government!J:J,Government!C:C, "Region 8",Government!K:K, "Type I & II") -> 0 | E14: =SUMIFS(Government!J:J,Government!C:C, "Region 8") -> 15 | F14: =countifs(Government!C:C,"Region 8") -> 14 | G14: =SUMIFS(Private!J:J,Private!C:C, "Region 8",Private!K:K, "Type I") -> 0 | H14: =SUMIFS(Private!J:J,Private!C:C, "Region 8",Private!K:K, "Type II") -> 0 | I14: =SUMIFS(Private!J:J,Private!C:C, "Region 8",Private!K:K, "Type I & II") -> 0 | J14: =SUMIFS(Private!J:J,Private!C:C, "Region 8") -> 0 | K14: =countifs(Private!C:C,"Region 8") -> 0 | L14: =sum(E14,J14) -> 15 | M14: =sum(F14,K14) -> 14
A15: ZAMBOANGA PENINSULA | B15: =SUMIFS(Government!J:J,Government!C:C, "Region 9",Government!K:K, "Type I") -> 6 | C15: =SUMIFS(Government!J:J,Government!C:C, "Region 9",Government!K:K, "Type II") -> 0 | D15: =SUMIFS(Government!J:J,Government!C:C, "Region 9",Government!K:K, "Type I & II") -> 0 | E15: =SUMIFS(Government!J:J,Government!C:C, "Region 9") -> 6 | F15: =countifs(Government!C:C,"Region 9") -> 5 | G15: =SUMIFS(Private!J:J,Private!C:C, "Region 9",Private!K:K, "Type I") -> 2 | H15: =SUMIFS(Private!J:J,Private!C:C, "Region 9",Private!K:K, "Type II") -> 0 | I15: =SUMIFS(Private!J:J,Private!C:C, "Region 9",Private!K:K, "Type I & II") -> 0 | J15: =SUMIFS(Private!J:J,Private!C:C, "Region 9") -> 2 | K15: =countifs(Private!C:C,"Region 9") -> 1 | L15: =sum(E15,J15) -> 8 | M15: =sum(F15,K15) -> 6
A16: NORTHERN MINDANAO | B16: =SUMIFS(Government!J:J,Government!C:C, "Region 10",Government!K:K, "Type I") -> 7 | C16: =SUMIFS(Government!J:J,Government!C:C, "Region 10",Government!K:K, "Type II") -> 0 | D16: =SUMIFS(Government!J:J,Government!C:C, "Region 10",Government!K:K, "Type I & II") -> 0 | E16: =SUMIFS(Government!J:J,Government!C:C, "Region 10") -> 7 | F16: =countifs(Government!C:C,"Region 10") -> 7 | G16: =SUMIFS(Private!J:J,Private!C:C, "Region 10",Private!K:K, "Type I") -> 1 | H16: =SUMIFS(Private!J:J,Private!C:C, "Region 10",Private!K:K, "Type II") -> 0 | I16: =SUMIFS(Private!J:J,Private!C:C, "Region 10",Private!K:K, "Type I & II") -> 0 | J16: =SUMIFS(Private!J:J,Private!C:C, "Region 10") -> 1 | K16: =countifs(Private!C:C,"Region 10") -> 1 | L16: =sum(E16,J16) -> 8 | M16: =sum(F16,K16) -> 8
A17: DAVAO | B17: =SUMIFS(Government!J:J,Government!C:C, "Region 11",Government!K:K, "Type I") -> 57 | C17: =SUMIFS(Government!J:J,Government!C:C, "Region 11",Government!K:K, "Type II") -> 0 | D17: =SUMIFS(Government!J:J,Government!C:C, "Region 11",Government!K:K, "Type I & II") -> 0 | E17: =SUMIFS(Government!J:J,Government!C:C, "Region 11") -> 57 | F17: =countifs(Government!C:C,"Region 11") -> 8 | G17: =SUMIFS(Private!J:J,Private!C:C, "Region 11",Private!K:K, "Type I") -> 2 | H17: =SUMIFS(Private!J:J,Private!C:C, "Region 11",Private!K:K, "Type II") -> 1 | I17: =SUMIFS(Private!J:J,Private!C:C, "Region 11",Private!K:K, "Type I & II") -> 0 | J17: =SUMIFS(Private!J:J,Private!C:C, "Region 11") -> 3 | K17: =countifs(Private!C:C,"Region 11") -> 3 | L17: =sum(E17,J17) -> 60 | M17: =sum(F17,K17) -> 11
A18: SOCCSKSARGEN | B18: =SUMIFS(Government!J:J,Government!C:C, "Region 12",Government!K:K, "Type I") -> 1 | C18: =SUMIFS(Government!J:J,Government!C:C, "Region 12",Government!K:K, "Type II") -> 0 | D18: =SUMIFS(Government!J:J,Government!C:C, "Region 12",Government!K:K, "Type I & II") -> 0 | E18: =SUMIFS(Government!J:J,Government!C:C, "Region 12") -> 1 | F18: =countifs(Government!C:C,"Region 12") -> 1 | G18: =SUMIFS(Private!J:J,Private!C:C, "Region 12",Private!K:K, "Type I") -> 1 | H18: =SUMIFS(Private!J:J,Private!C:C, "Region 12",Private!K:K, "Type II") -> 0 | I18: =SUMIFS(Private!J:J,Private!C:C, "Region 12",Private!K:K, "Type I & II") -> 0 | J18: =SUMIFS(Private!J:J,Private!C:C, "Region 12") -> 1 | K18: =countifs(Private!C:C,"Region 12") -> 1 | L18: =sum(E18,J18) -> 2 | M18: =sum(F18,K18) -> 2
A19: CARAGA | B19: =SUMIFS(Government!J:J,Government!C:C, "Region 13",Government!K:K, "Type I") -> 11 | C19: =SUMIFS(Government!J:J,Government!C:C, "Region 13",Government!K:K, "Type II") -> 0 | D19: =SUMIFS(Government!J:J,Government!C:C, "Region 13",Government!K:K, "Type I & II") -> 0 | E19: =SUMIFS(Government!J:J,Government!C:C, "Region 13") -> 11 | F19: =countifs(Government!C:C,"Region 13") -> 6 | G19: =SUMIFS(Private!J:J,Private!C:C, "Region 13",Private!K:K, "Type I") -> 0 | H19: =SUMIFS(Private!J:J,Private!C:C, "Region 13",Private!K:K, "Type II") -> 0 | I19: =SUMIFS(Private!J:J,Private!C:C, "Region 13",Private!K:K, "Type I & II") -> 0 | J19: =SUMIFS(Private!J:J,Private!C:C, "Region 13") -> 0 | K19: =countifs(Private!C:C,"Region 13") -> 0 | L19: =sum(E19,J19) -> 11 | M19: =sum(F19,K19) -> 6
A20: CAR | B20: =SUMIFS(Government!J:J,Government!C:C, "Cordillera",Government!K:K, "Type I") -> 4 | C20: =SUMIFS(Government!J:J,Government!C:C, "Cordillera",Government!K:K, "Type II") -> 0 | D20: =SUMIFS(Government!J:J,Government!C:C, "Cordillera",Government!K:K, "Type I & II") -> 0 | E20: =SUMIFS(Government!J:J,Government!C:C, "Cordillera") -> 4 | F20: =countifs(Government!C:C,"Cordillera") -> 4 | G20: =SUMIFS(Private!J:J,Private!C:C, "Cordillera",Private!K:K, "Type I") -> 2 | H20: =SUMIFS(Private!J:J,Private!C:C, "Cordillera",Private!K:K, "Type II") -> 5 | I20: =SUMIFS(Private!J:J,Private!C:C, "Cordillera",Private!K:K, "Type I & II") -> 0 | J20: =SUMIFS(Private!J:J,Private!C:C, "Cordillera") -> 7 | K20: =countifs(Private!C:C,"Cordillera") -> 6 | L20: =sum(E20,J20) -> 11 | M20: =sum(F20,K20) -> 10
A21: NIR | B21: =SUMIFS(Government!J:J,Government!C:C, "NIR",Government!K:K, "Type I") -> 1 | C21: =SUMIFS(Government!J:J,Government!C:C, "NIR",Government!K:K, "Type II") -> 0 | D21: =SUMIFS(Government!J:J,Government!C:C, "NIR",Government!K:K, "Type I & II") -> 0 | E21: =SUMIFS(Government!J:J,Government!C:C, "NIR") -> 1 | F21: =countifs(Government!C:C,"NIR") -> 1 | G21: =SUMIFS(Private!J:J,Private!C:C, "NIR",Private!K:K, "Type I") -> 0 | H21: =SUMIFS(Private!J:J,Private!C:C, "NIR",Private!K:K, "Type II") -> 0 | I21: =SUMIFS(Private!J:J,Private!C:C, "NIR",Private!K:K, "Type I & II") -> 0 | J21: =SUMIFS(Private!J:J,Private!C:C, "NIR") -> 0 | K21: =countifs(Private!C:C,"NIR") -> 0 | L21: =sum(E21,J21) -> 1 | M21: =sum(F21,K21) -> 1
A22: BARMM | B22: =SUMIFS(Government!J:J,Government!C:C, "BARMM",Government!K:K, "Type I") -> 0 | C22: =SUMIFS(Government!J:J,Government!C:C, "BARMM",Government!K:K, "Type II") -> 0 | D22: =SUMIFS(Government!J:J,Government!C:C, "BARMM",Government!K:K, "Type I & II") -> 0 | E22: =SUMIFS(Government!J:J,Government!C:C, "BARMM") -> 0 | F22: =countifs(Government!C:C,"BARMM") -> 0 | G22: =SUMIFS(Private!J:J,Private!C:C, "BARMM",Private!K:K, "Type I") -> 0 | H22: =SUMIFS(Private!J:J,Private!C:C, "BARMM",Private!K:K, "Type II") -> 0 | I22: =SUMIFS(Private!J:J,Private!C:C, "BARMM",Private!K:K, "Type I & II") -> 0 | J22: =SUMIFS(Private!J:J,Private!C:C, "BARMM") -> 0 | K22: =countifs(Private!C:C,"BARMM") -> 0 | L22: =sum(E22,J22) -> 0 | M22: =sum(F22,K22) -> 0
A23: Total Number Ambulance and Ambulance Service Providers | B23: =sum(B5:B22) -> 156 | C23: =sum(C5:C22) -> 2 | D23: =sum(D5:D22) -> 0 | E23: =sum(E5:E22) -> 158 | F23: =sum(F5:F22) -> 81 | G23: =sum(G5:G22) -> 39 | H23: =sum(H5:H22) -> 57 | I23: =sum(I5:I22) -> 0 | ... M23: =sum(M5:M22) -> 136

Sheet Government
A1: # | B1: NHFR CODE | C1: REGION | D1: PROVINCE | E1: CITY/ MUNICIPALITY | F1: BLDG OR HOUSE NO., STREET, BRGY (as applicable) | G1: NAME OF AMBULANCE SERVICE PROVIDER | H1: OWNERSHIP | I1: OWNER/ HEAD OF FACILITY | J1: NO. OF UNITS | K1: TYPE | L1: PLATE NO./ CONDUCTION STICKER | M1: CONTACT NOS. | N1: EMAIL ADDRESS | O1: VALIDITY FROM | P1: VALIDITY UNTIL | Q1: LICENSED NO. | R1: APPLICATION STATUS | S1: APPLICATION STATUS (IF WITH CHANGES) | T1: REMARKS | U1: Reference used by DMU
A2: 1 | C2: REGION 1 | D2: Ilocos Norte | E2: Adams | F2: Poblacion I | G2: ADAMS RURAL HEALTH UNIT | H2: Government | I2: Local Government Unit of Adams | J2: 2 | K2: Type I | L2: JN 255 A JN 342 A | O2: 45730 | P2: 46752 | Q2: 02-03-2527-ASP- 1 | R2: Still Accredited | U2: *
A3: 2 | B3: 48584 | C3: REGION 1 | D3: Ilocos Norte | E3: Bacarra | F3: Rizal Boulevard St., Brgy. 1 Sta. Rita | G3: BACARRA MUNICIPAL HEALTH OFFICE | H3: Government | I3: Bacarra Municipal Health Office | J3: 1 | K3: Type I | L3: NAO 4264 | M3: 0929-794-1241 | N3: bacarrarhu@gmail.com | O3: 45639 | P3: 46387 | Q3: 02-03-2426-ASP-1 | R3: Still Accredited | U3: *
A4: 3 | B4: 48582 | C4: REGION 1 | D4: Ilocos Norte | E4: Dumalneg | F4: J. Raval St., Cabaritan, District I | G4: DUMALNEG MUNICIPAL HEALTH OFFICE | H4: Government | I4: DUMALNEG MUNICIPAL HEALTH OFFICE | J4: 1 | K4: Type I | L4: F0 N939 | M4: (077) 670-7405 | N4: dumalneg_rhu2014@yahoo.com | O4: 45292 | P4: 46387 | Q4: 02-02-2527-ASP-2 | R4: Still Accredited | U4: *
A5: 4 | B5: 48583 | C5: REGION 1 | D5: Ilocos Norte | E5: Vintar | F5: Gomez St., San Nicolas (Pob.) | G5: VINTAR MUNICIPAL HEALTH OFFICE | H5: Government | I5: Local Government Unit of Vintar | J5: 1 | K5: Type I | L5: A2 A223 | M5: (077) 670 5274 | N5: municipalityofvintar@gmail.com | O5: 45625 | P5: 46387 | Q5: 02-01-2527-ASP-1 | R5: Still Accredited
A6: 5 | B6: 50621 | C6: REGION 1 | D6: Ilocos Sur | E6: San Juan City | F6: Taft St., Brgy. Lira, San | G6: SAN JUAN RURAL HEALTH UNIT | H6: Government | I6: Municipality of San Juan, Ilocos Sur | J6: 1 | K6: Type I | L6: I30 109 | O6: 45386 | P6: 46387 | Q6: 02-01-2628-ASP-1 | R6: Renewal
A7: 6 | B7: 48641 | C7: REGION 1 | D7: La Union | E7: San Fernando City | F7: Quezon Avenue, Sevilla | G7: DEPARTMENT OF SOCIAL WELFARE AND DEVELOPMENT - FIELD OFFICE I | H7: Government | I7: DEPARTMENT OF SOCIAL WELFARE AND DEVELOPMENT - FIELD OFFICE I | J7: 5 | K7: Type I | L7: A9 0981, A9 M098, A9 S332, A9 Y132, A9 M083 | M7: (072) 687 8000 | N7: fo1@dswd.gov.ph | O7: 45642 | P7: 46387 | Q7: 03-0008-2527-ASP-1 | R7: Still Accredited | S7: N/A
A8: 7 | C8: REGION 1 | D8: Pangasinan | E8: Alaminos City | F8: Quezon Ave., Poblacion | G8: CITY GOVERNMENT OF ALAMINOS (CDRRMO) | H8: Government | I8: Local Government Unit of Alaminos City | J8: 1 | K8: Type I | L8: SHR 992 | O8: 45810 | P8: 46752 | Q8: 03-0001-2527-ASP-1 | R8: Still Accredited | S8: N/A
A9: 8 | B9: 48645 | C9: REGION 1 | D9: Pangasinan | E9: Bayambang | F9: Brgy. Roxas St., Zone II | G9: LOCAL GOVERNMENT UNIT OF BAYAMBANG | H9: Government | I9: Local Government Unit of Bayambang | J9: 3 | K9: Type I | L9: SNA 9118 SNN 1990 FAA 215 | M9: (075) 632-12-19 | N9: posobayambang2016@yahoo.com | O9: 45376 | P9: 46752 | Q9: DOH051440 | R9: Still Accredited | S9: N/A
A10: 9 | C10: REGION 2 | D10: Cagayan | E10: Aparri | F10: Zone 1, Backling | G10: APARRI WEST SUPER HEALTH CENTER | H10: Government | I10: LGU | J10: 1 | K10: Type I | L10: SNA 9428 | M10: 9976508245 | N10: aparriwest_mho@yahoo.com | O10: 45834 | P10: 46752 | Q10: 08-011-2527-ASP-1 | R10: New Faciliy | U10: *
A11: 10 | C11: REGION 2 | D11: Cagayan | E11: Buguey | F11: Buguey Fire Station, Centro | G11: LGU -BUGUEY AMBULANCE | H11: Government | I11: LGU | J11: 1 | K11: Type I | L11: SAB 6386 | M11: 9532349544 | N11: lgubuguey@ymail.com | O11: 45519 | P11: 46387 | Q11: 08-002-2426-ASP-1 | R11: New Faciliy | U11: *
A12: 11 | C12: REGION 2 | D12: Nueva Vizcaya | E12: Bagabag | F12: San Pedro | G12: BAGABAG- RURAL HEALTH UNIT | H12: Government | I12: LGU | J12: 1 | K12: Type I | L12: SNA 9490 | M12: 9177931779 | N12: rhubagabag@gmail.com | O12: 45740 | P12: 46752 | Q12: DOH051668 | R12: New Faciliy
A13: 12 | C13: REGION 2 | D13: Nueva Vizcaya | E13: Bambang | F13: Boyie Street, Buag | G13: RURAL HEALTH UNIT OF BAMBANG | H13: Government | I13: LGU | J13: 3 | K13: Type I | L13: SND 3325; SND 3302; SNA 9434 | M13: 9561703191 | N13: mhobambang.nv@gmail.com | O13: 45566 | P13: 46387 | Q13: 08-012-2527-ASP-1 | R13: New Faciliy
A14: 13 | C14: REGION 2 | D14: Nueva Vizcaya | E14: Bayombong | F14: Capitol Compound, District IV | G14: PHILLIPINE RED CROSS- NUEVA VIZCAYA CHAPTER | H14: Government | I14: PRC Nueva Vizcaya Chapter | J14: 1 | K14: Type I | L14: AKA 4168 | M14: 9175079950 | N14: nueva.vizcaya@redcross.org.ph> | O14: 45728 | P14: 46752 | Q14: 09-0001-25-27-ASP-1 | R14: Still Accredited
A15: 14 | C15: REGION 2 | D15: Quirino | E15: Cabarroguis | F15: Poblacion, Mangandingay | G15: PROVINCIAL GOVERNMENT OF QUIRINO/ PROVINCIAL HEALTH OFFICE | H15: Government | I15: Province | J15: 1 | K15: Type I | L15: SND 3293 | M15: 9065739694 | N15: rhubagabag@gmail.com | O15: 45658 | P15: 46752 | Q15: 09-0002-24-26-ASP-1 | R15: Still Accredited
A16: 15 | C16: REGION 2 | D16: Quirino | E16: Diffun | F16: #6 Doña Street, Andres Bonifacio | G16: DIFFUN MUNICIPAL HEALTH OFFICE AND REPRODUCTIVE HEALTH CLINIC | H16: Government | I16: LGU | J16: 3 | K16: Type I | L16: F5K 722, SNN 2215, SNA 9468 | M16: 9171031401 | N16: mho_diffun@yahoo.com.ph | O16: 46023 | P16: 47118 | Q16: 09-0002-25-27-ASP-1 | R16: Still Accredited
A17: 16 | C17: REGION 3 | D17: Bataan | E17: Bagac | F17: Atilano Ricardo, Bagac, Bataan | G17: MUNICIPAL GOVERNMENT OF BAGAC, BATAAN | H17: Government | I17: LGU - Bagac, Bataan | J17: 2 | K17: Type I | L17: SND 3129 SND 3130 | M17: 0977-7979-300 | N17: rhubagac@gmail.com | O17: 45749 | P17: 46752 | Q17: 09-0001-26-28-ASP-1 | R17: Renewal
A18: 17 | B18: 48649 | C18: REGION 3 | D18: Bataan | E18: Limay | F18: Real St. , Poblacion, Limay, Bataan | G18: LIMAY RURAL HEALTH UNIT | H18: Government | I18: LGU - Limay, Bataan | J18: 3 | K18: Type I | L18: F4 J772 F2 G639 F2 G632 | M18: 0908-810-3361 | N18: nursemalou74@gmail.com | O18: 45658 | P18: 46752 | Q18: 09-0001-24-26-ASP-1 | R18: Still Accredited
A19: 18 | B19: 51440 | C19: REGION 3 | D19: Bulacan | E19: San Jose del Monte City | F19: CDRRMO Bldg., Sapang Palay Proper, City of San Jose Del Monte, Bulacan | G19: CITY DISASTER RISK REDUCTION AND MANAGEMENT OFFICE | H19: Government | I19: LGU - City of San Jose Del Monte, Bulacan | J19: 4 | K19: Type I | L19: F40064 F40078 F40068 F40103 | M19: 044-3066234/09326000119/09552067200/09328449461/09176384674 | N19: cs3.cdrrmo@gmail.com/franwaynesanpedro3@gmail.com | O19: 45481 | P19: 46387 | Q19: 10-0019-2426-ASP-1 | R19: New Faciliy
A20: 19 | B20: 50484 | C20: REGION 3 | D20: Nueva Ecija | E20: Bongabon | F20: Sinipit Poblacion, Bongabon, Nueva Ecija | G20: BONGABON MUNICIPAL HEALTH OFFICE | H20: Government | I20: LGU - Bongabon, Nueva Ecija | J20: 1 | K20: Type I | L20: F5 1241 | M20: 0915-764-2460 | N20: bongabonhrh@gmail.com | O20: 46023 | P20: 47118 | Q20: 10-0004-2527-ASP-1 | R20: New Faciliy | S20: N/A | T20: new facility in 2025
A21: 20 | B21: 50819 | C21: REGION 3 | D21: Nueva Ecija | E21: Cabanatuan City | F21: Kapitan Pepe, Cabanatuan City, Nueva Ecija | G21: CABANATUAN CITY HEALTH OFFICE | H21: Government | I21: LGU - Cabanatuan City, Nueva Ecija | J21: 1 | K21: Type I | L21: F4 D076 | M21: 9178511320 | N21: cho_cabanatuancity@yahoo.com | O21: 45406 | P21: 46387 | Q21: 10-0005-2527-ASP-1 | R21: New Faciliy | S21: N/A | T21: new facility in 2025
A22: 21 | B22: 50715 | C22: REGION 3 | D22: Nueva Ecija | E22: Lupao | F22: Neri St., Poblacion South, Lupao, Nueva Ecija | G22: LUPAO MUNICIPAL HEALTH CENTER | H22: Government | I22: LGU - Lupao, Nueva Ecija | J22: 1 | K22: Type I | L22: F4D 060 | M22: 0917-133-4856 | N22: lupaorhu88@gmail.com | O22: 45393 | P22: 46387 | Q22: 10-0001-2628-ASP-1 | R22: Renewal
A23: 22 | B23: 50687 | C23: REGION 3 | D23: Nueva Ecija | E23: San Isidro | F23: Plaza Santos, Poblacion, San Isidro, Nueva Ecija | G23: SAN ISIDRO MUNICIPAL HEALTH OFFICE | H23: Government | I23: LGU - San Isidro, Nueva Ecija | J23: 1 | K23: Type I | L23: F4D 052 | M23: 0966-422-9067 | N23: mhosanisidronuevaecija@gmail.com | O23: 45394 | P23: 46387 | Q23: 10-0002-2628-ASP-1 | R23: Renewal
A24: 23 | B24: 48653 | C24: REGION 3 | D24: Pampanga | E24: San Fernando City | F24: Heroes Hall, San Juan, City of San Fernando, Pampanga | G24: CITY HEALTH OFFICE - HEALTH EMERGENCY MANAGEMENT STAFF | H24: Government | I24: LGU - City of San Fernando, Pampanga | J24: 2 | K24: Type I | L24: F3R 357 QT 365A | M24: 0919-078-8456 | N24: citymedical2.hems2.csfp2@gmail.com | O24: 45980 | P24: 46752 | Q24: DOH053160 | R24: New Faciliy | S24: N/A | T24: new facility in 2025
A25: 24 | C25: REGION 3 | D25: Tarlac | E25: Concepcion | F25: Alpha, Balutu, Concepcion, Tarlac | G25: CONCEPCION RURAL HEALTH UNIT II | H25: Private | I25: LGU - Concepcion, Tarlac | J25: 1 | K25: Type I | L25: F4 D157 | M25: (045) 456-6365 | N25: rhu2balutu@yahoo.com | O25: 45658 | P25: 46752 | Q25: DOH051320 | R25: New Faciliy | S25: N/A | T25: new facility in 2024
A26: 25 | B26: 50778 | C26: REGION 3 | D26: Tarlac | E26: La Paz | F26: Caramutan, La Paz, Tarlac | G26: LA PAZ MUNICIPAL HEALTH OFFICE | H26: Government | I26: LGU - La Paz, Tarlac | J26: 1 | K26: Type I | L26: F5 J098 | M26: 0912-614-9866 | N26: lapazrhu12022@gmail.com | O26: 45378 | P26: 46387 | Q26: DOH048687 | R26: Renewal
A27: 26 | B27: 50770 | C27: REGION 3 | D27: Tarlac | E27: La Paz | F27: San Roque, La Paz, Tarlac | G27: LA PAZ RURAL HEALTH UNIT I | H27: Government | I27: LGU - La Paz, Tarlac | J27: 1 | K27: Type I | L27: F5 J082 | M27: 0912-614-9866 | N27: lapazrhu12022@gmail.com | O27: 45378 | P27: 46387 | Q27: 11-003-2426-ASP-1 | R27: New Faciliy
A28: 27 | B28: 48657 | C28: REGION 3 | D28: Tarlac | E28: Tarlac City | F28: Hilario St., Ligtasan, Tarlac City, Tarlac | G28: CITY HEALTH OFFICE TARLAC | H28: Government | I28: LGU - Tarlac City, Tarlac | J28: 1 | K28: Type I | L28: F4 D109 | M28: 045-491-8911 | N28: cho_tarlac@yahoo.com | O28: 45658 | P28: 46752 | Q28: 11-001-2527-ASP-1 | R28: New Faciliy
A29: 28 | B29: 54361 | C29: REGION 5 | D29: Albay | E29: Malilipot | F29: Brgy. 2, Poblacion, Malilipot, Albay | G29: LGU MALILIPOT | H29: Government | I29: Lgu Malilipot | J29: 1 | K29: Type I | L29: SND2810/0037345035 | M29: 9983213497 | N29: malilipotrhu@yahoo.com | O29: 45803 | P29: 46752 | Q29: 11-001-2527-ASP-1 | R29: New Faciliy
A30: 29 | B30: 48670 | C30: REGION 5 | D30: Camarines Sur | E30: Buhi | F30: Zone 5, San Buenaventura District 5, Buhi, Camarines Sur | G30: MUNICIPAL HEALTH OFFICE (BUHI-HEMS) | H30: Government | I30: Municipal Health Office (Buhi-HEMS) | J30: 3 | K30: Type I | L30: F3V 668 / F3V 678 / F3V 697 | M30: 0917-501-9705 | N30: buhirhu1@gmail.com | O30: 45292 | P30: 46387 | Q30: 11-001-2527-ASP-1 | R30: New Faciliy
A31: 30 | B31: 48679 | C31: REGION 7 | D31: Cebu | E31: Mandaue City | F31: Mezzanine Floor, FCB Building Corner P. Burgos Street and AC Cortes Avenue, Alang-Alang, Mandaue, Cebu | G31: CENTER FOR HEALTHCARE PROFESSIONS CEBU, INC. | H31: Government | I31: CENTER FOR HEALTHCARE PROFESSIONS CEBU, INC. | J31: 1 | K31: Type I | L31: GAU 7180 | M31: 0917-777-0851 / +63 (32) 420 1881 | N31: info@chpcebu.com | O31: 45292 | P31: 46387 | Q31: 11-001-2527-ASP-1 | R31: New Faciliy
A32: 31 | C32: REGION 8 | D32: Eastern Samar | E32: Oras | F32: Barangay Butnga, Oras, Eastern Samar | G32: ORAS RURAL HEALTH UNIT | H32: Government | I32: Local Government Unit of Oras | J32: 1 | K32: Type I | L32: SND 2749 | M32: 9475180799 | N32: orasrhu23@gmail.com | O32: 45639 | P32: 46387 | Q32: 11-001-2426-ASP-1 | R32: New Faciliy
A33: 32 | C33: REGION 8 | D33: Leyte | E33: MacArthur | F33: Taragona St., Barangay Poblacion, district 1, MacArthur, Leyte | G33: MACARTHUR RURAL HEALTH UNIT | H33: Government | I33: LGU MacArthur | J33: 1 | K33: Type I | L33: SND 2760 | M33: 9513668673 | N33: rhumacarthur17@gmail.com | O33: 46057 | P33: 47118 | Q33: 11-01-2527-PCF-1 | R33: Renewal
A34: 33 | C34: REGION 8 | D34: Leyte | E34: Mahaplag | F34: Barangay Poblacion, Mahaplag, Leyte | G34: RHU MAHAPLAG | H34: Government | I34: Local Government Unit of Mahaplag | J34: 1 | K34: Type I | L34: SND 2932 | M34: 9563947653 | N34: shcmahaplag@gmail.com | O34: 45771 | P34: 46752 | Q34: 12-001-2527-ASP-1 | R34: New Faciliy | S34: N/A | U34: *
A35: 34 | C35: REGION 8 | D35: Leyte | E35: Ormoc City | F35: Aunubing Street, Barangay Cogon, Ormoc City | G35: CITY HEALTH DEPARTMENT | H35: Government | I35: City Government of Ormoc | J35: 1 | K35: Type I | L35: SND 3510 | M35: 9209661466 | N35: chd.ormoc@yahoo.com | O35: 45730 | P35: 46752 | Q35: 16-002-25-ASP-1 | R35: New Faciliy | U35: *
A36: 35 | C36: REGION 8 | D36: Leyte | E36: Tacloban City | F36: Barangay 25, Kanhuraw Hill, Tacloban City | G36: TACLOBAN CITY HEALTH OFFICE | H36: Government | I36: City of Tacloban | J36: 1 | K36: Type I | L36: SND 2750 | M36: 9755885281 | N36: chotacloban2022@gmail.com | O36: 46111 | P36: 47118 | Q36: 16-004-25-ASP-1 | R36: New Faciliy | U36: *
A37: 36 | C37: REGION 8 | D37: Samar | E37: San Jose de Buan | F37: Barangay 3 Poblacion, San Jose de Buan, Samar | G37: SAN JOSE DE BUAN MUNICIPAL HEALTH OFFICE | H37: Government | I37: Local Government Unit of San Jose de Buan | J37: 1 | K37: Type I | L37: JR111A | M37: 9971737499 | N37: sanjosedebuanrhu@gmail.com | O37: 45785 | P37: 46752 | Q37: 16-003-25-ASP-1 | R37: New Faciliy | U37: *
A38: 37 | C38: REGION 8 | D38: Samar | E38: Santa Margarita | F38: Maharlika Highway, Barangay Monbon, Sta. Margairta, Samar | G38: RURAL HEALTH UNIT STA. MARGARITA | H38: Government | I38: Local Government Unit of Sta. Margairta | J38: 1 | K38: Type I | L38: F3V-658 | M38: 9970997686 | N38: rhusta.margaritasamar@gmail,.com | O38: 45729 | P38: 46752 | Q38: 16-002-25-ASP-1 | R38: Renewal | U38: *
A39: 38 | C39: REGION 8 | D39: Samar | E39: Talalora | F39: Santiago Street, Poblacion 1, Talalora, Samar | G39: RURAL HEALTH UNIT TALALORA | H39: Government | I39: Local Government Unit of Talalora | J39: 1 | K39: Type I | L39: F5T-597 | M39: 9361599611 | N39: health.talalora@gmail.com | O39: 45762 | P39: 46752 | Q39: 16-002 -24-ASP-1 | R39: Renewal | U39: *
A40: 39 | C40: REGION 8 | D40: Southern Leyte | E40: Anahawan | F40: Purok Sampaguita, Poblacion, Southern Leyte | G40: ANAHAWAN RURAL HEALTH UNIT & FAMILY PLANNING CENTER | H40: Government | I40: Local Government Unit of Anahawan | J40: 1 | K40: Type I | L40: SND 2743 | M40: 9270178990 | O40: 45636 | P40: 46387 | Q40: 16-005-25-ASP-1 | R40: New Faciliy | T40: 3rd Quarter | U40: *
...

Sheet Private
A1: # | B1: NHFR CODE | C1: REGION | D1: PROVINCE | E1: CITY/ MUNICIPALITY | F1: BLDG OR HOUSE NO., STREET, BRGY (as applicable) | G1: NAME OF AMBULANCE SERVICE PROVIDER | H1: OWNERSHIP | I1: OWNER/ HEAD OF FACILITY | J1: NO. OF UNITS | K1: TYPE | L1: PLATE NO./ CONDUCTION STICKER | M1: CONTACT NOS. | N1: EMAIL ADDRESS | O1: VALIDITY FROM | P1: VALIDITY UNTIL | Q1: LICENSED NO. | R1: APPLICATION STATUS | S1: APPLICATION STATUS (IF WITH CHANGES) | T1: REMARKS | U1: Reference used by DMU
A2: 1 | C2: REGION 3 | D2: Bataan | E2: Balanga City | F2: Capitol Compound, San Jose, Balanga City, Bataan | G2: PHILIPPINE RED CROSS - BATAAN CHAPTER | H2: Private | I2: Philippine Red Cross - Bataan Chapter | J2: 1 | K2: Type I | L2: WII 832 | M2: 0967-210-6103 | N2: bataan@redcross.org.ph | O2: 45735 | P2: 46752 | Q2: 13-0005-2527-ASP-2 | R2: New Faciliy
A3: 2 | C3: REGION 3 | D3: Nueva Ecija | E3: Cabanatuan City | F3: Rosita Building, Papaya Road, Mabini Homesite, Cabanatuan City, Nueva Ecija | G3: MED 1 AMBULANCE SERVICES INC. | H3: Private | I3: Noel Gonzales | J3: 1 | K3: Type II | L3: CCA 3765 | M3: 0905-327-0088 | N3: med1ambulancetransport@gmail.com | O3: 45737 | P3: 46752 | Q3: 13-0006-2527-ASP-2 | R3: New Faciliy
A4: 3 | C4: REGION 3 | D4: Nueva Ecija | E4: Cabanatuan City | F4: Old Capitol Building, Llanera St., Quezon, Cabanatuan City, Nueva Ecija | G4: PHILIPPINE RED CROSS - NUEVA ECIJA CHAPTER | H4: Private | I4: Philippine Red Cross - Nueva Ecija Chapter | J4: 1 | K4: Type I | L4: ZTT 729 | M4: 0943-523-8878 | N4: nueva.ecija@redcross.org.ph | O4: 45770 | P4: 46752 | Q4: 13-0007-2527-ASP-2 | R4: New Faciliy
A5: 4 | B5: 49021 | C5: REGION 3 | D5: Pampanga | E5: Angeles City | F5: 111 Rivera Avenue, Marisol Village Barangay Ninoy Aquino, Angeles City, Pampanga | G5: PROMPT AMBULANCE AND HEALTH SERVICES CORPORATION | H5: Private | I5: Prompt Ambulance and Health Services Corporation | J5: 2 | K5: Type I | L5: NEX 7329, NDZ 8064 | M5: (045) 436-7392 | N5: promptambulanceservice@yahoo.com | O5: 45658 | P5: 46752 | Q5: 13-0001-2628-ASP-2 | R5: Renewal
A6: 5 | B6: 49022 | C6: REGION 3 | D6: Pampanga | E6: San Fernando City | F6: Manila North Road, Baliti, City of San Fernando, Pampanga | G6: ITALIAN - THAI DEVELOPMENT PUBLIC COMPANY LIMITED | H6: Private | I6: Italian - Thai Development Public Company Limited | J6: 1 | K6: Type I | L6: NEW 6362 | M6: 0917-121-6216 | N6: joshuaelmer_dungca@yahoo.com | O6: 45292 | P6: 46387 | Q6: 13-0002-2628-ASP-2 | R6: Renewal
A7: 6 | C7: REGION 3 | D7: Tarlac | E7: Tarlac City | F7: Capitol Site, San Vicente, Tarlac City, Tarlac | G7: PHILIPPINE RED CROSS - TARLAC CHAPTER | H7: Private | I7: Philippine Red Cross - Tarlac Chapter | J7: 1 | K7: Type I | L7: NDH 6075 | M7: 0917-819-2312 | N7: tarlac@redcross.org.ph | O7: 45855 | P7: 46752 | Q7: 13-0003-2628-ASP-2 | R7: Renewal
A8: 7 | C8: REGION 3 | D8: Zambales | E8: Olongapo City | F8: #39 Magsaysay Drive, East Tapinac, Olongapo City, Zambales | G8: PHILIPPINE RED CROSS - OLONGAPO CHAPTER | H8: Private | I8: Philippine Red Cross - Olongapo Chapter | J8: 3 | K8: Type I | L8: ABD 2943 NER 7045 DAP 7104 | M8: 0917-889-2733 | N8: olongapo@redcross.org.ph | O8: 45867 | P8: 46752 | Q8: 13-0004-2628-ASP-2 | R8: Renewal
A9: 8 | B9: 49027 | C9: REGION 4-A | D9: Batangas | E9: Batac | F9: P. Panganiban St.,, BATANGAS CITY, BATANGAS | G9: SAVING PEOPLE'S HEALTH MULTI-PURPOSE COOPERATIVE | H9: Private | I9: SAVING PEOPLE'S HEALTH MULTI-PURPOSE COOPERATIVE | J9: 1 | K9: Type II | L9: ZGV892 | M9: (043) 723 8387/7232167 | N9: sphmc_coop@yahoo.com | O9: 45292 | P9: 46387 | Q9: 13-0006-2628-ASP-2 | R9: Renewal
A10: 9 | B10: 49025 | C10: REGION 4-A | D10: Batangas | E10: Batangas City | F10: Calansing, Simlong, Batangas City, Batangas | G10: ESYY TRANSPORT SERVICES | H10: Private | I10: Socorro A. Bas | J10: 1 | K10: Type I | L10: IOG 155 | M10: 0967-829-3533 / (043) 781-3885 | N10: esyy.ph@gmail.com | O10: 45658 | P10: 46752 | Q10: 13-0007-2628-ASP-2 | R10: Renewal
A11: 10 | B11: 51456 | C11: REGION 4-A | D11: Batangas | E11: Lipa City | F11: DP. Laygo St., Sabang, Lipa City, Batangas | G11: PHILIPPINE RED CROSS BATANGAS CHAPTER – LIPA CITY BRANCH EMS STATION | H11: Private | I11: Philippine Red Cross | J11: 1 | K11: Type I | L11: NIE472 | M11: 043-7400768/09980570443/09171800459 | N11: sslipa.redcrossbatangas@gmail.com | O11: 45512 | P11: 46387 | Q11: 13-0008-2628-ASP-2 | R11: Renewal
A12: 11 | B12: 49026 | C12: REGION 4-A | D12: Cavite | E12: Dasmariñas City | F12: Block 1 Lot 4 Fatima, CITY OF DASMARIÑAS, CAVITE | G12: BIO-AID DIAGNOSTIC CENTER | H12: Private | I12: CNN Healthcare Management Inc. | J12: 1 | K12: Type II | L12: TIB324 | M12: (046) 851 0703/8511453 | N12: codojr.ccnhealthcare@gmail.com | O12: 45292 | P12: 46387 | Q12: 13-0009-2628-ASP-2 | R12: New Faciliy
A13: 12 | C13: REGION 4-A | D13: Cavite | E13: Dasmariñas City | F13: 218 San Jose, Dasmariñas, Cavite | G13: Datastat Emergency & Safety Training Consultancy Services | H13: Private | I13: Catherine M. Tapawan | J13: 1 | K13: Type I | L13: AOA 4809 | M13: 9989919950 | N13: med1sanitater@gmail.com | O13: 45705 | P13: 46752 | Q13: 13-0010-2628-ASP-2 | R13: Renewal
A14: 13 | B14: 49030 | C14: REGION 4-A | D14: Rizal | E14: Antipolo City | F14: L-8 B-B Don Pedro St. Villa Cecilia Subd. Mambugan, Antipolo City, Rizal | G14: ER MED AMBULANCE SERVICES | H14: Private | I14: Mr. Jefferson D. Sernande | J14: 2 | K14: Type II | L14: FOY 444 NED 2593 | M14: 0915-132-4861 | N14: er.med@yahoo.com | O14: 45658 | P14: 46752 | Q14: 14-0001-2527-ASP-2 | R14: Still Accredited | V14: 79
A15: 14 | B15: 54452 | C15: REGION 5 | D15: Camarines Sur | E15: Naga City | F15: Sardonyx St., Villa Grande Homes Subd., Concepcion Grande, Naga City, Camarines Sur | G15: JHJA TRANSPORT SERVICES | H15: Private | I15: Juven C. Peñaflorida, RMT | J15: 1 | K15: Type I | L15: XHG581/13949670-0 | M15: 9632006786 | N15: st.johnhosp72_naga_4400@yahoo.com | O15: 45658 | P15: 46752 | Q15: DOH049053 | R15: Renewal | V15: 82
A16: 15 | C16: REGION 6 | D16: Iloilo | E16: Iloilo City | F16: 45 GUZMAN STREET BRGY. GUZMAN -JESENA | G16: LIFEBEAT AMBULANCE SEVICE PROVIDER | H16: Private | I16: Frankie Nolasco Famillaran | J16: 1 | K16: Type I | L16: FAF4123 | M16: 9672704084 | N16: lifebeambulanceservices@gmail.com | O16: 45824 | P16: 46752 | Q16: DOH049054 | R16: Renewal | V16: 83
A17: 16 | C17: REGION 6 | D17: Iloilo | E17: Iloilo City | F17: 2ND FLOOR, B LIFESTYLE COMPLEX, DIVERSION RD., CUARTERO, JARO, ILOILO CITY | G17: RONINEMS CORPORATION | H17: Private | I17: Dr. Hyacinth Sillo | J17: 1 | K17: Type I | L17: FAP6752 | M17: 9493999111 | N17: roninems2024@gmail.com | O17: 45483 | P17: 46387 | Q17: DOH049052 | R17: Renewal
A18: 17 | B18: 49031 | C18: REGION 7 | D18: Cebu | E18: Cebu City | F18: CMS Compound Governor Cuenco Avenue, Banilad , Cebu City | G18: EMERGENCY RESCUE UNIT FOUNDATION PHIL. INC. | H18: Private | I18: Emergency Rescue Unit Foundation, Phil. Inc. | J18: 4 | K18: Type II | L18: GAC 5538. GAM 5089, GAC 5537, GAC 5539 | M18: (63) (32) 233-9300 | N18: connect@eruf161.com.ph | O18: 45292 | P18: 46387 | Q18: DOH044545 | R18: New Faciliy
A19: 18 | C19: REGION 9 | D19: Zamboanga del Sur | E19: Zamboanga City | F19: Mayor Jaldon St. | G19: ALS LIFE SUPPORT | H19: Private | I19: Rioklyn P. Toledo | J19: 2 | K19: Type I | L19: NAR 2129/ NGT 6334 | M19: 9171260520 | N19: alszamboinc@gmail.com | O19: 45609 | P19: 46387 | Q19: DOH054730 | R19: New Faciliy
A20: 19 | B20: 51439 | C20: REGION 10 | D20: Lanao del Norte | E20: Cagayan de Oro City | F20: Brgy. Libertad, Kauswagan, Lanao del Norte | G20: GNPOWER KAUSWAGAN LTD. CO. | H20: Private | I20: Gnpower Kauswagan Ltd. Co. | J20: 1 | K20: Type I | L20: KAR3385 | M20: 063-8339040/09178355613 | N20: eden.yurong@gnpk.com.ph | O20: 45481 | P20: 46387 | Q20: DOH052049 | R20: New Faciliy
A21: 20 | B21: 49033 | C21: REGION 11 | D21: Davao del Sur | E21: Davao City | F21: Amya Building, Quimpo Boulevard Cor. Tulip Drive, Ecoland, Davao City | G21: ECOLAND MEDICAL AND WELLNESS CENTER, INC. | H21: Private | I21: Ecoland Medical and Wellness Center, Inc. | J21: 1 | K21: Type I | L21: MAU 5157 | M21: (082) 2241883 | N21: ecomedhospital@gmail.com | O21: 45316 | P21: 46752 | Q21: DOH049043 | R21: New Faciliy
A22: 21 | B22: 49032 | C22: REGION 11 | D22: Davao del Sur | E22: Davao City | F22: Door 7 & 8, SPK Building, Km. 7, Lanang, Vicente Hizon Sr., Davao City, Davao del Sur | G22: PROHEALTH EMS | H22: Private | I22: Prohealth EMS | J22: 1 | K22: Type II | L22: LAG 9501 | M22: 0923 083 9803 | N22: info.prohealthsolutions@gmail.com | O22: 45777 | P22: 46752 | Q22: 13-0001-2426-ASP-2 | R22: New Faciliy
A23: 22 | C23: REGION 11 | D23: Davao Occidental | E23: Malita | F23: Sitio Inaburan, Brgy. Culaman, Municipality of Malita Davao | G23: SAN MIGUEL CONSOLIDATED POWER CORPORATION | H23: Private | J23: 1 | K23: Type I | L23: NCQ 2711 | M23: 9381734516 | N23: kdeloso@smcgph.sanmiguel.com.ph | O23: 46023 | P23: 47118 | Q23: 13-0003-2426-ASP-2 | R23: New Faciliy
A24: 23 | C24: REGION 12 | D24: South Cotabato | E24: Lake Sebu | F24: Kibang, Brgy. Ned | G24: DELTA EARTHMOVING, INC. | H24: Private | I24: Ronald M. Manalac | J24: 1 | K24: Type I | L24: NIP 5428/1301-17350 | O24: 45483 | P24: 46752 | Q24: 13-0004-2527-ASP-2 | R24: New Faciliy
A25: 24 | C25: NCR | D25: Metro Manila | E25: Makati City | F25: 1-C Moonlite St., Brgy. Singkamas, Makati City | G25: AMBULANCE SERVICE CODEBLUE EMERGENCY | H25: Private | I25: Julian Enrique | J25: 1 | K25: Type II | L25: NEU4046 | M25: 0966-597-7754 | N25: codeblueems08@gmail.com | O25: 45916 | P25: 46752 | Q25: 03-0011-2527-ASP-2 | R25: Still Accredited | S25: N/A
A26: 25 | B26: 49042 | C26: NCR | D26: Metro Manila | E26: Makati City | F26: 25D Zeta II Bldg. 191, Salcedo St, Legaspi Village, CITY OF MAKATI, NCR, FOURTH DISTRICT | G26: ARGONIX MEDICAL CORPORATION | H26: Private | I26: ARGONIX MEDICAL CORPORATION | J26: 2 | K26: Type II | L26: NBW 1961, NBR 5741 | M26: (02) 8373 7377 / 0925-734-8476 | N26: argonixph@gmail.com | O26: 45292 | P26: 46387 | Q26: DOH049027 | R26: Renewal | U26: *
A27: 26 | C27: NCR | D27: Metro Manila | E27: Makati City | F27: 2260 Chino Roces Ext. Brgy. Magallanes, Makati | G27: LEIGHTON FIRST BALFOUR JOINT VENTURE | H27: Private | I27: Paul Hedley | J27: 1 | K27: Type I | L27: Plate No. CCD7644 CR No. 84323381 | M27: 0916-775-1797 | N27: maria.vito@lfbjv.com.ph | O27: 46023 | P27: 47118 | Q27: 4A-0002-2527-ASP-2 | R27: Renewal | U27: *
A28: 27 | C28: NCR | D28: Metro Manila | E28: Mandaluyong City | F28: No. 6 ADB Avenue, Wack-wack, Mandaluyong City | G28: ASIAN DEVELOPMENT BANK | H28: Private | I28: ASIAN DEVELOPMENT BANK | J28: 1 | K28: Type II | L28: Plate No. 205-0114, CR No. 463251526 | M28: 86322-4444 | N28: adusdiisariyavong@dba.org | O28: 46023 | P28: 47118 | Q28: DOH051456 | R28: New Faciliy | U28: *
A29: 28 | B29: DOH000000000050173 | C29: NCR | D29: Metro Manila | E29: Mandaluyong City | F29: Williams St., Cor Mayflower St., Highway Hills, Greenfield District, Mandaluyong City | G29: HEALTH DELIVERY SYSTEM INC. | H29: Private | I29: Health Delivery System Inc. | J29: 2 | K29: Type I | L29: PLATE NO. NCQ3713, CR No. 029052187 / PLATE NO. NKF 7750, CR NO. 0099004956 | M29: 9994224601 | N29: eric.elumbaring@healthfirst.com.ph | O29: 46023 | P29: 47118 | Q29: DOH049026 | R29: Renewal | U29: *
A30: 29 | C30: NCR | D30: Metro Manila | E30: Mandaluyong City | F30: Unit 207 Building F, Banahaw Medium Rise Condominium, Banahaw Street, Brgy. Highway Hills, Mandaluyong City | G30: MEDIXTOGO AMBULANCE SERVICE | H30: Private | I30: Dr. Joel B. Santos | J30: 1 | K30: Type II | L30: Plate No.. NHB4706 CR NO. 046217973-4 | M30: 9175115386 | N30: medixtogo@gmail.com | O30: 46023 | P30: 47118 | Q30: 4A-0003-2527-ASP-2 | R30: New Faciliy | U30: *
A31: 30 | B31: 49028 | C31: NCR | D31: Metro Manila | E31: Mandaluyong City | F31: 37 EDSA cor. Boni Ave., Brgy. Ilaya, Mandaluyong City | G31: PHILIPPINE RED CROSS - NATIONAL HEADQUARTERS | H31: Private | I31: Philippine Red Cross | J31: 5 | K31: Type I | L31: NIF 6637/DBF 2871/DBF 2874/DBF 2873 & DBF 2894 | M31: 9178068518 | N31: prc.ems@redcross.org.ph | O31: 45664 | P31: 46387 | Q31: DOH049050 | R31: Existing with Changes
A32: 31 | B32: 49039 | C32: NCR | D32: Metro Manila | E32: Manila | F32: 10 Granada St., Brgy. Gulod, Quezon City, Metro Manila | G32: AMBUCARE EMS SOLUTIONS | H32: Private | I32: Mr. Ryan N. Tizon | J32: 1 | K32: Type II | L32: PVO 421 | M32: 0999-8829-586 | N32: ambucare_ems@yahoo.com | O32: 45292 | P32: 46387 | Q32: 4A-0001-2527-ASP-2 | R32: Renewal | U32: *
A33: 32 | B33: DOH000000000050266 | C33: NCR | D33: Metro Manila | E33: Manila | F33: 540 ANTIPOLO ST., BRGY. 148, TONDO, MANILA | G33: ARCHERS AMBULANCE SERVICE | H33: Private | I33: Mr. Kevin E. Concepcion | J33: 1 | K33: Type II | L33: NFW7687 | M33: 09177988870 / 090228798716 | N33: archerambulance@gmail.com | O33: 46023 | P33: 47118 | Q33: 05-0001-2527-ASP-2 | R33: Still Accredited | U33: *
A34: 33 | C34: NCR | D34: Metro Manila | E34: Manila | F34: 1232 JUANING ST., 471, 1ST DISTRICT, SAMPALOC, MANILA | G34: FIL-AM RESCUE EQUIPMENT TRADING | H34: Private | I34: BEVERLY JOHN F. PARAYNO | J34: 1 | K34: Type II | L34: WSR629 | M34: 0995-9741-161 | N34: filamems@gmail.com | O34: 45855 | P34: 46752 | Q34: 06-0001-2426-ASP-2 | R34: New Faciliy | S34: N/A
A35: 34 | B35: 49041 | C35: NCR | D35: Metro Manila | E35: Manila | F35: #123 Juaning Street Sampaloc, Manila | G35: FILAM RESCUE VOLUNTEERS INC. | H35: Private | I35: Filam Rescue Volunteers Inc. | J35: 1 | K35: Type I | L35: WGD 808 | M35: 0995-974-1161 | N35: filamrescuevolunteer@gmail.com | O35: 45292 | P35: 46387 | Q35: 06-0001-2527-ASP-2 | R35: New Faciliy | S35: N/A
A36: 35 | C36: NCR | D36: Metro Manila | E36: Manila | F36: 1849 DAGUPAN COR. BALAYA ST., TONDO, BRGY. 54, MANILA | G36: PRIMECARE AMBULANCE SERVICE | H36: Private | I36: JEFFREY D. DATUIN | J36: 1 | K36: Type II | L36: Plate No. NEO 5969, CS No. 366347704 | M36: 0917-1151882 | N36: rwjcorrugating@gmail.com | O36: 46038 | P36: 47118 | Q36: DOH049031 | R36: Still Accredited | U36: *
A37: 36 | C37: NCR | D37: Metro Manila | E37: Manila | F37: 6th Floor Vertex One Felix Huertas Road, Sta. Cruz, Manila | G37: PT ADHI KARYA (PERSERO) TBK | H37: Private | I37: PT ADHI KARYA (PERSERO) TBK | J37: 1 | K37: Type I | L37: NIO3504 | M37: 0928-306-5960 | N37: ujang.ramdam@adhi.co.id | O37: 45775 | P37: 46752 | Q37: 09-0003-2426-ASP-2 | R37: Still Accredited | V37: 50 | W37: 61
A38: 37 | B38: 49047 | C38: NCR | D38: Metro Manila | E38: Manila | F38: 500 Santol St., Sta. Mesa, CITY OF MANILA, NCR, CITY OF MANILA, FIRST DISTRICT | G38: TRANSCARE EMERGENCY MEDICAL SERVICES | H38: Private | I38: TRANSCARE EMERGENCY MEDICAL SERVICES | J38: 2 | K38: Type II | L38: UQM 891 AAB 2697 | M38: 0928 389 0790 / 0936-923-2149 | N38: transcareemergencyservices@gmail.com | O38: 45292 | P38: 46387 | Q38: DOH051439 | R38: New Faciliy | U38: *
A39: 38 | B39: 49040 | C39: NCR | D39: Metro Manila | E39: Marikina City | F39: 756 Instruccion Street, Sampaloc, Manila, CITY OF MANILA, NCR, CITY OF MANILA, FIRST DISTRICT | G39: ACE COR MEDICAL SERVICES | H39: Private | I39: ACE COR MEDICAL SERVICES | J39: 6 | K39: Type II | L39: NBK 2140, NAD 2378, NCG 5936, NAA8988, NEJ3042, NEJ6549 | M39: 0917-506-2280 | N39: acecorambulance@yahoo.com | O39: 45292 | P39: 46387 | Q39: 11-02-2527-PCF-2 | R39: Renewal | S39: N/A
A40: 39 | C40: NCR | D40: Metro Manila | E40: Muntinlupa City | F40: Meralco Road, Sucat, Muntinlupa, 2nd District Muntinlupa | G40: PT ADHI KARYA (PERSERO) TBK - PHILIPPINE BRANCH | H40: Private | I40: PT ADHI KARYA (PERSERO) TBK - PHILIPPINE BRANCH | J40: 1 | K40: Type I | L40: NBR4229 | M40: 8525-4971 | N40: scrp.cps03c@adhiptppjv.com | O40: 45783 | P40: 46752 | Q40: 11-002-2527-ASP-2 | R40: New Faciliy | S40: N/A
...

Sheet Master Data
A1: REGION | B1: CHD | C1: Province | D1: CITY / MUNICIPALITY
K3: Clinical Lab | L3: Infirmary | M3: Clinical Lab - Hospital | N3: Cancer Treatment Facility - Hospital | O3: Status | P3: Dental Lab | Q3: Psychiatrict Care | R3: LDWA | S3: Type of Ambulance Service | T3: Covid Testing | U3: Dialysis Clinics | V3: Medical Facility for Oversease Workers and Seafarers | W3: DATRC | Y3: Modality | Z3: Chemical Water
H4: AD-ONS SERVICES | J4: BSF | K4: Service Capability | L4: DOH RETAINED | M4: Secondary | N4: Cancer Specialty Hospital | O4: New | P4: FIXED | Q4: Custodial Psychiatric Care Facility | R4: Microbiological | S4: Type I | T4: rRT PCR | U4: Hospital based | V4: Regular Land-based and Seafarer | W4: Residential | X4: Institution-based | Y4: Therapeutic Community
A5: NCR | B5: METRO MANILA | C5: Abra | D5: Aborlan | E5: Government | F5: General | G5: Level 1 | H5: G6PD Confirmatory | I5: Hospital-based | J5: Blood Station | K5: Primary | L5: LGU | M5: Tertiary | N5: Cancer Specialty Center in a General Hospital | O5: Renewal | P5: REMOVABLE | Q5: Acute Chronic Psychiatric Facility | R5: Physico-Chemical | S5: Type II | T5: Cartridge-based PCR | U5: Non hospital based | V5: Special Seafarer's Medical Facility | W5: Non-Residential | X5: Free Standing | Y5: Eclectic
A6: REGION 1 | B6: ILOCOS REGION | C6: Agusan del Norte | D6: Abra de Ilog | E6: Private | F6: Specialty | G6: Level 2 | H6: rHIVda Confirmatory Laboratory | I6: Non-Hospital-based | J6: Blood Collection Unit | K6: Secondary | L6: UNIVERSITY/SCHOOL | M6: Molecular Lab | N6: Cancer Treatment Unit in a General Hospital | R6: Microbiological and Physico-Chemical | S6: Type I & II | T6: rRT PCR/ Cartridge-based PCR | W6: Residential with Oupatient Service | Y6: Hazelden Minnesotta
A7: REGION 2 | B7: CAGAYAN VALLEY REGION | C7: Agusan del Sur | D7: Abucay | G7: Level 3 | H7: Dialysis Clinic | J7: Blood Collection Unit/Blood Services | K7: Tertiary | L7: GOCC | M7: N/A | N7: N/A | Y7: Faith-based
A8: REGION 3 | B8: CENTRAL LUZON | C8: Aklan | D8: Abulug | H8: Diagnostic X-ray Services | J8: Blood Bank | K8: Limited | L8: AFP
A9: REGION 4-A | B9: CALABARZON | C9: Albay | D9: Abuyog | H9: HIV Testing Laboratory | J9: Blood Bank with additional function | L9: PAF
A10: REGION 4-B | B10: MIMAROPA | C10: Antique | D10: Adams | H10: Physical Medicine and Rehabilitation Unit | J10: Blood Center | K10: Institutional Character | L10: PNP
A11: REGION 5 | B11: BICOL REGION | C11: Apayao | D11: Agdangan | H11: Blood Bank | J11: Blood Collection Unit/Blood Station | K11: Institution-based | L11: DND
A12: REGION 6 | B12: WESTERN VISAYAS REGION | C12: Aurora | D12: Aglipay | H12: Specialized Diagnostic X-ray Services | K12: Non-Institution based | L12: MOH BARMM
A13: REGION 7 | B13: CENTRAL VISAYAS REGION | C13: Basilan | D13: Agno | H13: Tertiary Laboratory w/ histopathology | L13: PGH
A14: REGION 8 | B14: EASTERN VISAYAS REGION | C14: Bataan | D14: Agoncillo | H14: Anatomic Pathology | L14: PROVINCE
A15: REGION 9 | B15: ZAMBOANGA PENINSULA | C15: Batanes | D15: Agoo | H15: Dental X-ray Services | K15: Function | L15: N/A
A16: REGION 10 | B16: NORTHERN MINDANAO REGION | C16: Batangas | D16: Aguilar | H16: Ambulatory Surgical Clinic | K16: CP
A17: REGION 11 | B17: SOUTHERN MINDANAO REGION | C17: Benguet | D17: Aguinaldo | H17: Blood Collection Unit | K17: AP
A18: REGION 12 | B18: SOCCSKSARGEN | C18: Biliran | D18: Agutaya | H18: Cancer Treatment Facility | K18: CP-AP
A19: REGION 13 | B19: CARAGA | C19: Bohol | D19: Ajuy | H19: Laboratory for Drinking Water Analysis | K19: CP With Associate AP
A20: CORDILLERA | B20: CAR | C20: Bukidnon | D20: Akbar | H20: Radiation Therapy Service
A21: NIR | B21: NEGROS ISLAND REGION
A22: BARMM | B22: MOH - BARMM | C22: Bulacan | D22: Al-Barka | H22: Radiation Oncology Services
C23: Cagayan | D23: Ala Esperanza | H23: Pharmacy
C24: Camarines Norte | D24: Alabat | H24: Mobile Clinical Laboratory
C25: Camarines Sur | D25: Alabel | H25: Psychiatric Care
C26: Camiguin | D26: Alamada
C27: Capiz | D27: Alaminos
C28: Catanduanes | D28: Alaminos City
C29: Cavite | D29: Alangalang
C30: Cebu | D30: Albuera
C31: Cotabato | D31: Alburquerque
C32: Davao de Oro | D32: Alcala
C33: Davao del Norte | D33: Alcantara
C34: Davao del Sur | D34: Alcoy
C35: Davao Occidental | D35: Alegria
C36: Davao Oriental | D36: Aleosan
C37: Dinagat Islands | D37: Alfonso
... C102: Polomolok | D102: Bacuag
D103: Badian
D104: Badiangan
D105: Badoc
...
