Workbook

Sheet Summary
A1: Region | B1: CHD | C1: Regional Distribution of Hospitals in the Philippines (as of June 30, 2026)
C2: GOVERNMENT | F2: TOTAL | G2: PRIVATE | J2: TOTAL | K2: GOVT AND PRIVATE HOSPITALS | N2: TOTAL
C4: LEVEL 1 | D4: LEVEL 2 | E4: LEVEL 3 | G4: LEVEL 1 | H4: LEVEL 2 | I4: LEVEL 3 | K4: LEVEL 1 | L4: LEVEL 2 | M4: LEVEL 3
A5: NCR | B5: METRO MANILA | C5: =COUNTIFS(Government!C:C, "NCR", Government!H:H, "Government", Government!K:K, "Level 1") -> 14 | D5: =COUNTIFS(Government!C:C, "NCR", Government!H:H, "Government", Government!K:K, "Level 2") -> 8 | E5: =COUNTIFS(Government!C:C, "NCR", Government!H:H, "Government", Government!K:K, "Level 3") -> 29 | F5: =sum(C5:E5) -> 51 | G5: =COUNTIFS(Private!C:C, "NCR", Private!H:H, "Private", Private!K:K, "Level 1") -> 32 | H5: =COUNTIFS(Private!C:C, "NCR", Private!H:H, "Private", Private!K:K, "Level 2") -> 41 | I5: =COUNTIFS(Private!C:C, "NCR", Private!H:H, "Private", Private!K:K, "Level 3") -> 29 | J5: =SUM(G5:I5) -> 102 | K5: =SUM(C5,G5) -> 46 | L5: =SUM(D5,H5) -> 49 | M5: =SUM(E5,I5) -> 58 | N5: =SUM(K5:M5) -> 153
A6: REGION 1 | B6: ILOCOS REGION | C6: =COUNTIFS(Government!C:C, "REGION 1", Government!H:H, "Government", Government!K:K, "Level 1") -> 25 | D6: =COUNTIFS(Government!C:C, "REGION 1", Government!H:H, "Government", Government!K:K, "Level 2") -> 8 | E6: =COUNTIFS(Government!C:C, "REGION 1", Government!H:H, "Government", Government!K:K, "Level 3") -> 3 | F6: =sum(C6:E6) -> 36 | G6: =COUNTIFS(Private!C:C, "REGION 1", Private!H:H, "Private", Private!K:K, "Level 1") -> 26 | H6: =COUNTIFS(Private!C:C, "REGION 1", Private!H:H, "Private", Private!K:K, "Level 2") -> 21 | I6: =COUNTIFS(Private!C:C, "REGION 1", Private!H:H, "Private", Private!K:K, "Level 3") -> 1 | J6: =SUM(G6:I6) -> 48 | K6: =SUM(C6,G6) -> 51 | L6: =SUM(D6,H6) -> 29 | M6: =SUM(E6,I6) -> 4 | N6: =SUM(K6:M6) -> 84
A7: REGION 2 | B7: CAGAYAN VALLEY REGION | C7: =COUNTIFS(Government!C:C, "REGION 2", Government!H:H, "Government", Government!K:K, "Level 1") -> 19 | D7: =COUNTIFS(Government!C:C, "REGION 2", Government!H:H, "Government", Government!K:K, "Level 2") -> 2 | E7: =COUNTIFS(Government!C:C, "REGION 2", Government!H:H, "Government", Government!K:K, "Level 3") -> 3 | F7: =sum(C7:E7) -> 24 | G7: =COUNTIFS(Private!C:C, "REGION 2", Private!H:H, "Private", Private!K:K, "Level 1") -> 26 | H7: =COUNTIFS(Private!C:C, "REGION 2", Private!H:H, "Private", Private!K:K, "Level 2") -> 16 | I7: =COUNTIFS(Private!C:C, "REGION 2", Private!H:H, "Private", Private!K:K, "Level 3") -> 0 | J7: =SUM(G7:I7) -> 42 | K7: =SUM(C7,G7) -> 45 | L7: =SUM(D7,H7) -> 18 | M7: =SUM(E7,I7) -> 3 | N7: =SUM(K7:M7) -> 66
A8: REGION 3 | B8: CENTRAL LUZON | C8: =COUNTIFS(Government!C:C, "REGION 3", Government!H:H, "Government", Government!K:K, "Level 1") -> 47 | D8: =COUNTIFS(Government!C:C, "REGION 3", Government!H:H, "Government", Government!K:K, "Level 2") -> 5 | E8: =COUNTIFS(Government!C:C, "REGION 3", Government!H:H, "Government", Government!K:K, "Level 3") -> 6 | F8: =sum(C8:E8) -> 58 | G8: =COUNTIFS(Private!C:C, "REGION 3", Private!H:H, "Private", Private!K:K, "Level 1") -> 70 | H8: =COUNTIFS(Private!C:C, "REGION 3", Private!H:H, "Private", Private!K:K, "Level 2") -> 51 | I8: =COUNTIFS(Private!C:C, "REGION 3", Private!H:H, "Private", Private!K:K, "Level 3") -> 4 | J8: =SUM(G8:I8) -> 125 | K8: =SUM(C8,G8) -> 117 | L8: =SUM(D8,H8) -> 56 | M8: =SUM(E8,I8) -> 10 | N8: =SUM(K8:M8) -> 183
A9: REGION 4-A | B9: CALABARZON | C9: =COUNTIFS(Government!C:C, "REGION 4-A", Government!H:H, "Government", Government!K:K, "Level 1") -> 52 | D9: =COUNTIFS(Government!C:C, "REGION 4-A", Government!H:H, "Government", Government!K:K, "Level 2") -> 3 | E9: =COUNTIFS(Government!C:C, "REGION 4-A", Government!H:H, "Government", Government!K:K, "Level 3") -> 3 | F9: =sum(C9:E9) -> 58 | G9: =COUNTIFS(Private!C:C, "REGION 4-A", Private!H:H, "Private", Private!K:K, "Level 1") -> 81 | H9: =COUNTIFS(Private!C:C, "REGION 4-A", Private!H:H, "Private", Private!K:K, "Level 2") -> 86 | I9: =COUNTIFS(Private!C:C, "REGION 4-A", Private!H:H, "Private", Private!K:K, "Level 3") -> 3 | J9: =SUM(G9:I9) -> 170 | K9: =SUM(C9,G9) -> 133 | L9: =SUM(D9,H9) -> 89 | M9: =SUM(E9,I9) -> 6 | N9: =SUM(K9:M9) -> 228
A10: REGION 4-B | B10: MIMAROPA | C10: =COUNTIFS(Government!C:C, "REGION 4-B", Government!H:H, "Government", Government!K:K, "Level 1") -> 15 | D10: =COUNTIFS(Government!C:C, "REGION 4-B", Government!H:H, "Government", Government!K:K, "Level 2") -> 3 | E10: =COUNTIFS(Government!C:C, "REGION 4-B", Government!H:H, "Government", Government!K:K, "Level 3") -> 0 | F10: =sum(C10:E10) -> 18 | G10: =COUNTIFS(Private!C:C, "REGION 4-B", Private!H:H, "Private", Private!K:K, "Level 1") -> 9 | H10: =COUNTIFS(Private!C:C, "REGION 4-B", Private!H:H, "Private", Private!K:K, "Level 2") -> 7 | I10: =COUNTIFS(Private!C:C, "REGION 4-B", Private!H:H, "Private", Private!K:K, "Level 3") -> 0 | J10: =SUM(G10:I10) -> 16 | K10: =SUM(C10,G10) -> 24 | L10: =SUM(D10,H10) -> 10 | M10: =SUM(E10,I10) -> 0 | N10: =SUM(K10:M10) -> 34
A11: REGION 5 | B11: BICOL REGION | C11: =COUNTIFS(Government!C:C, "REGION 5", Government!H:H, "Government", Government!K:K, "Level 1") -> 16 | D11: =COUNTIFS(Government!C:C, "REGION 5", Government!H:H, "Government", Government!K:K, "Level 2") -> 3 | E11: =COUNTIFS(Government!C:C, "REGION 5", Government!H:H, "Government", Government!K:K, "Level 3") -> 3 | F11: =sum(C11:E11) -> 22 | G11: =COUNTIFS(Private!C:C, "REGION 5", Private!H:H, "Private", Private!K:K, "Level 1") -> 19 | H11: =COUNTIFS(Private!C:C, "REGION 5", Private!H:H, "Private", Private!K:K, "Level 2") -> 14 | I11: =COUNTIFS(Private!C:C, "REGION 5", Private!H:H, "Private", Private!K:K, "Level 3") -> 1 | J11: =SUM(G11:I11) -> 34 | K11: =SUM(C11,G11) -> 35 | L11: =SUM(D11,H11) -> 17 | M11: =SUM(E11,I11) -> 4 | N11: =SUM(K11:M11) -> 56
A12: REGION 6 | B12: WESTERN VISAYAS REGION | C12: =COUNTIFS(Government!C:C, "REGION 6", Government!H:H, "Government", Government!K:K, "Level 1") -> 18 | D12: =COUNTIFS(Government!C:C, "REGION 6", Government!H:H, "Government", Government!K:K, "Level 2") -> 6 | E12: =COUNTIFS(Government!C:C, "REGION 6", Government!H:H, "Government", Government!K:K, "Level 3") -> 2 | F12: =sum(C12:E12) -> 26 | G12: =COUNTIFS(Private!C:C, "REGION 6", Private!H:H, "Private", Private!K:K, "Level 1") -> 2 | H12: =COUNTIFS(Private!C:C, "REGION 6", Private!H:H, "Private", Private!K:K, "Level 2") -> 15 | I12: =COUNTIFS(Private!C:C, "REGION 6", Private!H:H, "Private", Private!K:K, "Level 3") -> 3 | J12: =SUM(G12:I12) -> 20 | K12: =SUM(C12,G12) -> 20 | L12: =SUM(D12,H12) -> 21 | M12: =SUM(E12,I12) -> 5 | N12: =SUM(K12:M12) -> 46
A13: REGION 7 | B13: CENTRAL VISAYAS REGION | C13: =COUNTIFS(Government!C:C, "REGION 7", Government!H:H, "Government", Government!K:K, "Level 1") -> 12 | D13: =COUNTIFS(Government!C:C, "REGION 7", Government!H:H, "Government", Government!K:K, "Level 2") -> 8 | E13: =COUNTIFS(Government!C:C, "REGION 7", Government!H:H, "Government", Government!K:K, "Level 3") -> 3 | F13: =sum(C13:E13) -> 23 | G13: =COUNTIFS(Private!C:C, "REGION 7", Private!H:H, "Private", Private!K:K, "Level 1") -> 8 | H13: =COUNTIFS(Private!C:C, "REGION 7", Private!H:H, "Private", Private!K:K, "Level 2") -> 15 | I13: =COUNTIFS(Private!C:C, "REGION 7", Private!H:H, "Private", Private!K:K, "Level 3") -> 8 | J13: =SUM(G13:I13) -> 31 | K13: =SUM(C13,G13) -> 20 | L13: =SUM(D13,H13) -> 23 | M13: =SUM(E13,I13) -> 11 | N13: =SUM(K13:M13) -> 54
A14: REGION 8 | B14: EASTERN VISAYAS REGION | C14: =COUNTIFS(Government!C:C, "REGION 8", Government!H:H, "Government", Government!K:K, "Level 1") -> 19 | D14: =COUNTIFS(Government!C:C, "REGION 8", Government!H:H, "Government", Government!K:K, "Level 2") -> 1 | E14: =COUNTIFS(Government!C:C, "REGION 8", Government!H:H, "Government", Government!K:K, "Level 3") -> 1 | F14: =sum(C14:E14) -> 21 | G14: =COUNTIFS(Private!C:C, "REGION 8", Private!H:H, "Private", Private!K:K, "Level 1") -> 24 | H14: =COUNTIFS(Private!C:C, "REGION 8", Private!H:H, "Private", Private!K:K, "Level 2") -> 5 | I14: =COUNTIFS(Private!C:C, "REGION 8", Private!H:H, "Private", Private!K:K, "Level 3") -> 1 | J14: =SUM(G14:I14) -> 30 | K14: =SUM(C14,G14) -> 43 | L14: =SUM(D14,H14) -> 6 | M14: =SUM(E14,I14) -> 2 | N14: =SUM(K14:M14) -> 51
A15: REGION 9 | B15: ZAMBOANGA PENINSULA | C15: =COUNTIFS(Government!C:C, "REGION 9", Government!H:H, "Government", Government!K:K, "Level 1") -> 8 | D15: =COUNTIFS(Government!C:C, "REGION 9", Government!H:H, "Government", Government!K:K, "Level 2") -> 7 | E15: =COUNTIFS(Government!C:C, "REGION 9", Government!H:H, "Government", Government!K:K, "Level 3") -> 1 | F15: =sum(C15:E15) -> 16 | G15: =COUNTIFS(Private!C:C, "REGION 9", Private!H:H, "Private", Private!K:K, "Level 1") -> 21 | H15: =COUNTIFS(Private!C:C, "REGION 9", Private!H:H, "Private", Private!K:K, "Level 2") -> 8 | I15: =COUNTIFS(Private!C:C, "REGION 9", Private!H:H, "Private", Private!K:K, "Level 3") -> 0 | J15: =SUM(G15:I15) -> 29 | K15: =SUM(C15,G15) -> 29 | L15: =SUM(D15,H15) -> 15 | M15: =SUM(E15,I15) -> 1 | N15: =SUM(K15:M15) -> 45
A16: REGION 10 | B16: NORTHERN MINDANAO REGION | C16: =COUNTIFS(Government!C:C, "REGION 10", Government!H:H, "Government", Government!K:K, "Level 1") -> 16 | D16: =COUNTIFS(Government!C:C, "REGION 10", Government!H:H, "Government", Government!K:K, "Level 2") -> 4 | E16: =COUNTIFS(Government!C:C, "REGION 10", Government!H:H, "Government", Government!K:K, "Level 3") -> 3 | F16: =sum(C16:E16) -> 23 | G16: =COUNTIFS(Private!C:C, "REGION 10", Private!H:H, "Private", Private!K:K, "Level 1") -> 36 | H16: =COUNTIFS(Private!C:C, "REGION 10", Private!H:H, "Private", Private!K:K, "Level 2") -> 16 | I16: =COUNTIFS(Private!C:C, "REGION 10", Private!H:H, "Private", Private!K:K, "Level 3") -> 1 | J16: =SUM(G16:I16) -> 53 | K16: =SUM(C16,G16) -> 52 | L16: =SUM(D16,H16) -> 20 | M16: =SUM(E16,I16) -> 4 | N16: =SUM(K16:M16) -> 76
A17: REGION 11 | B17: DAVAO REGION | C17: =COUNTIFS(Government!C:C, "REGION 11", Government!H:H, "Government", Government!K:K, "Level 1") -> 9 | D17: =COUNTIFS(Government!C:C, "REGION 11", Government!H:H, "Government", Government!K:K, "Level 2") -> 2 | E17: =COUNTIFS(Government!C:C, "REGION 11", Government!H:H, "Government", Government!K:K, "Level 3") -> 2 | F17: =sum(C17:E17) -> 13 | G17: =COUNTIFS(Private!C:C, "REGION 11", Private!H:H, "Private", Private!K:K, "Level 1") -> 24 | H17: =COUNTIFS(Private!C:C, "REGION 11", Private!H:H, "Private", Private!K:K, "Level 2") -> 20 | I17: =COUNTIFS(Private!C:C, "REGION 11", Private!H:H, "Private", Private!K:K, "Level 3") -> 3 | J17: =SUM(G17:I17) -> 47 | K17: =SUM(C17,G17) -> 33 | L17: =SUM(D17,H17) -> 22 | M17: =SUM(E17,I17) -> 5 | N17: =SUM(K17:M17) -> 60
A18: REGION 12 | B18: SOCCSKSARGEN | C18: =COUNTIFS(Government!C:C, "REGION 12", Government!H:H, "Government", Government!K:K, "Level 1") -> 11 | D18: =COUNTIFS(Government!C:C, "REGION 12", Government!H:H, "Government", Government!K:K, "Level 2") -> 7 | E18: =COUNTIFS(Government!C:C, "REGION 12", Government!H:H, "Government", Government!K:K, "Level 3") -> 1 | F18: =sum(C18:E18) -> 19 | G18: =COUNTIFS(Private!C:C, "REGION 12", Private!H:H, "Private", Private!K:K, "Level 1") -> 43 | H18: =COUNTIFS(Private!C:C, "REGION 12", Private!H:H, "Private", Private!K:K, "Level 2") -> 18 | I18: =COUNTIFS(Private!C:C, "REGION 12", Private!H:H, "Private", Private!K:K, "Level 3") -> 2 | J18: =SUM(G18:I18) -> 63 | K18: =SUM(C18,G18) -> 54 | L18: =SUM(D18,H18) -> 25 | M18: =SUM(E18,I18) -> 3 | N18: =SUM(K18:M18) -> 82
A19: REGION 13 | B19: CARAGA | C19: =COUNTIFS(Government!C:C, "REGION 13", Government!H:H, "Government", Government!K:K, "Level 1") -> 10 | D19: =COUNTIFS(Government!C:C, "REGION 13", Government!H:H, "Government", Government!K:K, "Level 2") -> 3 | E19: =COUNTIFS(Government!C:C, "REGION 13", Government!H:H, "Government", Government!K:K, "Level 3") -> 1 | F19: =sum(C19:E19) -> 14 | G19: =COUNTIFS(Private!C:C, "REGION 13", Private!H:H, "Private", Private!K:K, "Level 1") -> 5 | H19: =COUNTIFS(Private!C:C, "REGION 13", Private!H:H, "Private", Private!K:K, "Level 2") -> 7 | I19: =COUNTIFS(Private!C:C, "REGION 13", Private!H:H, "Private", Private!K:K, "Level 3") -> 0 | J19: =SUM(G19:I19) -> 12 | K19: =SUM(C19,G19) -> 15 | L19: =SUM(D19,H19) -> 10 | M19: =SUM(E19,I19) -> 1 | N19: =SUM(K19:M19) -> 26
A20: NIR | B20: NEGROS ISLAND REGION | C20: =COUNTIFS(Government!C:C, "NIR", Government!H:H, "Government", Government!K:K, "Level 1") -> 16 | D20: =COUNTIFS(Government!C:C, "NIR", Government!H:H, "Government", Government!K:K, "Level 2") -> 2 | E20: =COUNTIFS(Government!C:C, "NIR", Government!H:H, "Government", Government!K:K, "Level 3") -> 1 | F20: =sum(C20:E20) -> 19 | G20: =COUNTIFS(Private!C:C, "NIR", Private!H:H, "Private", Private!K:K, "Level 1") -> 5 | H20: =COUNTIFS(Private!C:C, "NIR", Private!H:H, "Private", Private!K:K, "Level 2") -> 8 | I20: =COUNTIFS(Private!C:C, "NIR", Private!H:H, "Private", Private!K:K, "Level 3") -> 4 | J20: =SUM(G20:I20) -> 17 | K20: =SUM(C20,G20) -> 21 | L20: =SUM(D20,H20) -> 10 | M20: =SUM(E20,I20) -> 5 | N20: =SUM(K20:M20) -> 36
A21: CAR | B21: CORDILLERA | C21: =COUNTIFS(Government!C:C, "CORDILLERA", Government!H:H, "Government", Government!K:K, "Level 1") -> 11 | D21: =COUNTIFS(Government!C:C, "CORDILLERA", Government!H:H, "Government", Government!K:K, "Level 2") -> 4 | E21: =COUNTIFS(Government!C:C, "CORDILLERA", Government!H:H, "Government", Government!K:K, "Level 3") -> 1 | F21: =sum(C21:E21) -> 16 | G21: =COUNTIFS(Private!C:C, "CORDILLERA", Private!H:H, "Private", Private!K:K, "Level 1") -> 10 | H21: =COUNTIFS(Private!C:C, "CORDILLERA", Private!H:H, "Private", Private!K:K, "Level 2") -> 3 | I21: =COUNTIFS(Private!C:C, "CORDILLERA", Private!H:H, "Private", Private!K:K, "Level 3") -> 1 | J21: =SUM(G21:I21) -> 14 | K21: =SUM(C21,G21) -> 21 | L21: =SUM(D21,H21) -> 7 | M21: =SUM(E21,I21) -> 2 | N21: =SUM(K21:M21) -> 30
A22: BARMM | B22: MOH - BARMM | C22: =COUNTIFS(Government!C:C, "BARMM", Government!H:H, "Government", Government!K:K, "Level 1") -> 13 | D22: =COUNTIFS(Government!C:C, "BARMM", Government!H:H, "Government", Government!K:K, "Level 2") -> 1 | E22: =COUNTIFS(Government!C:C, "BARMM", Government!H:H, "Government", Government!K:K, "Level 3") -> 0 | F22: =sum(C22:E22) -> 14 | G22: =COUNTIFS(Private!C:C, "BARMM", Private!H:H, "Private", Private!K:K, "Level 1") -> 12 | H22: =COUNTIFS(Private!C:C, "BARMM", Private!H:H, "Private", Private!K:K, "Level 2") -> 0 | I22: =COUNTIFS(Private!C:C, "BARMM", Private!H:H, "Private", Private!K:K, "Level 3") -> 0 | J22: =SUM(G22:I22) -> 12 | K22: =SUM(C22,G22) -> 25 | L22: =SUM(D22,H22) -> 1 | M22: =SUM(E22,I22) -> 0 | N22: =SUM(K22:M22) -> 26
A23: Total No. of Hospitals: | C23: =sum(C5:C22) -> 331 | D23: =sum(D5:D22) -> 77 | E23: =sum(E5:E22) -> 63 | F23: =sum(F5:F22) -> 471 | G23: =SUM(G5:G22) -> 453 | H23: =SUM(H5:H22) -> 351 | I23: =SUM(I5:I22) -> 61 | J23: =sum(G23:I23) -> 865 | K23: =SUM(K5:K22) -> 784 | L23: =SUM(L5:L22) -> 428 | M23: =SUM(M5:M22) -> 124 | N23: =SUM(F23,J23) -> 1336
A28: REGION | B28: GOVERNMENT | D28: PRIVATE
B29: GENERAL | C29: SPECIALTY | D29: GENERAL | E29: SPECIALTY | G29: l1 | H29: =C23+G23 -> 784
G30: l2 | H30: =D23+H23 -> 428
A31: NCR | G31: l3 | H31: =E23+I23 -> 124
A32: REGION 1 | H32: =sum(H29:H31) -> 1336
A33: REGION 2
A34: REGION 3
A35: REGION 4-A
A36: REGION 4-B
A37: REGION 5
A38: REGION 6
A39: REGION 7
A40: REGION 8 | I40: (
A41: REGION 9
A42: REGION 10
A43: REGION 11
A44: REGION 12
A45: REGION 13
...

Sheet Government
A1: # | B1: NHFR CODE | C1: REGION | D1: PROVINCE | E1: CITY/ MUNICIPALITY | F1: BLDG OR HOUSE NO., STREET, BRGY (as applicable) | G1: NAME OF HOSPITAL | H1: OWNERSHIP | I1: OWNERSHIP CLASS | J1: CLASS | K1: SERVCE CAPABILITY | L1: ABC | M1: ADD-ONS SERVICES | N1: BLOOD SERVICE FACILITY (Service Capability) | O1: rHIV Confirmatory Laboratory | P1: AMBULANCE (No./ TYPE / PLATE NO.) Pls. Seperate if different Type | Q1: TOTAL NO. OF AMBULANCE (TYPE 1) | R1: TOTAL NO. OF AMBULANCE (TYPE 2) | S1: TOTAL NO. OF AMBULANCE | T1: NAME OF AMBULANCE SERVICE PROVIDER IF W/ MOA | U1: NO OF DIALYSIS STATION (If Applicable) | V1: NAME OF DIALYSIS PROVIDER (If Applicable) | W1: CTF CLASSIFICATION (If Applicable) | X1: CLINICAL LAB CLASSIFICATION (If Applicable) | Y1: MEDICAL DIRECTOR/ CHIEF OF HOSPITAL | Z1: CONTACT NOS. | AA1: E-MAIL ADDRESS | AB1: VALIDITY FROM | AC1: VALIDITY UNTIL | AD1: LICENSE NO. | AE1: APPLICATION STATUS | AF1: APPLICATION STATUS (IF WITH CHANGES) | AG1: REMARKS
A2: 1 | B2: 00023 | C2: REGION 1 | D2: Ilocos Norte | E2: Bangui | F2: Brgy. Abaca | G2: BANGUI DISTRICT HOSPITAL | H2: Government | I2: LGU | J2: General | K2: Level 1 | L2: 25 | N2: Blood Station | O2: No | P2: 2, 1, Type 1, Plate No. SNA 7900, CR No. 0006909396 1, Type 1, Plate No. SND 7359, CR No. 41760608-1 | Q2: 2 | R2: N/A | S2: 2 | T2: N/A | U2: N/A | V2: N/A | W2: N/A | X2: Secondary | Y2: Dr. Elvin Chester S. Alcoriza | Z2: 9204689353 | AA2: banguidh@gmail.com | AB2: 46023 | AC2: 46387 | AD2: 01-0024-26-H1-1 | AE2: Renewal | AF2: N/A
A3: 2 | B3: 02593 | C3: REGION 1 | D3: Ilocos Norte | E3: Batac | F3: Barangay 6, San Julian, Batac, Ilocos Norte | G3: MARIANO MARCOS MEMORIAL HOSPITAL AND MEDICAL CENTER | H3: Government | I3: DOH RETAINED | J3: General | K3: Level 3 | L3: 400 | M3: Dialysis Clinic (18 stations) Blood Bank (with additional function to collect, test & process blood) G6PD Confirmatory rHIVda Confirmatory Laboratory HIV Testing Laboratory Specialized Diagnostic X-ray Services (Computed Tomography, Mammography, Bone Densitometry) Dental X-Ray Services (Panoramic & Cephalometric) | N3: Blood Bank with additional function | O3: Yes | P3: 1. Type 2, Plate No. 130109, CR No. 0000138877 2. Type 2, Plate No. NCC 3199, CR No. 311617261 3. Type 2, Plate No. 130209 CR No. 40521664-1 4. Type 2, Plate No. SND 5647, CR No. 177609202 | R3: 4 | S3: 4 | U3: 18 | V3: N/A | X3: Tertiary | Y3: Dr. Maria Lourdes K. Otayza | Z3: 077-600-8000 | AA3: mmmh_doh@yahoo.com | AB3: 46023 | AC3: 46387 | AD3: 01-0004-26-L3-1 | AE3: Renewal | AF3: N/A | AG3: DECENTRALIZED TO ILOCOS CHD (EFFECTIVE JANUARY 2025)
A4: 3 | B4: 02073 | C4: REGION 1 | D4: Ilocos Norte | E4: Laoag City | F4: Brgy. 23 San Matias, P. Gomez St. | G4: GOV. ROQUE B. ABLAN SR. MEMORIAL HOSPITAL | H4: Government | I4: LGU | J4: General | K4: Level 2 | L4: 100 | M4: Blood Station, HIV Testing Lab, Specialized Diagnostic X-ray Services:Computed Tomography Dialysis | N4: Blood Station | P4: 1, TYPE 2, Plate No. 130102 CR No. 0006914752 | R4: 1 | S4: 1 | U4: 6 | V4: N/A | X4: Tertiary | Y4: Dr. Arlene G. Ragasa | Z4: 772-0303 | AA4: pho_grbasmh@yahoo.com | AB4: 46023 | AC4: 46387 | AD4: 01-0026-26-H2-1 | AE4: Renewal | AF4: Add-on Service | AG4: Add-on (DIALYSIS-6 stations)
A5: 4 | B5: 00611 | C5: REGION 1 | D5: Ilocos Norte | E5: Laoag City | F5: Brgy. 46 Nalbo | G5: LAOAG CITY GENERAL HOSPITAL | H5: Government | I5: LGU | J5: General | K5: Level 1 | L5: 50 | M5: HIV Testing Lab. Blood Station Diagnostic x-ray (Level 3) Clinical Chemistry: Troponin-I, Troponin-T, HbA1c, CK-MB, Calcium, Phosphorus, Magnesium, Lactate Dehydrogenase (LDH), Alkaline Phosphatase (ALP) Immunology/Serology: Prostate-Specific Antigen (PSA), TSH, FT3, FT4 Others: Arterial Blood Gas (ABG) | N5: Blood Station | O5: No | P5: 1, Type 1, Plate No. SHY 134, CR No. 6354465-5 | Q5: 1 | R5: N/A | S5: 1 | T5: N/A | U5: 4 | V5: N/A | W5: N/A | X5: Secondary | Y5: Dr. Marsha Lou A. Wapan | Z5: 077-670-6304 09955817054 09338708355 | AA5: lcgh_lc@yahoo.com | AB5: 46023 | AC5: 46387 | AD5: 01-0046-26-H1-1 | AE5: Existing with Changes | AF5: Add-on Service | AG5: Add-on: Clinical Chemistry: Troponin-I, Troponin-T, HbA1c, CK-MB, Calcium, Phosphorus, Magnesium, Lactate Dehydrogenase (LDH), Alkaline Phosphatase (ALP) Immunology/Serology: Prostate-Speficic Antigen (PSA), TSH, FT3, FT4 Others: Arterial Blood Gas (ABG) Issued LTO (03/31/25)
A6: 5 | B6: 05358 | C6: REGION 1 | D6: Ilocos Sur | E6: Candon City | F6: San. Nicolas | G6: CITY OF CANDON HOSPITAL (Dr. Ricardo R. Gacula Memorial Medical Center) | H6: Government | I6: LGU | J6: General | K6: Level 2 | L6: 25 | M6: Specialized Diagnostic X-ray Services:Computed Tomography (City of Candon Doctors, Inc) Dialysis Clinic. | N6: Blood Station | P6: 1, Type2, Conduction Sticker No. P6 B441, CR No. 405214805 | R6: 1 | S6: 1 | U6: 12 | V6: N/A | X6: Tertiary | Y6: Dr. Archimedes A. Mercado | Z6: 742-5675 | AA6: cityofcandonhospital@ yahoo.com | AB6: 46023 | AC6: 46387 | AD6: 01-0013-26-H2-1 | AE6: Renewal | AF6: Add-on Service
A7: 6 | B7: 43601 | C7: REGION 1 | D7: Ilocos Sur | E7: Candon City | F7: Parioc Primero | G7: ILOCOS SUR MEDICAL CENTER | H7: Government | I7: DOH RETAINED | J7: General | K7: Level 2 | L7: 200 | M7: Dialysis Rapid HIV Diagnostic Algorithm Blood Bank wiht additional functions Specialized Diagnostic X-ray Services:Computed Tomography Anatomical Pathology (Surgical, Cytology and Frozen Section) Magnetic Resonance Imaging | N7: Blood Bank with additional function | O7: Yes | P7: 1, Type II, CS No. P8 D518 CR No. 437704610 | R7: 1 | S7: 1 | T7: City of Candon Hospital | U7: 12 | V7: N/A | X7: Tertiary | Y7: Dr. Angel D. Trinidad | Z7: 9164976615 | AA7: mcc@ismc.doh.gov.ph | AB7: 46023 | AC7: 46387 | AD7: 01-0016-26-H2-1 | AE7: Renewal | AF7: N/A
A8: 7 | B8: 00431 | C8: REGION 1 | D8: Ilocos Sur | E8: Cervantes | F8: National Road, Rosario | G8: ILOCOS SUR DISTRICT HOSPITAL-BESSANG PASS CERVANTES | H8: Government | I8: LGU | J8: General | K8: Level 1 | L8: 25 | N8: Blood Station | O8: No | P8: N/A | Q8: N/A | R8: N/A | S8: 0 | T8: Luis Hora Regional Memorial Hospital | U8: N/A | V8: N/A | W8: N/A | X8: Secondary | Y8: Dr. Theresa A. Basabas | Z8: 9090775565 | AA8: bessangpassmemorialhospital@yahoo.com | AB8: 46023 | AC8: 46387 | AD8: 01-0003-26-H1-1 | AE8: Renewal | AF8: N/A
A9: 8 | B9: 00281 | C9: REGION 1 | D9: Ilocos Sur | E9: Magsingal | F9: Sta. Monica | G9: ILOCOS SUR DISTRICT HOSPITAL-MAGSINGAL | H9: Government | I9: LGU | J9: General | K9: Level 1 | L9: 25 | M9: Clinical Chemistry: Magnesium, Phosphorus, Total Bilirubin, Total Protein, Albumin, Alkaline Phosphatase (ALP), Lactate Dehydrogenase (LDH), Anti-HBS Rapid Test Kit, Troponin- I, HbA1c Immunology/Serology: CTnI/CK-MB/Myo Triple Cardiac Markers, TSH, FT4, FT3, T3, T4, Prostate Specific Antigen (PSA), C-Reactive Protein (CRP) | N9: Blood Station | O9: No | P9: 1, Type 1, Plate No. GB 7112, CR No. 262898296 | Q9: 1 | R9: N/A | S9: 1 | T9: N/A | U9: N/A | V9: N/A | W9: N/A | X9: Secondary | Y9: Dr. Mirtle Ruth Ato-Tanawit | Z9: 077-604-0577 09361982146 | AA9: hospitalmagsingaldistrict@yahoo.com | AB9: 46023 | AC9: 46387 | AD9: 01-0019-26-H1-1 | AE9: Existing with Changes | AF9: Add-on Service | AG9: Add-on: Clinical Chemistry: Magnesium, Phosphorus, Total Bilirubin, Total Protein, Albumin, Alkaline Phosphatase (ALP), Lactate Dehydrogensae (LDH), Anti-HBS Rapid Test Kit, Troponin-I, HbA1c Imunology/Serology: CTnI/CK-MB/Myo Triple Cardiac Markers, TSH, FT4, FT3, T3, T4, Prostate Specific Antigen (PSA), C-Reactive Protein (CRP) Issued LTO (05-28-25)
A10: 9 | B10: 04036 | C10: REGION 1 | D10: Ilocos Sur | E10: Narvacan | F10: Paratong | G10: ILOCOS SUR DISTRICT HOSPITAL-NARVACAN | H10: Government | I10: LGU | J10: General | K10: Level 1 | L10: 50 | M10: Clinical Chemistry Examinations: Lipase, HbA1c,Amylase, ALP, LDH, Albumin, Bilirubin (DIrect & Total), Total Protein, Total Calcium, Ionized Calcium, Ionized Magnesium Machine-based Serological and Immunological Testing: Troponin I (Quantitative & Qualitative), CEA, CA-125, Thyroid Function Tests (TSH, FT4, FT3, T4, T3), Cardiac Triple (Quantitative), HCV (Rapid), CRP (Quantitative) | N10: Blood Station | O10: Yes | P10: 2, Type 1, Plate No. SAA 5184, CR No. 236646292 Type 1, Plate No. F4K411, CR No. 431831864 | Q10: 2 | R10: N/A | S10: 2 | T10: N/A | U10: N/A | V10: N/A | W10: N/A | X10: Secondary | Y10: Dr. Junardin B. Soliven | Z10: 077-604-0271 09172172115 09060215440 | AA10: cisdhhospital@yahoo.com | AB10: 46023 | AC10: 46387 | AD10: 01-0005-26-H1-1 | AE10: Renewal | AF10: N/A
A11: 10 | B11: 02463 | C11: REGION 1 | D11: Ilocos Sur | E11: Santa Lucia | F11: National Highway, San Juan | G11: ILOCOS SUR DISTRICT HOSPITAL-STA LUCIA | H11: Government | I11: LGU | J11: General | K11: Level 1 | L11: 25 | M11: HIV Testing Laboratory Clinical Chemistry: HBA1c Immunological Testing: Troponin -I Qualitative and Quantitative | N11: Blood Station | O11: No | P11: N/A | Q11: N/A | R11: N/A | S11: 0 | T11: ISDH- Narvacan | U11: N/A | V11: N/A | W11: N/A | X11: Secondary | Y11: Dr. Winston Jake P. Etalin | Z11: 09209141967 09151633280 | AA11: staluciadistricthospital@yahoo.com.ph | AB11: 46023 | AC11: 46387 | AD11: 01-0029-26-H1-1 | AE11: Renewal | AF11: N/A
A12: 11 | B12: 00254 | C12: REGION 1 | D12: Ilocos Sur | E12: Sinait | F12: Maharlika Highway, Brgy. Curtin | G12: ILOCOS SUR DISTRICT HOSPITAL-SINAIT | H12: Government | I12: LGU | J12: General | K12: Level 1 | L12: 25 | M12: HIV Testing Laboratory Clinical Chemistry: HbA1c, Amylase, Total protein,Total Billirubin,Direct Billirubin, Albumin Serological and Immunological Testing: Cardiac Markers, Troponin I, CK-MB, Tumor Marker, Beta HCG, Thyroid Function Test | N12: Blood Station | O12: Yes | P12: N/A | Q12: N/A | R12: N/A | S12: 0 | T12: LGU San Juan, Ilocos Sur | U12: N/A | V12: N/A | W12: N/A | X12: Secondary | Y12: Dr. Porfirio D. Tugas Jr. | Z12: 9175700940 | AA12: isdhsinait@gmail.com | AB12: 46023 | AC12: 46387 | AD12: 01-0009-26-H1-1 | AE12: Renewal | AF12: N/A
A13: 12 | B13: 03212 | C13: REGION 1 | D13: Ilocos Sur | E13: Tagudin | F13: Bio | G13: ILOCOS SUR DISTRICT HOSPITAL-TAGUDIN | H13: Government | I13: LGU | J13: General | K13: Level 1 | L13: 50 | M13: Clinical Chemistry: HbA1c Immunological & Serological Testing: TSH,T3,T4 | N13: Blood Station | O13: No | P13: N/A | Q13: N/A | R13: N/A | S13: 0 | T13: Ilocos Sur Medical Center | U13: N/A | V13: N/A | W13: N/A | X13: Secondary | Y13: Dr. Julianito L. Bona | Z13: 077-748-7015 / 09190977594 | AA13: tagudin_hospital@yahoo.com | AB13: 46023 | AC13: 46387 | AD13: 01-0006-26-H1-1 | AE13: Renewal | AF13: N/A
A14: 13 | B14: 05002 | C14: REGION 1 | D14: Ilocos Sur | E14: Vigan City | F14: Quirino Blvd. Tamag | G14: ILOCOS SUR PROVINCIAL HOSPITAL GABRIELA SILANG | H14: Government | I14: LGU | J14: General | K14: Level 2 | L14: 100 | M14: Blood Bank (with additional function to collect, test & process blood) HIV Testing LAboratory Rapid HIV Didagnostic Algorithm (rHIVda) Dialysis (5 stastions) Diagnostic X-Ray Services (Level 3) Specialized Diagnostic X-ray Services:Computed Tomography, Mamography Dental X-ray Services: Panoramic Magnetic Resonance Imaging Covid-19 (SARS-CoV-2) Resting Laboratory, artridge-based polymerase chain reaction Molecular Pathology | N14: Blood Bank with additional function | O14: Yes | P14: 1, Type 2, Plate No. NEV 8246 CR No: 436875445 | R14: 1 | S14: 1 | U14: 3 | V14: N/A | X14: Tertiary | Y14: Dr. Enrique Pocholo Baquiran | Z14: 674-1813 | AA14: pho_gabriela@yahoo.com | AB14: 46023 | AC14: 46387 | AD14: 01-0026-26-H2-1 | AE14: Renewal | AF14: N/A
A15: 14 | B15: 02877 | C15: REGION 1 | D15: La Union | E15: Agoo | F15: Nazareno | G15: LA UNION MEDICAL CENTER | H15: Government | I15: LGU | J15: General | K15: Level 2 | L15: 100 | M15: Blood bank (with additional function to collect, test & process blood) HIV Testing LAboratory, Pharmacy (2) Specialized Diagnostic X-ray Services:Computed Tomography | N15: Blood Bank with additional function | P15: 2, Type 2, Plate No: SAA 2076 CR No. 214787510 CS: MU 3982 CR No: 342082996 | R15: 2 | S15: 2 | V15: N/A | X15: Tertiary | Y15: Dr. Sarah Jane Villanueva | Z15: 607-5938 09273298668 | AA15: lumc_official02@yahoo.com | AB15: 46023 | AC15: 46387 | AD15: 01-0003-26-H2-1 | AE15: Renewal | AF15: N/A
A16: 15 | B16: 03199 | C16: REGION 1 | D16: La Union | E16: Bacnotan | F16: Poblacion | G16: BACNOTAN DISTRICT HOSPITAL | H16: Government | I16: LGU | J16: General | K16: Level 1 | L16: 25 | M16: Clinical Chemistry: Troponin-I, HbA1c Immunology/Serology: TSH, T3, T4, C-Reactive Protein (CRP) | N16: Blood Station | O16: No | P16: 2, Type 1, Plate No. MU 3987, CR No. 342144924 & Plate No. SAA 2072, CR No. 212396240 | Q16: 2 | R16: N/A | S16: 2 | T16: N/A | U16: N/A | V16: N/A | W16: N/A | X16: Secondary | Y16: Dr. Zenserly D. Pagaduan | Z16: 072-607-4044 / 09171734922 | AA16: bdh_bacnotan@yahoo.com | AB16: 46023 | AC16: 46387 | AD16: 01-0032-26-H1-1 | AE16: Existing with Changes | AF16: Add-on Service | AG16: Add-on: Clinical Chemistry: Troponin-I, HbA1c Immunology/Serology: TSH, T3, T4, C-Reactive Protein (CRP) Issued LTO (12/22/2025)
A17: 16 | B17: 03432 | C17: REGION 1 | D17: La Union | E17: Balaoan | F17: Bungol | G17: BALAOAN DISTRICT HOSPITAL | H17: Government | I17: LGU | J17: General | K17: Level 1 | L17: 25 | N17: Blood Station | O17: No | P17: 2, Type I, Plate No. NU3951, CR No. 342083044, & Plate No. SAA 2078, CR No. 214788674 | Q17: 2 | R17: N/A | S17: 2 | T17: N/A | U17: N/A | V17: N/A | W17: N/A | X17: Secondary | Y17: Dr. Mark Anthony S. Tomboc | Z17: 072-607-1186 0970-654-8805 | AA17: bldh.balaoan@gmail.com | AB17: 46023 | AC17: 46387 | AD17: 01-0012-26-H1-1 | AE17: Renewal | AF17: N/A
A18: 17 | B18: 02952 | C18: REGION 1 | D18: La Union | E18: Caba | F18: Poblacion Sur | G18: CABA DISTRICT HOSPITAL | H18: Government | I18: LGU | J18: General | K18: Level 1 | L18: 15 | M18: HAV IgG/IgM, S. typhi, Leptospira test, HbA1c | N18: Blood Station | O18: No | P18: 2,Type I, Plate No. SAA2077, CR No. 214787591 & Plate No. MU 4887, CR No. 342083011 | Q18: 2 | R18: N/A | S18: 2 | T18: N/A | U18: N/A | V18: N/A | W18: N/A | X18: Secondary | Y18: Dr. Antonio L. Valdriz Jr. | Z18: 09125559918 09564817840 | AA18: cdh@launion.gov.ph | AB18: 46023 | AC18: 46387 | AD18: 01-0030-26-H1-1 | AE18: Existing with Changes | AF18: Add-on Service | AG18: Add on: Immunology/Serology: HAV IgG/IgM, S. typhi, Leptospira test, HbA1c Issued LTO (03/06/2026)
A19: 18 | B19: 03757 | C19: REGION 1 | D19: La Union | E19: Naguilian | F19: Natividad | G19: NAGUILIAN DISTRICT HOSPITAL | H19: Government | I19: LGU | J19: General | K19: Level 1 | L19: 25 | M19: Clinical Chemistry: HbA1c, Troponin-I Immunology/Serology: Typhoid test kit, Leptospira, Anti-HAV Rapid Test Kit | N19: Blood Station | O19: No | P19: 2,Type I, Plate No. MU 3971, CR No. 342083022 & Plate no. SAA 2069, CR No. 219396203 | Q19: 2 | R19: N/A | S19: 2 | T19: N/A | U19: N/A | V19: N/A | W19: N/A | X19: Secondary | Y19: Dr. Cinderella P. Florendo | Z19: 072-609-1853 / 09209696745 | AA19: ndh@launion.gov.ph | AB19: 46023 | AC19: 46387 | AD19: 01-0048-26-H1-1 | AE19: Existing with Changes | AF19: Add-on Service | AG19: Add-on: Clinical Chemistry: HbA1c, Troponin-I Immunology/Serology: Typhoid test kit, Leptospira, Anti-HAV Rapid Test Kit Issued LTO (10/24/2025)
A20: 19 | B20: 04628 | C20: REGION 1 | D20: La Union | E20: Rosario | F20: Concepcion | G20: ROSARIO DISTRICT HOSPITAL | H20: Government | I20: LGU | J20: General | K20: Level 1 | L20: 25 | M20: HIV Testing Laboratory | N20: Blood Station | O20: No | P20: 1, Type 1, Plate No. SAA 2070, CR No. 212396225 | Q20: 1 | R20: N/A | S20: 1 | T20: N/A | U20: N/A | V20: N/A | W20: N/A | X20: Secondary | Y20: Dr. Michelle D. Arellano | Z20: 072-687-0456/9988 09088101985 | AA20: rdh@launion.gov.ph | AB20: 46023 | AC20: 46387 | AD20: 01-0047-26-H1-1 | AE20: Renewal | AF20: N/A
A21: 20 | B21: 02777 | C21: REGION 1 | D21: La Union | E21: San Fernando City | F21: Barangay Parian, San Fernando City, La Union | G21: ILOCOS TRAINING AND REGIONAL MEDICAL CENTER | H21: Government | I21: DOH RETAINED | J21: General | K21: Level 3 | L21: 306 | M21: Dialysis Clinic (13 stations) G6PD Confirmatory Laboratory HIV Testing Laboratory Laboratory for Drinking Water Analysis Specialized Diagnostic X-ray Services( Computed Tomography) Dental X-ray Services (Peri-apical) COVID-19 Testing Laboratory Clinical Laboratory for Molecular Pathology | N21: Blood Bank with additional function | O21: Yes | P21: 1. Type 2, Plate No. P6 F319, CR No. 39071155-4 2. Type 2, Plate No. F2 1960, CR No. 4318-29296 3. Type 2, Plate No. F4 H390, CR No. 436887371 | Q21: 0 | R21: 3 | S21: 3 | U21: 13 | V21: N/A | X21: Tertiary | Y21: Dr. Unity H. Cortez (OIC-Medical Center Chief II) | Z21: 072-607-6418 09158554459 | AA21: itrmc2010@yahoo.com nmr.itrmc20@gmail.com | AB21: 46023 | AC21: 46387 | AD21: 01-0003-26-L3-1 | AE21: Renewal | AF21: N/A | AG21: DECENTRALIZED TO ILOCOS CHD (EFFECTIVE JANUARY 2025)
A22: 21 | B22: 03374 | C22: REGION 1 | D22: Pangasinan | E22: Alaminos City | F22: Sabaro, Poblacion | G22: WESTERN PANGASINAN DISTRICT HOSPITAL | H22: Government | I22: LGU | J22: General | K22: Level 1 | L22: 75 | M22: HIV Testing Laboratory | N22: Blood Station | O22: No | P22: 2, Type I, Conduction No.YW 5718, CR No. 241079694 & Plate No. F4A487, CR No. 39410462-0 | Q22: 2 | R22: N/A | S22: 2 | T22: N/A | U22: 10 | V22: N/A | W22: N/A | X22: Secondary | Y22: Dr. Ma. Teresa G. Sanchez | Z22: 075-632-3810 | AA22: wpdhalaminosnew@yahoo.com | AB22: 46023 | AC22: 46387 | AD22: 01-0004-26-H1-1 | AE22: Renewal | AF22: N/A
A23: 22 | B23: 38481 | C23: REGION 1 | D23: Pangasinan | E23: Asingan | F23: Bypass Road, Dupac | G23: ASINGAN COMMUNITY HOSPITAL (SANTIAGO ABELLA GINEZ SR. MEM'L HOSPITAL) | H23: Government | I23: LGU | J23: General | K23: Level 1 | L23: 24 | M23: Clinical Chemistry: HbA1c Serology and Immunological Testing: Troponin-I | N23: Blood Station | O23: No | P23: 1, Type 1, Plate No. F4J725, CR No. 44964724-3 | Q23: 1 | R23: N/A | S23: 1 | T23: N/A | U23: N/A | V23: N/A | W23: N/A | X23: Secondary | Y23: Dr. Ma. Teresa M. Aquino | Z23: 9176256067 | AA23: asinhosp@yahoo.com | AB23: 46023 | AC23: 46387 | AD23: 01-0018-26-H1-L1 | AE23: Renewal | AF23: N/A
A24: 23 | B24: 04320 | C24: REGION 1 | D24: Pangasinan | E24: Bayambang | F24: Bical Norte | G24: BAYAMBANG DISTRICT HOSPITAL | H24: Government | I24: LGU | J24: General | K24: Level 1 | L24: 89 | M24: Clinical Chemistry, HbA1c, Calcium, Serology and Immunological Testing Thypidot, Troponin I Leptospira Thyroid function Test | N24: Blood Station | O24: No | P24: 1,Type I, Conduction No. S4J507, CR No. 449973985 | Q24: 1 | R24: N/A | S24: 1 | T24: N/A | U24: N/A | V24: N/A | W24: N/A | X24: Secondary | Y24: Dr. Rhonulfo F. Fama | Z24: 075-592-2958 | AA24: bayambang_districthospital80@yahoo.com | AB24: 46023 | AC24: 46387 | AD24: 01-0014-26-H1-L1 | AE24: Existing with Changes | AF24: Add-on Service | AG24: Add-on: Ambulance Service Provider Issued License 04-24-25
A25: 24 | B25: 07479 | C25: REGION 1 | D25: Pangasinan | E25: Bolinao | F25: Sampaloc | G25: BOLINAO COMMUNITY HOSPITAL | H25: Government | I25: LGU | J25: General | K25: Level 1 | L25: 25 | N25: Blood Station | O25: No | P25: 2,Type I, Plate no. YW 2080 & Type I, Conduction No. F4A202, CR No. 39425385 | Q25: 2 | R25: N/A | S25: 2 | T25: N/A | U25: N/A | V25: N/A | W25: N/A | X25: Secondary | Y25: Dr. Genevieve S. Rivera | Z25: 09267271282/ 09778509125 | AA25: bolinao_c_h@ymail.com | AB25: 46023 | AC25: 46387 | AD25: 01-0036-26-H1-1 | AE25: Renewal | AF25: N/A
A26: 25 | B26: 00273 | C26: REGION 1 | D26: Pangasinan | E26: Dagupan City | F26: Arellano St., Dagupan City | G26: REGION 1 MEDICAL CENTER | H26: Government | I26: DOH RETAINED | J26: General | K26: Level 3 | L26: 300 | M26: Dialysis Clinic (6 stations) G6PD Confirmatory HIV Testing Laboratory Laboratory for Drinking Water Analysis Pharmacy (2) Acute-Chronic Psychiatric Care Facility -16 beds Specialized Diagnostic X-ray Services (Computed Tomography, mammography, digital subtraction angiography) Dental X-Ray Services (Panoramic, Cephalometric, Peri-apical ) | N26: Blood Bank | O26: Yes | P26: 1. Type 2, Plate No. 010101, CR No. 334607943 2. Type 2, Plate No. NAK 4485, CR No. 338808525 3. Type 2, Plate No. 130109, CR No. 35982830-2 4. Type 2, Plate No. 130106, CR No. 38609095-0 | Q26: 0 | R26: 4 | S26: 4 | U26: 6 | V26: N/A | X26: Tertiary | Y26: Dr. Joseph Roland O. Mejia | Z26: 075-515-89-16 | AA26: region1mc@gmail.com | AB26: 46023 | AC26: 46387 | AD26: 01-0002-26-L3-1 | AE26: Renewal | AF26: N/A | AG26: DECENTRALIZED TO ILOCOS CHD (EFFECTIVE JANUARY 2025)
A27: 26 | B27: 00475 | C27: REGION 1 | D27: Pangasinan | E27: Dasol | F27: Bobonot | G27: DASOL COMMUNITY HOSPITAL (COL. DOMINGO A. VALDEZ MEMORIAL HOSPITAL) | H27: Government | I27: LGU | J27: General | K27: Level 1 | L27: 20 | N27: Blood Station | O27: No | P27: 1, Type I, Plate no. SND 6129, CR No. 39410463-1 | Q27: 1 | R27: N/A | S27: 1 | T27: N/A | U27: N/A | V27: N/A | W27: N/A | X27: Secondary | Y27: Dr. Ginalyn R. Malalis | Z27: 9209686860 | AA27: dasolcommunityhospital@gmail.com | AB27: 46023 | AC27: 46387 | AD27: 01-0039-26-H1-1 | AE27: Renewal | AF27: N/A
A28: 27 | B28: 01824 | C28: REGION 1 | D28: Pangasinan | E28: Lingayen | F28: Jimenez St., Poblacion | G28: LINGAYEN DISTRICT HOSPITAL (DON MARIANO C. VERSOZA MEMORIAL HOSPITAL) | H28: Government | I28: LGU | J28: General | K28: Level 1 | L28: 40 | M28: Clinical Chemistry: HbA1c, Troponin- I Immunology/Serology: TSH, FT3, FT4, Leptospira, Typhidot Rapid Tests Kits | N28: Blood Station | O28: No | P28: 2, Type I, Plate No. A4H639 & Plate No. NDR 6077 | Q28: 2 | R28: N/A | S28: 2 | T28: N/A | U28: 13 | V28: N/A | W28: N/A | X28: Secondary | Y28: Dr. Aurelio O. Carino | Z28: 075-542-2295 09223852982 | AA28: ldh_pang@yahoo.com | AB28: 46023 | AC28: 46387 | AD28: 01-0031-26-H1-1 | AE28: Existing with Changes | AF28: Add-on Service | AG28: Add-on: Clinical Chemistry: Troponin- I, HbA1c Immunology/Serology: TSH, FT3, FT4, Leptospira, Typhidot Rapid Tests Kits Issued LTO (03-26-25) Add on Services: Dialysis Clinic: 13 Stations Issued LTO (06-02-25)
A29: 28 | B29: 04280 | C29: REGION 1 | D29: Pangasinan | E29: Manaoag | F29: Baritao | G29: MANAOAG COMMUNITY HOSPITAL | H29: Government | I29: LGU | J29: General | K29: Level 1 | L29: 25 | M29: Clinical Chemistry: HbA1c, Troponin- I | N29: Blood Station | O29: No | P29: 1,Type I, Plate No. 131206, CR No. 35423967-5 | Q29: 1 | R29: N/A | S29: 1 | T29: N/A | U29: N/A | V29: N/A | W29: N/A | X29: Secondary | Y29: Dr. Donn P. Doria | Z29: 075-5230992 | AA29: manaoagcommunityhospital2013@yahoo.com.ph | AB29: 46023 | AC29: 46387 | AD29: 01-0011-26-H1-1 | AE29: Existing with Changes | AF29: Add-on Service | AG29: Add-on: Clinical Chemistry: HbA1c, Troponin-I Issued LTO (06-11-25)
A30: 29 | B30: 022132 | C30: REGION 1 | D30: Pangasinan | E30: Mangatarem | F30: Casilagan | G30: MANGATAREM DISTRICT HOSPITAL | H30: Government | I30: LGU | J30: General | K30: Level 1 | L30: 25 | M30: Specialized Diagnostic X-ray Services: Computed Tomography | N30: Blood Station | O30: No | P30: 3,Type I, Plate No. YX 0377, CR No. 241274740, Plate No. 13120, CR No. 35423970-1 & CR No. 4497400-0, Conduction Sticker S4H111 | Q30: 3 | R30: N/A | S30: 3 | T30: N/A | U30: N/A | V30: N/A | W30: N/A | X30: Secondary | Y30: Dr. Eusebio DG. Sison | Z30: 9688703888 | AA30: mangataremdistricthospital@gmail.com | AB30: 46023 | AC30: 46387 | AD30: 01-0022-26-H1-1 | AE30: Renewal | AF30: N/A
A31: 30 | B31: 00243 | C31: REGION 1 | D31: Pangasinan | E31: Mapandan | F31: 24 Fire Tree St. Poblacion | G31: MAPANDAN COMMUNITY HOSPITAL | H31: Government | I31: LGU | J31: General | K31: Level 1 | L31: 20 | M31: Clinical Chemistry: HbA1c, Troponin- I Immunology/Serology: H. pylori test, Typhidot, T3, T4, FT3, FT4, TSH | N31: Blood Station | O31: No | P31: 1,Type I, Conduction Sticker F4-J720, CR No. 283263466 | Q31: 1 | R31: N/A | S31: 1 | T31: N/A | U31: N/A | V31: N/A | W31: N/A | X31: Secondary | Y31: Dr. Pablito G. Banta | Z31: 075-632-0491 | AA31: mapandancommhosp@yahoo.com | AB31: 46023 | AC31: 46387 | AD31: 01-0026-26-H1-1 | AE31: Existing with Changes | AF31: Add-on Service | AG31: Add-on: Clinical Chemistry: HbA1c, Troponin-I Immunology/Serology: H. pylori test, Typhidot, T3, T4, FT3, FT4, TSH Issued LTO (06-19-25)
A32: 31 | B32: 02819 | C32: REGION 1 | D32: Pangasinan | E32: Pozorrubio | F32: Talogtog | G32: POZORRUBIO COMMUNITY HOSPITAL | H32: Government | I32: LGU | J32: General | K32: Level 1 | L32: 44 | M32: Clinical Chemistry: Troponin-I, HbA1c | N32: Blood Station | O32: No | P32: 1,Type I, Plate No. FIR 283 | Q32: 1 | R32: N/A | S32: 1 | T32: N/A | U32: N/A | V32: N/A | W32: N/A | X32: Secondary | Y32: Dr. Agnes Leored D. Rioflorido | Z32: 075-632-3978 | AA32: pozmunhospital@gmail.com | AB32: 46023 | AC32: 46387 | AD32: 01-0002-26-H1-1 | AE32: Existing with Changes | AF32: Add-on Service | AG32: Add-on: Clinical Chemistry: HbA1c, Troponin-I Issued LTO (11/28/2025)
A33: 32 | B33: 43601 | C33: REGION 1 | D33: Pangasinan | E33: Rosales | F33: Government Center Carmay East | G33: CONRADO F. ESTRELLA REGIONAL MEDICAL AND TRAUMA CENTER | H33: Government | I33: DOH RETAINED | J33: General | K33: Level 2 | L33: 103 | M33: Blood Bank with additional function Specialized Diagnostic X-ray Services:Computed Tomography Magnetic Resonance Imaging | N33: Blood Bank with additional function | P33: 1, Type I, Conduction No. F4KH16 CR No: 43183187-5 | R33: 1 | S33: 1 | V33: N/A | X33: Tertiary | Y33: Dr. Emerson B. Patawaran | Z33: 0755296863 / 09177819724 | AA33: cfermtc@gmail.com | AB33: 46023 | AC33: 46387 | AD33: 01-0014-26-H2-1 | AE33: Renewal | AF33: N/A
A34: 33 | B34: 1917 | C34: REGION 1 | D34: Pangasinan | E34: San Carlos City | F34: Bolingit | G34: PANGASINAN PROVINICIAL HOSPITAL | H34: Government | I34: LGU | J34: General | K34: Level 2 | L34: 250 | M34: Blood Bank (with additional function to collect, test & process) HIV Testing Laboratory RApid HIV Diagnostic Algorithm (rHIVda) Dialysis Clinic Specialized Diagnostic X-ray Servicess; Computed Tomography COVID-19 (SARS-COV-2) Testing Laboratory (Pangasinan Molecular Diagnostic Laboratory) Reverse TRanscriptase-Polymerase Chain Reaction | N34: Blood Bank with additional function | O34: Yes | P34: 1, Type 2, CS No: S3 0382 CR No: 44997499-6 | R34: 1 | S34: 1 | U34: 14 | V34: N/A | X34: Tertiary | Y34: Dr. Cipriano Fernandez | Z34: 0933-4637274 | AA34: desu.pph@gmail.com | AB34: 46023 | AC34: 46387 | AD34: 01-0020-26-H2-1 | AE34: Renewal | AF34: N/A
A35: 34 | B35: 5829 | C35: REGION 1 | D35: Pangasinan | E35: Tayug | F35: New Magallanes | G35: EASTERN PANGASINAN DISTRICT HOSPITAL | H35: Government | I35: LGU | J35: General | K35: Level 2 | L35: 150 | M35: Anatomic Pathology (surgical, cytology and frozedn section)Specialized Diagnostic X-ray Services:Computed Tomography | N35: Blood Station | P35: 1. Type 2-ALS Conduction Sticker No. f4 J413 CR No: 44964724-0 | R35: 1 | S35: 1 | V35: N/A | X35: Tertiary | Y35: Dr. Agnes Leored D. Rioflorido | Z35: 0926-3000057 09663204020 | AA35: epdh_tayug@yahoo.com | AB35: 46023 | AC35: 46387 | AD35: 01-0005-26-H2-1 | AE35: Renewal | AF35: N/A
A36: 35 | B36: 02854 | C36: REGION 1 | D36: Pangasinan | E36: Umingan | F36: Burgos St., Poblacion West | G36: UMINGAN COMMUNITY HOSPITAL | H36: Government | I36: LGU | J36: General | K36: Level 1 | L36: 15 | N36: Blood Station | O36: No | P36: 1, Type I, Conduction No. F4 5408, CR No. 44964719-2 | Q36: 1 | R36: N/A | S36: 1 | T36: N/A | U36: N/A | V36: N/A | W36: N/A | X36: Secondary | Y36: Dr. Sonny Edward V. Urbano | Z36: 075-5776-5033 09338198389 | AA36: uminganch@yahoo.com | AB36: 46023 | AC36: 46387 | AD36: 01-0033-26-H1-1 | AE36: Renewal | AF36: N/A
A37: 36 | B37: 00265 | C37: REGION 1 | D37: Pangasinan | E37: Urdaneta | F37: Dilan Paurido | G37: URDANETA DISTRICT HOSPITAL (DON AMADEO J. PEREZ SR. MEMORIAL GENERAL HOSPITAL) | H37: Government | I37: LGU | J37: General | K37: Level 1 | L37: 110 | M37: HIV Testing Laboratory Thyroid Function Test (TSH, FT4, FT3) | N37: Blood Station | O37: No | P37: 2, Type I, Plate No. SND 6115 & Plate No. NDQ 7967 | Q37: 2 | R37: N/A | S37: 2 | T37: N/A | U37: 10 | V37: N/A | W37: N/A | X37: Secondary | Y37: Dr. Arnulfo L. Olivar | Z37: 075-632-6248 | AA37: urdanetadistricthospital@gmail.com | AB37: 46023 | AC37: 46387 | AD37: 01-0028-26-H1-1 | AE37: Renewal | AF37: N/A
A38: 37 | B38: 5201 | C38: REGION 2 | D38: Batanes | E38: Basco | F38: National Road, Kayhuvokan | G38: BATANES GENERAL HOSPITAL | H38: Government | I38: DOH RETAINED | J38: General | K38: Level 2 | L38: 75 | M38: Drug Testing Lab, Pharmacy, Hospital Blood Bank (with additional functions to collect test & process blood) Diagnostic X-ray (Levell 2) , Speciialized Diagnostic X-ray Services: Computed Tamography,Mammography ,Bone Densitometry, Magnetic Resonance Imaging, rHIVda Confirmatory Laboratory, Covid-19 (SARS-CoV 2) Testing Laboratory, Clinical Laboratory for Anatomic PAthology: * Histopathology | N38: Blood Bank with additional function | P38: 2/Type 2/NCF 3752 & Type 2, SNN 3186 | R38: 2 | S38: 2 | U38: 2 | V38: N/A | X38: Tertiary | Y38: Dr. Jeffrey Antony T. Canceran | Z38: 9688573557 | AA38: bataneshospital@gmail.com | AB38: 46023 | AC38: 46387 | AD38: 02-14-26-H1-1 | AE38: Renewal | AF38: N/A | AG38: Additional 1 Type 2 Ambulance Unit- 5/11/2026 (2nd Quarte)
A39: 38 | B39: 07486 | C39: REGION 2 | D39: Cagayan | E39: Aparri | F39: National Highway, Toran | G39: APARRI PROVINCIAL HOSPITAL | H39: Government | I39: Province | J39: General | K39: Level 1 | L39: 50 | M39: Pharmacy, Diagnostic X-ray (Level 1) , Dental Clinic Hormone (AFP, LH, Progestone, FSH) Special Chemistry ( Total Bilirubin, Direct Bilirubin, TP, D-dimer, Alb, Globulin, ALP, C3, HbA1c, Vit. D, Trop I, CK-MB) S;pecial Hematology (ESR) Special Serology (ASO, S. typhi, Leptospira, PSA, CEA, CRP) Thyroid Function Test (TSH, fT3, fT4) | N39: Blood Station | P39: 1/Type 1/CS No. P8P 6970 | Q39: 1 | S39: 1 | V39: N/A | X39: Secondary | Y39: Dr. Diana Rhea V. Garde | Z39: (078) 377-3207 09363718430 | AA39: aparriprovincialhospital@gmail.com | AB39: 46023 | AC39: 46387 | AD39: 02-32-26-H1-1 | AE39: Renewal | AF39: N/A
A40: 39 | B40: 04346 | C40: REGION 2 | D40: Cagayan | E40: Ballesteros | F40: Cabuluan West | G40: BALLESTEROS DISTRICT HOSPITAL | H40: Government | I40: Province | J40: General | K40: Level 1 | L40: 25 | M40: Pharmacy, Diagnostic X-ray (Level 1) | N40: Blood Station | O40: Yes | P40: 1,Type 1/ P8M230 | Q40: 1 | S40: 1 | V40: N/A | X40: Secondary | Y40: Dr. Nicasio M. Galano, Jr. | Z40: 9569451942 | AA40: ballesterosdistricthospital@gmail.com | AB40: 46023 | AC40: 46387 | AD40: 02-40-26-H1-1 | AE40: Renewal | AF40: N/A
...

Sheet Private
B1: NHFR CODE | C1: REGION | D1: PROVINCE | E1: CITY/ MUNICIPALITY | F1: BLDG OR HOUSE NO., STREET, BRGY (as applicable) | G1: NAME OF FACILITY | H1: OWNERSHIP | I1: OWNERSHIP CLASS | J1: CLASS | K1: SERVCE CAPABILITY | L1: ABC | M1: ADD-ONS SERVICES | N1: BLOOD SERVICE FACILITY (Service Capability) | O1: rHIVda Confirmatory Laboratory | P1: AMBULANCE (No./ TYPE / PLATE NO.) Pls. Seperate if different Type | Q1: TOTAL NO. OF AMBULANCE (TYPE 1) | R1: TOTAL NO. OF AMBULANCE (TYPE 2) | S1: TOTAL NO. OF AMBULANCE | T1: NAME OF AMBULANCE SERVICE PROVIDER IF W/ MOA | U1: NO OF DIALYSIS STATION (If Applicable) | V1: CTF CLASSIFICATION (If Applicable) | W1: CLINICAL LAB CLASSIFICATION (If Applicable) | X1: MEDICAL DIRECTOR/ CHIEF OF HOSPITAL | Y1: CONTACT NOS. | Z1: E-MAIL ADDRESS | AA1: VALIDITY FROM | AB1: VALIDITY UNTIL | AC1: LICENSE NO. | AD1: APPLICATION STATUS | AE1: APPLICATION STATUS | AF1: REMARKS
A2: 1 | B2: 03441 | C2: REGION 1 | D2: Ilocos Norte | E2: Bacarra | F2: National Highway, Brgy. 21, Libtong | G2: DR. BONIFACIA V. ALBANO MEMORIAL HOSPITAL | H2: Private | I2: N/A | J2: General | K2: Level 1 | L2: 25 | N2: Blood Station | O2: No | P2: N/A | Q2: N/A | R2: N/A | S2: 0 | T2: Bacarra Municipal Health Office | U2: 6 | V2: N/A | W2: Secondary | X2: Dr. Juanita Marita A. Cua | Y2: 077-670-3142 09495991813 | Z2: bmc_1970@yahoo.com | AA2: 46023 | AB2: 46387 | AC2: 01-0050-26-H1-2 | AD2: Renewal | AE2: N/A
A3: 2 | B3: 01804 | C3: REGION 1 | D3: Ilocos Norte | E3: Batac | F3: Castro St., Brgy 11 Ben-Agan | G3: GAOAT GENERAL HOSPITAL | H3: Private | I3: N/A | J3: General | K3: Level 1 | L3: 16 | N3: Blood Station | O3: No | P3: 1, Type I Plate No. CRR359, CR No. 038600000009042 | Q3: 1 | R3: N/A | S3: 1 | T3: N/A | U3: N/A | V3: N/A | W3: Secondary | X3: Dr. Ramon M. Gaoat | Y3: 077-600-0450 09399129112 | Z3: gaoatgeneralhospital@gmail.com | AA3: 46023 | AB3: 46387 | AC3: 01-0023-26-H1-2 | AD3: Renewal | AE3: N/A
A4: 3 | B4: 17409 | C4: REGION 1 | D4: Ilocos Norte | E4: Laoag City | F4: Legaspi St., Brgy. 29, Sto Tomas | G4: KARMELLI CLINIC & HOSPITAL | H4: Private | I4: N/A | J4: General | K4: Level 1 | L4: 28 | M4: Intensive Care Unit - 8 units | N4: Blood Station | O4: No | P4: N/A | Q4: N/A | R4: N/A | S4: 0 | T4: Philippines Red Cross | U4: N/A | V4: N/A | W4: Tertiary | X4: Dr. Norman Panfilo Rabago | Y4: 077-772-2292/2752; 607-0364; | Z4: karmelliclinic_hospital@yahoo.com | AA4: 46023 | AB4: 46387 | AC4: 01-0049-26-H1-2 | AD4: Renewal | AE4: N/A
A5: 4 | B5: 05640 | C5: REGION 1 | D5: Ilocos Norte | E5: San Nicolas | F5: 29 Bonoan St. Barangay 2 | G5: THE BLACK NAZARENE HOSPITAL INC. | H5: Private | I5: N/A | J5: General | K5: Level 2 | L5: 48 | M5: Specialized Diagnostic X-ray Services:Computed Tomography | N5: Blood Station | P5: 1, Type II, Plate No. AAU 5454 CR No.204141464 | R5: 1 | S5: 1 | U5: 10 | W5: Tertiary | X5: Dr. Jonathan G. Noble | Y5: 9153030906 | Z5: it.tbnhi@gmail.com | AA5: 46023 | AB5: 46387 | AC5: 01-0011-26-H2-2 | AD5: Renewal | AE5: N/A
A6: 5 | B6: 05234 | C6: REGION 1 | D6: Ilocos Sur | E6: Bantay | F6: Roxas Dike | G6: METRO VIGAN HOSPITAL | H6: Private | I6: N/A | J6: General | K6: Level 2 | L6: 80 | M6: HIV Testing Laboratory, Specialized Diagnostic X-ray Services:Computed Tomography (Ilocos Sur CT Scan & Diagnostic Center, Inc.) Mamography Litotripsy | N6: Blood Station | P6: 2, Type2 Plate No: AFC 172 CR No: 13215544-6 Plate No. IAF 9508, CR No. 0003188796 | R6: 2 | S6: 2 | U6: 11 | V6: N/A | W6: Tertiary | X6: Dr. Digna Ragasa | Y6: 0917-8431311 | Z6: metroviganhospital1998@gmail.com | AA6: 46023 | AB6: 46387 | AC6: 01-0002-26-H2-2 | AD6: Renewal | AE6: N/A
A7: 6 | B7: 32085 | C7: REGION 1 | D7: Ilocos Sur | E7: Bantay | F7: Guimod | G7: NORTHSIDE DOCTORS HOSPITAL | H7: Private | I7: N/A | J7: General | K7: Level 2 | L7: 100 | M7: Specialized Diagnostic X-ray Services:Computed Tomography Dialysis | N7: Blood Station | P7: 1,Type 2, IAC 8439 Cr No. 0003130243 | R7: 1 | S7: 1 | U7: 8 | W7: Tertiary | X7: Dr. Rosita P. Rialubin | Y7: 0917-1472661 | Z7: northsidedochosp@yahoo.com | AA7: 46023 | AB7: 46387 | AC7: 01-0028-26-H2-2 | AD7: Renewal | AE7: N/A
A8: 7 | B8: 00343 | C8: REGION 1 | D8: Ilocos Sur | E8: Cabugao | F8: Singson St., Rizal | G8: PIRA HOSPITAL, INC. | H8: Private | I8: N/A | J8: General | K8: Level 1 | L8: 29 | M8: Clinical Chemistry: Troponin-I, HbA1c Immunology/Serology: FT4, T4, TSH, Prostate-Specific Antigen (PSA), C-Reative Protein (CRP) | N8: Blood Station | O8: No | P8: 1, Type I, Plate No. TOG388, CR No. 41786299-2 | Q8: 1 | R8: N/A | S8: 1 | T8: N/A | U8: N/A | V8: N/A | W8: Secondary | X8: Dr. Maria Alejandra Rlyn P. Narcelles | Y8: 077-604-9802 09177125823 | Z8: pirahospital@yahoo.com | AA8: 46023 | AB8: 46387 | AC8: 01-0015-26-H1-2 | AD8: Existing with Changes | AE8: Add-on Service | AF8: Add-on: Clinical Chemistry: HbA1c, Troponin-I Immunology/Serology: TSH, FT4, T4, Prostate Specific Antigen (PSA), C-Reactive Protein (CRP) Issued LTO (7-15-25)
A9: 8 | B9: 07032 | C9: REGION 1 | D9: Ilocos Sur | E9: Cabugao | F9: Manila North Road, Baclig | G9: SUERO GENERAL HOSPITAL | H9: Private | I9: N/A | J9: General | K9: Level 1 | L9: 34 | M9: Clinical Chemistry : Serum, Ca, Billirubin, HbA1c, Albumin, Magnesium, Total Protein, Amylase, B-HCG Immunology and Serology : Troponin 1- Quantitative , Thypidot, TSH, FT4, Prostate-Specific Antigen (PSA), Anti-HCV Rapid Test Kits, Anti-HAV Rapid Test Kits, C-Reative Protein (CRP) | N9: Blood Station | O9: No | P9: 1, Type I, Plate No.CAN 2339 | Q9: 1 | R9: N/A | S9: 1 | T9: N/A | U9: N/A | V9: N/A | W9: Secondary | X9: Dr. Chita S. Suero | Y9: 9178139433 | Z9: suerogenhosp@yahoo.com | AA9: 46023 | AB9: 46387 | AC9: 01-0041-26-H1-2 | AD9: Existing with Changes | AE9: Add-on Service | AF9: Add-on: Clinical Chemistry: Albumin, Magnesium, Total Protein, Calcium, Bililrubin, HbA1c, Amylase , B-HCG Immunology/Serology: TSH, FT4, Prostate-Specific Antigen (PSA), Anti- HCV Rapid Test Kits, Anti-HAV Rapid Test Kits Issued LTO (04-10-25) Add-on: Sars-Cov-2 Issued LTO (11/18/2025) Ambulatory Surgical Clinic (Ophthalmologic Surgery) Issued LTO (12/02/2025)
A10: 9 | B10: 02871 | C10: REGION 1 | D10: Ilocos Sur | E10: Candon City | F10: Tablac | G10: CANDON GENERAL HOSPITAL | H10: Private | I10: N/A | J10: General | K10: Level 1 | L10: 25 | M10: Clinical Chemistry: HbA1c, Amylase, Lipase, Total Bilirubin, Direct and Indirect Bilirubin, Lactate Dehydrogenase, Alkaline Phosphatase, Magnesium, Phosphorus, Total Protein, Albumin, Troponin-I (Qualitative), Troponin-T (Quantitative) Immunology/Serology: Widal, Hepa A (HAV IgM Qualitative), Anti-HCV (Qualitative), Anti HBS (Qualitative), Thyroid Functions (T4, T3, FT3, FT4, TSH) Clinical Microscopy: Micral Test | N10: Blood Station | O10: No | P10: 1, Type I, Plate No. AAS 9640, CR No. 199150630 | Q10: 1 | R10: N/A | S10: 1 | T10: N/A | U10: N/A | V10: N/A | W10: Secondary | X10: Mr. Dino T. Chua | Y10: 077-742-6098 09173151975 | Z10: candongeneralhospital@gmail.com | AA10: 46023 | AB10: 46387 | AC10: 01-0016-26-H1-2 | AD10: Existing with Changes | AE10: Add-on Service | AF10: Add-on: Immunology/Serology: TSH, FT4, FT3, T3, T4 Issued LTO (03-14-25)
A11: 10 | B11: 5976 | C11: REGION 1 | D11: Ilocos Sur | E11: Candon City | F11: Bldg. 33, 25 De Marzo St., San Antonio | G11: CANDON ST. MARTIN DE PORRES HOSPITAL | H11: Private | I11: N/A | J11: General | K11: Level 1 | L11: 51 | M11: Specialized Diagnostic Services (Computed Tomography) Ambulatory Surgical Clinic (Ophthalmologic Surgery) Intensive Care Unit | N11: Blood Station | O11: No | P11: 1, Type I, Plate No. NGD 2563, Conduction No.F3 G662, CR No. 38392438 | Q11: 1 | R11: N/A | S11: 1 | T11: N/A | U11: 6 | V11: N/A | W11: Tertiary | X11: Dr. Modesto A. Pacquing | Y11: 9171096093 | Z11: smphpldt@gmail.com stmartindeporreshospital@yahoo.com | AA11: 46023 | AB11: 46387 | AC11: 01-0025-26-H1-2 | AD11: Renewal | AE11: N/A
A12: 11 | B12: 00359 | C12: REGION 1 | D12: Ilocos Sur | E12: Candon City | F12: 43 Madarang St., San Jose | G12: RESONABLE HOSPITAL | H12: Private | I12: N/A | J12: General | K12: Level 1 | L12: 24 | N12: Blood Station | O12: No | P12: N/A | Q12: N/A | R12: N/A | S12: 0 | T12: N/A | U12: N/A | V12: N/A | W12: Secondary | X12: Dr. Maureen M. Resonable | Y12: 077-742-6461 09175131575 | Z12: resonablehospital2002@gmail.com | AA12: 46023 | AB12: 46387 | AC12: 01-0040-26-H1-2 | AD12: Renewal | AE12: N/A
A13: 12 | B13: 04075 | C13: REGION 1 | D13: Ilocos Sur | E13: Sinait | F13: Maharlika Highway, Brgy. Namnama | G13: CORPUZ CLINIC AND HOSPITAL | H13: Private | I13: N/A | J13: General | K13: Level 1 | L13: 50 | M13: CT-Scan Services Clinical Chemistry: HbA1c, Troponin-I, Magnesium, Phosphorus, Alkaline Phosphate, Ionized Calcium, Amylase, Lipase, Albumin, Total Calcium, Bilirubin (Total, Direct, Indirect) Immunology and Serology: Prostate-Specific Antigen (PSA), Thyroid Profile (TSH, FT4, FT3, T4, T3), C-Reactive Protein (CRP), Procalcitonin (PCT), Anti-Streptolysin O (ASO), Carcinoembryonic Antigen (CEA), CK-MB, PRO-BNP, B- HCG Hematology: D-Dimer Others: Arterial Blood Gas | N13: Blood Station | O13: No | P13: 1, Type I, Plate No. NFO6840, CR No. 46149177-4 | Q13: 1 | R13: N/A | S13: 1 | T13: N/A | U13: N/A | V13: N/A | W13: Secondary | X13: Dr. Martin V. Corpuz | Y13: 09175653740 09175133380 09175653944 09178987025 | Z13: corpuzclinichospital@yahoo.com | AA13: 46023 | AB13: 46387 | AC13: 01-0007-26-H1-2 | AD13: Existing with Changes | AE13: Add-on Service | AF13: Add-on: Clinical Chemistry: Magnesium, Alkaline Phosphatase (ALP), Phosphorus, Ionized Calcium, Amylase, Lipase, Albumin, Total Calcium, Bilirubin, CK-MB, Pro-BNP, B-HCG Immunology/Serology: C-Reactive Protein (CRP), Procalcitonin (PCT), Anti-Streptolysin O (ASO), Carcinoembryonic Antigen (CEA) Hematology: D-Dimer Issued LTO (03-24-25)
A14: 13 | B14: 30122 | C14: REGION 1 | D14: Ilocos Sur | E14: Sinait | F14: National Highway, Tapao | G14: STO. CRISTO MILAGROSO HOSPITAL | H14: Private | I14: N/A | J14: General | K14: Level 1 | L14: 25 | N14: Blood Station | O14: No | P14: 1, Type 1, Plate No. IAG 5495, CR No. 007620471 | Q14: N/A | R14: N/A | S14: 0 | T14: N/A | U14: N/A | V14: N/A | W14: Secondary | X14: Dr. Nanette Q. Yagumyum | Y14: 9171059045 | Z14: stocristomilagrosohospital@gmail.com | AA14: 46023 | AB14: 46387 | AC14: 01-0035-26-H1-2 | AD14: Existing with Changes | AE14: Add-on Service | AF14: Add on: Ambulance Service Provider: 1, Type 1, Plate No. IAG 5495, CR No. 007620471 LTO Issued (01/05/2026)
A15: 14 | B15: 00365 | C15: REGION 1 | D15: Ilocos Sur | E15: Sta. Maria | F15: Simpson St., Poblacion Sur | G15: REYES ULEP CLINIC AND HOSPITAL | H15: Private | I15: N/A | J15: General | K15: Level 1 | L15: 25 | M15: HBA1C Immunology & Serology Troponin -I, Troponin T | N15: Blood Station | O15: No | P15: 1, Type I, Plate No. AFF 436 | Q15: 1 | R15: N/A | S15: 1 | T15: N/A | U15: N/A | V15: N/A | W15: Secondary | X15: Dr. Erwin R. Ulep | Y15: 9669530782 | Z15: reyesulepclinicandhospital@gmail.com | AA15: 46023 | AB15: 46387 | AC15: 01-0010-26-H1-2 | AD15: Renewal | AE15: N/A
A16: 15 | B16: 05694 | C16: REGION 1 | D16: Ilocos Sur | E16: Vigan City | F16: Rizal Street Extension, Brgy. Tamag, | G16: ILOCOS SUR COOPERATIVE MEDICAL MISSION GROUP AND HOSPITAL | H16: Private | I16: N/A | J16: General | K16: Level 1 | L16: 11 | M16: Clinical Chemistry: HbA1c, Ferritin Immunology/Serology: TSH, FT4, FT3, Prostate-Specific Antigen (PSA), Troponin-I, Anti-HAV Rapid Test Kits, HAV IgM, Salmonella Typhi Rapid Test Kit | N16: Blood Station | O16: No | P16: N/A | Q16: N/A | R16: N/A | S16: 0 | T16: Metro Vigan Hospital | U16: 4 | V16: N/A | W16: Secondary | X16: Dr. Abraham Auberon Austria | Y16: 9776335322 | Z16: iscmmgh_coop@yahoo.com.ph | AA16: 46023 | AB16: 46387 | AC16: 01-0043-26-H1-2 | AD16: Existing with Changes | AE16: Add-on Service | AF16: Add-on: Clinical Chemistry: Hba1c, Troponin-I Immunology/Serology: TSH, FT3, FT4, Ferritin, Prostate Specific Antigen (PSA), Anti-HAV Rapid Test Kit, Salmonella Typhi Rapid Test Kit Issued LTO (7-30-25)
A17: 16 | B17: 00376 | C17: REGION 1 | D17: Ilocos Sur | E17: Vigan City | F17: Pantay Daya | G17: VQR FOUNDATION FOR MEDICAL AND COMMUNITY DEVELOPMENT, INC. | H17: Private | I17: N/A | J17: General | K17: Level 1 | L17: 30 | M17: Clinical Chemistry: HbA1c, Total Protein, Albumin Immunology and Serology: Thyroid Function Test, Troponin-I, Prostate-Specific Antigen (PSA) | N17: Blood Station | O17: No | P17: N/A | Q17: N/A | R17: N/A | S17: 0 | T17: Northside Doctors' Hospital | U17: 5 | V17: N/A | W17: Secondary | X17: Dr. Glenn Agileo C. Battad | Y17: 077-647-2788 | Z17: st.jamesvqrhospital@yahoo.com | AA17: 46023 | AB17: 46387 | AC17: 01-0020-26-H1-2 | AD17: Renewal | AE17: N/A
A18: 17 | B18: 00312 | C18: REGION 1 | D18: La Union | E18: Agoo | F18: Mac Arther H-way, San Pedro | G18: AGOO FAMILY HOSPITAL | H18: Private | I18: N/A | J18: General | K18: Level 1 | L18: 15 | M18: Clinical Chemistry: HbA1c, Magnesium, Phosphorus, Calcium Immunology and Serology: Troponin- I , Tyhphidot | N18: Blood Station | O18: No | P18: N/A | Q18: N/A | R18: N/A | S18: 0 | T18: N/A | U18: N/A | V18: N/A | W18: Secondary | X18: Dr. Jose E. Aspiras Jr. | Y18: 9175640199 | Z18: docjoe1959@yahoo.com | AA18: 46023 | AB18: 46387 | AC18: 01-0038-26-H1-2 | AD18: Renewal | AE18: N/A
