Workbook

Sheet  COPY Summary
A1: REGION | B1: CHD | C1: No. of Regulated Infirmaries Per Region and by Level (as of June 30, 2023)
C2: GOVERNMENT | E2: PRIVATE | G2: TOTAL NO. OF FACILITIES | H2: TOTAL NO. OF ABC | I2: GOVENMENT AND PRIVATE INFIRMARIES
C4: No. of Facilities | D4: ABC | E4: No. of Facilities | F4: ABC | I4: Total No. of Facilities | J4: Total ABC | K4: REGION
A5: NCR | B5: METRO MANILA | C5: =countifs(Government!B:B,"NCR", Government!G:G,"Government") -> 0 | D5: =SUMIFS(Government!I:I,Government!B:B,"NCR", Government!G:G,"Government") -> 0 | E5: =countifs(Government!B:B,"NCR", Government!G:G,"Private") -> 0 | F5: =SUMIFS(Government!I:I,Government!B:B,"NCR", Government!G:G,"Private") -> 0 | G5: =SUM(C5,E5) -> 0 | H5: =SUM(D5,F5) -> 0 | I5: =C5+E5 -> 0 | J5: =D5+F5 -> 0 | K5: NCR | L5: =SUM(D5,F5) -> 0
A6: REGION 1 | B6: ILOCOS REGION | C6: =countifs(Government!B:B,"Region 1", Government!G:G,"Government") -> 0 | D6: =SUMIFS(Government!I:I,Government!B:B,"Region 1", Government!G:G,"Government") -> 0 | E6: =countifs(Government!B:B,"Region 1", Government!G:G,"Private") -> 0 | F6: =SUMIFS(Government!I:I,Government!B:B,"Region 1", Government!G:G,"Private") -> 0 | G6: =SUM(C6,E6) -> 0 | H6: =SUM(D6,F6) -> 0 | I6: =C6+E6 -> 0 | J6: =D6+F6 -> 0 | K6: REGION 1 | L6: =SUM(D6,F6) -> 0
A7: REGION 2 | B7: CAGAYAN VALLEY REGION | C7: =countifs(Government!B:B,"Region 2", Government!G:G,"Government") -> 0 | D7: =SUMIFS(Government!I:I,Government!B:B,"Region 2", Government!G:G,"Government") -> 0 | E7: =countifs(Government!B:B,"Region 2", Government!G:G,"Private") -> 0 | F7: =SUMIFS(Government!I:I,Government!B:B,"Region 2", Government!G:G,"Private") -> 0 | G7: =SUM(C7,E7) -> 0 | H7: =SUM(D7,F7) -> 0 | I7: =C7+E7 -> 0 | J7: =D7+F7 -> 0 | K7: REGION 2 | L7: =SUM(D7,F7) -> 0
A8: REGION 3 | B8: CENTRAL LUZON | C8: =countifs(Government!B:B,"Region 3", Government!G:G,"Government") -> 0 | D8: =SUMIFS(Government!I:I,Government!B:B,"Region 3", Government!G:G,"Government") -> 0 | E8: =countifs(Government!B:B,"Region 3", Government!G:G,"Private") -> 0 | F8: =SUMIFS(Government!I:I,Government!B:B,"Region 3", Government!G:G,"Private") -> 0 | G8: =SUM(C8,E8) -> 0 | H8: =SUM(D8,F8) -> 0 | I8: =C8+E8 -> 0 | J8: =D8+F8 -> 0 | K8: REGION 3 | L8: =SUM(D8,F8) -> 0
A9: REGION 4-A | B9: CALABARZON | C9: =countifs(Government!B:B,"Region 4-A", Government!G:G,"Government") -> 0 | D9: =SUMIFS(Government!I:I,Government!B:B,"Region 4-A", Government!G:G,"Government") -> 0 | E9: =countifs(Government!B:B,"Region 4-A", Government!G:G,"Private") -> 0 | F9: =SUMIFS(Government!I:I,Government!B:B,"Region 4-A", Government!G:G,"Private") -> 0 | G9: =SUM(C9,E9) -> 0 | H9: =SUM(D9,F9) -> 0 | I9: =C9+E9 -> 0 | J9: =D9+F9 -> 0 | K9: REGION 4-A | L9: =SUM(D9,F9) -> 0
A10: REGION 4-B | B10: MIMAROPA | C10: =countifs(Government!B:B,"Region 4-B", Government!G:G,"Government") -> 0 | D10: =SUMIFS(Government!I:I,Government!B:B,"Region 4-B", Government!G:G,"Government") -> 0 | E10: =countifs(Government!B:B,"Region 4-B", Government!G:G,"Private") -> 0 | F10: =SUMIFS(Government!I:I,Government!B:B,"Region 4-B", Government!G:G,"Private") -> 0 | G10: =SUM(C10,E10) -> 0 | H10: =SUM(D10,F10) -> 0 | I10: =C10+E10 -> 0 | J10: =D10+F10 -> 0 | K10: REGION 4-B | L10: =SUM(D10,F10) -> 0
A11: REGION 5 | B11: BICOL REGION | C11: =countifs(Government!B:B,"Region 5", Government!G:G,"Government") -> 0 | D11: =SUMIFS(Government!I:I,Government!B:B,"Region 5", Government!G:G,"Government") -> 0 | E11: =countifs(Government!B:B,"Region 5", Government!G:G,"Private") -> 0 | F11: =SUMIFS(Government!I:I,Government!B:B,"Region 5", Government!G:G,"Private") -> 0 | G11: =SUM(C11,E11) -> 0 | H11: =SUM(D11,F11) -> 0 | I11: =C11+E11 -> 0 | J11: =D11+F11 -> 0 | K11: REGION 5 | L11: =SUM(D11,F11) -> 0
A12: REGION 6 | B12: WESTERN VISAYAS REGION | C12: =countifs(Government!B:B,"Region 6", Government!G:G,"Government") -> 0 | D12: =SUMIFS(Government!I:I,Government!B:B,"Region 6", Government!G:G,"Government") -> 0 | E12: =countifs(Government!B:B,"Region 6", Government!G:G,"Private") -> 0 | F12: =SUMIFS(Government!I:I,Government!B:B,"Region 6", Government!G:G,"Private") -> 0 | G12: =SUM(C12,E12) -> 0 | H12: =SUM(D12,F12) -> 0 | I12: =C12+E12 -> 0 | J12: =D12+F12 -> 0 | K12: REGION 6 | L12: =SUM(D12,F12) -> 0
A13: REGION 7 | B13: CENTRAL VISAYAS REGION | C13: =countifs(Government!B:B,"Region 7", Government!G:G,"Government") -> 0 | D13: =SUMIFS(Government!I:I,Government!B:B,"Region 7", Government!G:G,"Government") -> 0 | E13: =countifs(Government!B:B,"Region 7", Government!G:G,"Private") -> 0 | F13: =SUMIFS(Government!I:I,Government!B:B,"Region 7", Government!G:G,"Private") -> 0 | G13: =SUM(C13,E13) -> 0 | H13: =SUM(D13,F13) -> 0 | I13: =C13+E13 -> 0 | J13: =D13+F13 -> 0 | K13: REGION 7 | L13: =SUM(D13,F13) -> 0
A14: REGION 8 | B14: EASTERN VISAYAS REGION | C14: =countifs(Government!B:B,"Region 8", Government!G:G,"Government") -> 0 | D14: =SUMIFS(Government!I:I,Government!B:B,"Region 8", Government!G:G,"Government") -> 0 | E14: =countifs(Government!B:B,"Region 8", Government!G:G,"Private") -> 0 | F14: =SUMIFS(Government!I:I,Government!B:B,"Region 8", Government!G:G,"Private") -> 0 | G14: =SUM(C14,E14) -> 0 | H14: =SUM(D14,F14) -> 0 | I14: =C14+E14 -> 0 | J14: =D14+F14 -> 0 | K14: REGION 8 | L14: =SUM(D14,F14) -> 0
A15: REGION 9 | B15: ZAMBOANGA PENINSULA | C15: =countifs(Government!B:B,"Region 9", Government!G:G,"Government") -> 0 | D15: =SUMIFS(Government!I:I,Government!B:B,"Region 9", Government!G:G,"Government") -> 0 | E15: =countifs(Government!B:B,"Region 9", Government!G:G,"Private") -> 0 | F15: =SUMIFS(Government!I:I,Government!B:B,"Region 9", Government!G:G,"Private") -> 0 | G15: =SUM(C15,E15) -> 0 | H15: =SUM(D15,F15) -> 0 | I15: =C15+E15 -> 0 | J15: =D15+F15 -> 0 | K15: REGION 9 | L15: =SUM(D15,F15) -> 0
A16: REGION 10 | B16: NORTHERN MINDANAO REGION | C16: =countifs(Government!B:B,"Region 10", Government!G:G,"Government") -> 0 | D16: =SUMIFS(Government!I:I,Government!B:B,"Region 10", Government!G:G,"Government") -> 0 | E16: =countifs(Government!B:B,"Region 10", Government!G:G,"Private") -> 0 | F16: =SUMIFS(Government!I:I,Government!B:B,"Region 10", Government!G:G,"Private") -> 0 | G16: =SUM(C16,E16) -> 0 | H16: =SUM(D16,F16) -> 0 | I16: =C16+E16 -> 0 | J16: =D16+F16 -> 0 | K16: REGION 10 | L16: =SUM(D16,F16) -> 0
A17: REGION 11 | B17: DAVAO REGION | C17: =countifs(Government!B:B,"Region 11", Government!G:G,"Government") -> 0 | D17: =SUMIFS(Government!I:I,Government!B:B,"Region 11", Government!G:G,"Government") -> 0 | E17: =countifs(Government!B:B,"Region 11", Government!G:G,"Private") -> 0 | F17: =SUMIFS(Government!I:I,Government!B:B,"Region 11", Government!G:G,"Private") -> 0 | G17: =SUM(C17,E17) -> 0 | H17: =SUM(D17,F17) -> 0 | I17: =C17+E17 -> 0 | J17: =D17+F17 -> 0 | K17: REGION 11 | L17: =SUM(D17,F17) -> 0
A18: REGION 12 | B18: SOCCSKSARGEN | C18: =countifs(Government!B:B,"Region 12", Government!G:G,"Government") -> 0 | D18: =SUMIFS(Government!I:I,Government!B:B,"Region 12", Government!G:G,"Government") -> 0 | E18: =countifs(Government!B:B,"Region 12", Government!G:G,"Private") -> 0 | F18: =SUMIFS(Government!I:I,Government!B:B,"Region 12", Government!G:G,"Private") -> 0 | G18: =SUM(C18,E18) -> 0 | H18: =SUM(D18,F18) -> 0 | I18: =C18+E18 -> 0 | J18: =D18+F18 -> 0 | K18: REGION 12 | L18: =SUM(D18,F18) -> 0
A19: REGION 13 | B19: CARAGA | C19: =countifs(Government!B:B,"Region 13", Government!G:G,"Government") -> 0 | D19: =SUMIFS(Government!I:I,Government!B:B,"Region 13", Government!G:G,"Government") -> 0 | E19: =countifs(Government!B:B,"Region 13", Government!G:G,"Private") -> 0 | F19: =SUMIFS(Government!I:I,Government!B:B,"Region 13", Government!G:G,"Private") -> 0 | G19: =SUM(C19,E19) -> 0 | H19: =SUM(D19,F19) -> 0 | I19: =C19+E19 -> 0 | J19: =D19+F19 -> 0 | K19: REGION 13 | L19: =SUM(D19,F19) -> 0
A20: CORDILLERA | B20: CAR | C20: =countifs(Government!B:B,"CORDILLERA", Government!G:G,"Government") -> 0 | D20: =SUMIFS(Government!I:I,Government!B:B,"CORDILLERA", Government!G:G,"Government") -> 0 | E20: =countifs(Government!B:B,"CORDILLERA", Government!G:G,"Private") -> 0 | F20: =SUMIFS(Government!I:I,Government!B:B,"CORDILLERA", Government!G:G,"Private") -> 0 | G20: =SUM(C20,E20) -> 0 | H20: =SUM(D20,F20) -> 0 | I20: =C20+E20 -> 0 | J20: =D20+F20 -> 0 | K20: CORDILLERA | L20: =SUM(D20,F20) -> 0
A21: BARMM | B21: MOH - BARMM | C21: =countifs(Government!B:B,"BARMM", Government!G:G,"Government") -> 0 | D21: =SUMIFS(Government!I:I,Government!B:B,"BARMM", Government!G:G,"Government") -> 0 | E21: =countifs(Government!B:B,"BARMM", Government!G:G,"Private") -> 0 | F21: =SUMIFS(Government!I:I,Government!B:B,"BARMM", Government!G:G,"Private") -> 0 | G21: =SUM(C21,E21) -> 0 | H21: =SUM(D21,F21) -> 0 | I21: =C21+E21 -> 0 | J21: =D21+F21 -> 0 | K21: BARMM | L21: =SUM(D21,F21) -> 0
A22: Total No. of Infirmaries: | C22: =sum(C5:C21) -> 0 | D22: =sum(D5:D21) -> 0 | E22: =SUM(E5:E21) -> 0 | F22: =SUM(F5:F21) -> 0 | G22: =SUM(C22,E22) -> 0 | H22: =SUM(D22,F22) -> 0 | I22: =SUM(I5:I21) -> 0 | J22: =SUM(J5:J21) -> 0
L23: =SUM(L5:L22) -> 0
H25: =SUM(D22,F22) -> 0
A28: GOVERNMENT | B28: =C22 -> 0
A29: PRIVATE | B29: =E22 -> 0
A32: REGION | B32: GOVERNMENT
A36: NCR | B36: 5
A37: REGION 1 | B37: 9
A38: REGION 2 | B38: 22
A39: REGION 3 | B39: 14
A40: REGION 4-A | B40: 27
A41: REGION 4-B | B41: 25
A42: REGION 5 | B42: 32
A43: REGION 6 | B43: 28
A44: REGION 7 | B44: 42
A45: REGION 8 | B45: 29
A46: REGION 9 | B46: 19
A47: REGION 10 | B47: 19
... A52: BARMM | B52: 16
A54: REGION | B54: PRIVATE
...

Sheet Closed Facility
A1: # | B1: REGION | C1: CHD | D1: PROVINCE | E1: CITY/MUNICIPALITY | F1: BLDG OR HOUSE NO., STREET, BRGY (as applicable) | G1: NAME OF FACILITY | H1: OWNERSHIP | I1: OWNERSHIP CLASSIFICATION (For Government Only) | J1: ABC | K1: ADD-ONS SERVICES | L1: CLINICAL LAB CLASSIFICATION (If Applicable) | M1: MEDICAL DIRECTOR/ CHIEF OF HOSPITAL | N1: CONTACT NOS. | O1: E-MAIL ADDRESS | P1: AMBULANCE (No./ TYPE / PLATE NO.) Pls. Seperate if different Type | Q1: NAME OF AMBULANCE SERVICE PROVIDER IF W/ MOA | R1: VALIDITY FROM | S1: VALIDITY UNTIL | T1: LICENSE NO. | U1: REMARKS
B2: REGION 10 | G2: Dra
A3: 1 | B3: REGION 13 | D3: Butuan | E3: Butuan City | F3: Nonan Village, J.C. Aquino Ave., Butuan City | G3: Caraga Hospital Infant Care & Lying-in Center | H3: Private | J3: 16 | M3: Dr. Winefredo Osigan | P3: 1, Type1, Plate No. LAC 1417, CR No.304643872 | U3: Not renewed
A4: 2 | B4: REGION 13 | D4: Butuan | E4: Butuan City | F4: Camp Rodriguez, Libertad, But. City | G4: PNP Hospital Region 13 | I4: PNP | J4: 10 | M4: Psupt. Michael Angelo L. Mallari, MD | T4: 16 - 31- 22 - I - 1 | U4: Not renewed
A5: 3 | B5: REGION 13 | D5: Butuan | E5: Butuan City | F5: Lot 371-1-2, South Montilla Road, Barrio Villa Kananga, Butuan City | G5: Allied Care Experts (ACE) Medical Center-Butuan City | H5: Private | J5: 44 | P5: 1 (Type 1) Plate No. DBG 5659 CR No. 46907073-3 | R5: 45027 | S5: 45291 | T5: 16 - 27- 23- l-2
A6: 4 | B6: REGION 13 | D6: Agusan del Norte | E6: Magallanes | F6: Magallanes, Agusan del Norte | G6: St. Joseph Infirmary | H6: Private | J6: 15 | M6: Dr. Elena Abarquez | P6: Type 2, Plate No. JCU 540 CR. No. 7202380-3 | R6: 44927 | S6: 45291 | T6: 16 - 01-23- l-2 | U6: Not renewed
A7: 5 | B7: REGION 13 | D7: Surigao del Sur | E7: Bislig City | F7: P-4, Caramcam, Mangagoy, Bislig City | G7: Family Medical Clinic | H7: Private | J7: 30 | M7: Dr. Aurora S. Babano | P7: MOA with Andres Soriano Hospital | U7: Not renewed
A8: 6 | B8: REGION 13 | D8: Surigao del Sur | E8: Cantilan | F8: P-5 National Highway, Pag-antayan, Cantilan, Surigao del Sur | G8: Isidro M. Olan Sr.Memorial Clinic and Hospital Inc. | H8: Private | J8: 10 | M8: Dr. Valentin D. Olan | P8: Plate No. SFJ 350, CR No. 0059996447 | U8: Not renewed
A9: 7 | B9: REGION 13 | D9: Surigao del Norte | F9: V. del Socorro St., Socorro, Surigao del Norte | G9: Socorro District Hospital | H9: Province | I9: LGU | J9: 10 | M9: Dr. Nikki J. Carduza | P9: 1 Type 1, Plate No. SAA6865 CR No. 262456994 | T9: 16 - 17- 22 - I - 1 | U9: Not renewed

Sheet Dialysis
A1: # | B1: REGION | C1: CHD | D1: PROVINCE | E1: CITY/ MUNICIPALITY | F1: BLDG OR HOUSE NO., STREET, BRGY (as applicable) | G1: OWNERSHIP | H1: NAME OF CLINIC | I1: NO. OF STATION | J1: HEAD OF THE FACILITY | K1: CONTACT NUMBER | L1: E MAIL ADDRESS | M1: VALIDITY FROM | N1: VALIDITY UNTIL | O1: LICENSED NO. | P1: REMARKS
A2: 1 | F2: Application @ HFSRB
A3: 2
A4: 3
A5: 4
A6: 5
A7: 6
A8: 7
A9: 8
A10: 9
A11: 10
A12: 11
A13: 12
A14: 13
... A480: 479

Sheet Blood Center

Sheet Summary
A1: REGION | B1: CHD | C1: Regional Distribution of Infirmaries in the Philippines (as of June 30, 2026)
C2: GOVERNMENT | E2: PRIVATE | G2: TOTAL NO. OF FACILITIES | H2: TOTAL NO. OF ABC | I2: GOVENMENT AND PRIVATE INFIRMARIES
C4: No. of Facilities | D4: ABC | E4: No. of Facilities | F4: ABC | I4: Total No. of Facilities | J4: Total ABC
A5: NCR | B5: METRO MANILA | C5: =countifs(Government!C:C,"NCR", Government!H:H,"Government") -> 4 | D5: =SUMIFS(Government!J:J,Government!C:C,"NCR", Government!H:H,"Government") -> 84 | E5: =countifs(Private!C:C,"NCR", Private!H:H,"Private") -> 16 | F5: =SUMIFS(Private!J:J,Private!C:C,"NCR", Private!H:H,"Private") -> 160 | G5: =SUM(C5,E5) -> 20 | H5: =SUM(D5,F5) -> 244 | I5: =C5+E5 -> 20 | J5: =D5+F5 -> 244
A6: REGION 1 | B6: ILOCOS REGION | C6: =countifs(Government!C:C,"Region 1", Government!H:H,"Government") -> 10 | D6: =SUMIFS(Government!J:J,Government!C:C,"Region 1", Government!H:H,"Government") -> 138 | E6: =countifs(Private!C:C,"Region 1", Private!H:H,"Private") -> 26 | F6: =SUMIFS(Private!J:J,Private!C:C,"Region 1", Private!H:H,"Private") -> 334 | G6: =SUM(C6,E6) -> 36 | H6: =SUM(D6,F6) -> 472 | I6: =C6+E6 -> 36 | J6: =D6+F6 -> 472
A7: REGION 2 | B7: CAGAYAN VALLEY REGION | C7: =countifs(Government!C:C,"Region 2", Government!H:H,"Government") -> 28 | D7: =SUMIFS(Government!J:J,Government!C:C,"Region 2", Government!H:H,"Government") -> 377 | E7: =countifs(Private!C:C,"Region 2", Private!H:H,"Private") -> 8 | F7: =SUMIFS(Private!J:J,Private!C:C,"Region 2", Private!H:H,"Private") -> 105 | G7: =SUM(C7,E7) -> 36 | H7: =SUM(D7,F7) -> 482 | I7: =C7+E7 -> 36 | J7: =D7+F7 -> 482
A8: REGION 3 | B8: CENTRAL LUZON | C8: =countifs(Government!C:C,"Region 3", Government!H:H,"Government") -> 20 | D8: =SUMIFS(Government!J:J,Government!C:C,"Region 3", Government!H:H,"Government") -> 361 | E8: =countifs(Private!C:C,"Region 3", Private!H:H,"Private") -> 23 | F8: =SUMIFS(Private!J:J,Private!C:C,"Region 3", Private!H:H,"Private") -> 301 | G8: =SUM(C8,E8) -> 43 | H8: =SUM(D8,F8) -> 662 | I8: =C8+E8 -> 43 | J8: =D8+F8 -> 662
A9: REGION 4-A | B9: CALABARZON | C9: =countifs(Government!C:C,"Region 4-A", Government!H:H,"Government") -> 21 | D9: =SUMIFS(Government!J:J,Government!C:C,"Region 4-A", Government!H:H,"Government") -> 358 | E9: =countifs(Private!C:C,"Region 4-A", Private!H:H,"Private") -> 16 | F9: =SUMIFS(Private!J:J,Private!C:C,"Region 4-A", Private!H:H,"Private") -> 196 | G9: =SUM(C9,E9) -> 37 | H9: =SUM(D9,F9) -> 554 | I9: =C9+E9 -> 37 | J9: =D9+F9 -> 554
A10: REGION 4-B | B10: MIMAROPA | C10: =countifs(Government!C:C,"Region 4-B", Government!H:H,"Government") -> 26 | D10: =SUMIFS(Government!J:J,Government!C:C,"Region 4-B", Government!H:H,"Government") -> 378 | E10: =countifs(Private!C:C,"Region 4-B", Private!H:H,"Private") -> 8 | F10: =SUMIFS(Private!J:J,Private!C:C,"Region 4-B", Private!H:H,"Private") -> 69 | G10: =SUM(C10,E10) -> 34 | H10: =SUM(D10,F10) -> 447 | I10: =C10+E10 -> 34 | J10: =D10+F10 -> 447
A11: REGION 5 | B11: BICOL REGION | C11: =countifs(Government!C:C,"Region 5", Government!H:H,"Government") -> 34 | D11: =SUMIFS(Government!J:J,Government!C:C,"Region 5", Government!H:H,"Government") -> 482 | E11: =countifs(Private!C:C,"Region 5", Private!H:H,"Private") -> 21 | F11: =SUMIFS(Private!J:J,Private!C:C,"Region 5", Private!H:H,"Private") -> 265 | G11: =SUM(C11,E11) -> 55 | H11: =SUM(D11,F11) -> 747 | I11: =C11+E11 -> 55 | J11: =D11+F11 -> 747
A12: REGION 6 | B12: WESTERN VISAYAS REGION | C12: =countifs(Government!C:C,"Region 6", Government!H:H,"Government") -> 18 | D12: =SUMIFS(Government!J:J,Government!C:C,"Region 6", Government!H:H,"Government") -> 319 | E12: =countifs(Private!C:C,"Region 6", Private!H:H,"Private") -> 4 | F12: =SUMIFS(Private!J:J,Private!C:C,"Region 6", Private!H:H,"Private") -> 51 | G12: =SUM(C12,E12) -> 22 | H12: =SUM(D12,F12) -> 370 | I12: =C12+E12 -> 22 | J12: =D12+F12 -> 370
A13: REGION 7 | B13: CENTRAL VISAYAS REGION | C13: =countifs(Government!C:C,"Region 7", Government!H:H,"Government") -> 28 | D13: =SUMIFS(Government!J:J,Government!C:C,"Region 7", Government!H:H,"Government") -> 449 | E13: =countifs(Private!C:C,"Region 7", Private!H:H,"Private") -> 9 | F13: =SUMIFS(Private!J:J,Private!C:C,"Region 7", Private!H:H,"Private") -> 131 | G13: =SUM(C13,E13) -> 37 | H13: =SUM(D13,F13) -> 580 | I13: =C13+E13 -> 37 | J13: =D13+F13 -> 580
A14: REGION 8 | B14: EASTERN VISAYAS REGION | C14: =countifs(Government!C:C,"Region 8", Government!H:H,"Government") -> 32 | D14: =SUMIFS(Government!J:J,Government!C:C,"Region 8", Government!H:H,"Government") -> 388 | E14: =countifs(Private!C:C,"Region 8", Private!H:H,"Private") -> 8 | F14: =SUMIFS(Private!J:J,Private!C:C,"Region 8", Private!H:H,"Private") -> 111 | G14: =SUM(C14,E14) -> 40 | H14: =SUM(D14,F14) -> 499 | I14: =C14+E14 -> 40 | J14: =D14+F14 -> 499
A15: REGION 9 | B15: ZAMBOANGA PENINSULA | C15: =countifs(Government!C:C,"Region 9", Government!H:H,"Government") -> 24 | D15: =SUMIFS(Government!J:J,Government!C:C,"Region 9", Government!H:H,"Government") -> 484 | E15: =countifs(Private!C:C,"Region 9", Private!H:H,"Private") -> 11 | F15: =SUMIFS(Private!J:J,Private!C:C,"Region 9", Private!H:H,"Private") -> 151 | G15: =SUM(C15,E15) -> 35 | H15: =SUM(D15,F15) -> 635 | I15: =C15+E15 -> 35 | J15: =D15+F15 -> 635
A16: REGION 10 | B16: NORTHERN MINDANAO REGION | C16: =countifs(Government!C:C,"Region 10", Government!H:H,"Government") -> 20 | D16: =SUMIFS(Government!J:J,Government!C:C,"Region 10", Government!H:H,"Government") -> 398 | E16: =countifs(Private!C:C,"Region 10", Private!H:H,"Private") -> 16 | F16: =SUMIFS(Private!J:J,Private!C:C,"Region 10", Private!H:H,"Private") -> 262 | G16: =SUM(C16,E16) -> 36 | H16: =SUM(D16,F16) -> 660 | I16: =C16+E16 -> 36 | J16: =D16+F16 -> 660
A17: REGION 11 | B17: DAVAO REGION | C17: =countifs(Government!C:C,"Region 11", Government!H:H,"Government") -> 14 | D17: =SUMIFS(Government!J:J,Government!C:C,"Region 11", Government!H:H,"Government") -> 236 | E17: =countifs(Private!C:C,"Region 11", Private!H:H,"Private") -> 29 | F17: =SUMIFS(Private!J:J,Private!C:C,"Region 11", Private!H:H,"Private") -> 553 | G17: =SUM(C17,E17) -> 43 | H17: =SUM(D17,F17) -> 789 | I17: =C17+E17 -> 43 | J17: =D17+F17 -> 789
A18: REGION 12 | B18: SOCCSKSARGEN | C18: =countifs(Government!C:C,"Region 12", Government!H:H,"Government") -> 15 | D18: =SUMIFS(Government!J:J,Government!C:C,"Region 12", Government!H:H,"Government") -> 269 | E18: =countifs(Private!C:C,"Region 12", Private!H:H,"Private") -> 26 | F18: =SUMIFS(Private!J:J,Private!C:C,"Region 12", Private!H:H,"Private") -> 505 | G18: =SUM(C18,E18) -> 41 | H18: =SUM(D18,F18) -> 774 | I18: =C18+E18 -> 41 | J18: =D18+F18 -> 774
A19: REGION 13 | B19: CARAGA | C19: =countifs(Government!C:C,"Region 13", Government!H:H,"Government") -> 20 | D19: =SUMIFS(Government!J:J,Government!C:C,"Region 13", Government!H:H,"Government") -> 263 | E19: =countifs(Private!C:C,"Region 13", Private!H:H,"Private") -> 5 | F19: =SUMIFS(Private!J:J,Private!C:C,"Region 13", Private!H:H,"Private") -> 100 | G19: =SUM(C19,E19) -> 25 | H19: =SUM(D19,F19) -> 363 | I19: =C19+E19 -> 25 | J19: =D19+F19 -> 363
A20: NIR | B20: NEGROS ISLAND REGION | C20: =countifs(Government!C:C,"NIR", Government!H:H,"Government") -> 18 | D20: =SUMIFS(Government!J:J,Government!C:C,"NIR", Government!H:H,"Government") -> 240 | E20: =countifs(Private!C:C,"NIR", Private!H:H,"Private") -> 2 | F20: =SUMIFS(Private!J:J,Private!C:C,"NIR", Private!H:H,"Private") -> 35 | G20: =SUM(C20,E20) -> 20 | H20: =SUM(D20,F20) -> 275 | I20: =C20+E20 -> 20 | J20: =D20+F20 -> 275
A21: CORDILLERA | B21: CAR | C21: =countifs(Government!C:C,"CORDILLERA", Government!H:H,"Government") -> 23 | D21: =SUMIFS(Government!J:J,Government!C:C,"Cordillera", Government!H:H,"Government") -> 338 | E21: =countifs(Private!C:C,"Cordillera", Private!H:H,"Private") -> 8 | F21: =SUMIFS(Private!J:J,Private!C:C,"CORDILLERA", Private!H:H,"Private") -> 105 | G21: =SUM(C21,E21) -> 31 | H21: =SUM(D21,F21) -> 443 | I21: =C21+E21 -> 31 | J21: =D21+F21 -> 443
A22: BARMM | B22: MOH - BARMM | C22: =countifs(Government!C:C,"BARMM", Government!H:H,"Government") -> 9 | D22: =SUMIFS(Government!J:J,Government!C:C,"BARMM", Government!H:H,"Government") -> 150 | E22: =countifs(Private!C:C,"BARMM", Private!H:H,"Private") -> 14 | F22: =SUMIFS(Private!J:J,Private!C:C,"BARMM", Private!H:H,"Private") -> 212 | G22: =SUM(C22,E22) -> 23 | H22: =SUM(D22,F22) -> 362 | I22: =C22+E22 -> 23 | J22: =D22+F22 -> 362
A23: Total No. of Infirmaries: | C23: =sum(C5:C22) -> 364 | D23: =sum(D5:D22) -> 5712 | E23: =SUM(E5:E22) -> 250 | F23: =SUM(F5:F22) -> 3646 | G23: =SUM(C23,E23) -> 614 | H23: =SUM(D23,F23) -> 9358 | I23: =SUM(I5:I22) -> 614 | J23: =SUM(J5:J22) -> 9358

Sheet Government
B1: NHFR CODE | C1: REGION | D1: PROVINCE | E1: CITY / MUNICIPALITY | F1: BLDG OR HOUSE NO., STREET, BRGY (as applicable) | G1: NAME OF FACILITY | H1: OWNERSHIP | I1: OWNERSHIP CLASSIFICATION (For Government Only) | J1: ABC | K1: ADD-ONS SERVICES | L1: CLINICAL LAB CLASSIFICATION (If Applicable) | M1: MEDICAL DIRECTOR / CHIEF OF HOSPITAL | N1: CONTACT NOS. | O1: E-MAIL ADDRESS | P1: AMBULANCE (No./ TYPE / PLATE NO.) Pls. Seperate if different Type | Q1: NAME OF AMBULANCE SERVICE PROVIDER IF W/ MOA | R1: VALIDITY FROM | S1: VALIDITY UNTIL | T1: LICENSE NO. | U1: APPLICATION STATUS | V1: APPLICATION STATUS (IF WITH CHANGES) | W1: REMARKS
A2: 1 | B2: 02928 | C2: REGION 1 | D2: Ilocos Norte | E2: Dingras | F2: Suyo | G2: DINGRAS DISTRICT HOSPITAL | H2: Government | I2: PROVINCE | J2: 18 | K2: -Diagnostic X-ray (Level 2) -Pharmacy -Add-on Clinical Laboratory: 1. Clinical chemistry: -HBAIC | L2: Secondary | M2: Roland B. Andres, MD | N2: 600-3085 | O2: dingrashospital75@gmail.com | P2: TYPE I- Plate No. 130102 CR No. 0020096579 | Q2: Gov. Roque Ablan Sr. Memorial Hospital | R2: 46023 | S2: 46387 | T2: 01-0008-26-I-1 | U2: Renewal | V2: N/A | X2: *
A3: 2 | B3: 06707 | C3: REGION 1 | D3: Ilocos Norte | E3: Marcos | F3: Guava St., Brgy. Lydia | G3: DOÑA JOSEFA EDRALIN MARCOS DISTRICT HOSPITAL | H3: Government | I3: PROVINCE | J3: 18 | K3: -Diagnostic X-ray (Level 1) -Pharmacy -Clinical Laboratory | L3: Secondary | M3: Maria Kristeta C. Manrique, MD | N3: 09215658000 | O3: DJEMDH@yahoo.com.ph | P3: TYPE I-AMBULANCE/ Plate No. 130102 CR No. 0020090157 | R3: 46023 | S3: 46387 | T3: 01-0031-26-I-1 | U3: Renewal | V3: N/A | X3: *
A4: 3 | B4: 00001 | C4: REGION 1 | D4: Ilocos Norte | E4: Piddig | F4: Agcaoili St., Cor. Goodbye Street, Brgy. 2 Anao | G4: PIDDIG DISTRICT HOSPITAL | H4: Government | I4: PROVINCE | J4: 15 | K4: Clinical Laboratory Add On (08-04-2025): 1. Clinical Chemistry: -HBAIC | L4: Primary | M4: Cheryl R. Laguatan, MD | N4: 077-676-1406/ 6003323/ 09171434290 | O4: piddigdh@yahoo.com | P4: TYPE I AMBULANCE (01-09-2024) Plate# 130102 CR # 0006911142 | R4: 46023 | S4: 46387 | T4: 01-0029-26-I-1 | U4: Renewal | V4: N/A | X4: *
A5: 4 | B5: 30121 | C5: REGION 1 | D5: Ilocos Sur | E5: Quirino | F5: Poblacion II | G5: QUIRINO PRIMARY HEALTH CARE FACILITY | H5: Government | I5: LGU | J5: 10 | K5: Clinical Laboratory | L5: Secondary | M5: Precious Ivony D. Alfonso-Catriz, MD, DFM | N5: 09108946621 | O5: qphcf@yahoo.com | Q5: Luis Hora Memorial Regional Hospital | R5: 46023 | S5: 46387 | T5: 01-0017-26-I-1 | U5: Renewal | V5: N/A | X5: *
A6: 5 | B6: 00280 | C6: REGION 1 | D6: Ilocos Sur | E6: Salcedo | F6: National Road, Poblacion Sur | G6: ILOCOS SUR DISTRICT HOSPITAL-SALCEDO | H6: Government | I6: PROVINCE | J6: 15 | K6: -Diagnostic X-Ray (Level 1) -Pharmacy -Add on Clinical Laboratory: 1. Clinical Chemistry: --HBAIC 2. Immunology/Serology: --Troponin I (Qualitative and Quantitative) | L6: Secondary | M6: Federico Anaen, Jr., MD, MHA | N6: 09951293539 | O6: salcedomedicare@yahoo.com | Q6: Candon St. Martin de Porres Hospital | R6: 46023 | S6: 46387 | T6: 01-0009-26-I-1 | U6: Renewal | V6: N/A | X6: *
A7: 6 | B7: 32065 | C7: REGION 1 | D7: Ilocos Sur | E7: Vigan City | F7: Tamag | G7: UNIVERSITY OF NORTHERN PHILIPPINES HOSPITAL | H7: Government | I7: UNIVERSITY / SCHOOL | J7: 18 | K7: -Add on Clinical Laboratory: 1. Clinical Chemistry: --HBAIC (08-19-2024) | L7: Secondary | M7: Marsha MIchelle C. Cabuena | N7: 09175333398 | O7: unp.hospita@yahoo.com/unphlab@gmail.com | Q7: Metro Vigan Hospital/ Ilocos Sur Provincial Hospital - Gabriela Silang | R7: 46023 | S7: 46387 | T7: 01-0030-26-I-1 | U7: Renewal | V7: N/A | X7: *
A8: 7 | C8: REGION 1 | D8: Pangasinan | E8: Labrador | F8: Brgy. Poblacion, District II | G8: LABRADOR MUNICIPAL INFIRMARY | H8: Government | I8: LGU | J8: 10 | K8: None | M8: Mark Ross M. Rosario, MD | N8: 9162437676 | O8: labradormunicipalinfirmary@gmail.com | R8: 46023 | S8: 46387 | T8: 01-0032-26-I-1 | U8: Initial | V8: N/A
A9: 8 | C9: REGION 1 | D9: Pangasinan | E9: Malasiqui | F9: Brgy. Cabatlig | G9: MALASIQUI MUNICIPAL HOSPITAL | H9: Government | I9: LGU | J9: 16 | K9: >Pharmacy >Diagnostic X-Ray (Level 1) >Clinical Laboratory | L9: Primary | M9: Cielo E. Almoite, MD, MPH | N9: 9629339935 | O9: malasiquimunicipalhospital@gmail.com | P9: MOA | Q9: Christ Bearer Infirmary | R9: 46122 | S9: 46387 | T9: 01-0035-26-I-1 | U9: Initial | V9: N/A | X9: *
A10: 9 | B10: 32061 | C10: REGION 1 | D10: Pangasinan | E10: Rosales | F10: Pine St.,Zone V, District 6 | G10: ROSALES INFIRMARY UNIT | H10: Government | I10: LGU | J10: 12 | K10: None | M10: Adam Arlie B. Guieb, MD | N10: (075)-517-6065 | O10: rosalesinfirmaryunit@gmail.com | R10: 46023 | S10: 46387 | T10: 01-0026-26-I-1 | U10: Renewal | V10: N/A | X10: *
A11: 10 | B11: 38481 | C11: REGION 1 | D11: Pangasinan | E11: Sual | F11: Caoayan | G11: SUAL PRIMARY CARE FACILTY - INFIRMARY | H11: Government | I11: LGU | J11: 6 | K11: - Pharmacy -Diagnostic X-Ray (Level 1) -Clinical Laboratory | L11: Secondary | M11: Jasfer Neil B. Nadong, MD | N11: 09190646207 | O11: pcfinfirmary@gmail.com | P11: Type I AMBULANCE (01-24-2024) Plate No. 130105, CR No.45035689 | R11: 46023 | S11: 46387 | T11: 01-0012-26-I-1 | U11: Renewal | V11: N/A | X11: *
A12: 11 | B12: 4052 | C12: REGION 2 | D12: Batanes | E12: Itbayat | F12: National Road, San Rafael | G12: ITBAYAT DISTRICT HOSPITAL | H12: Government | I12: PROVINCE | J12: 15 | K12: None | L12: N/A | M12: Dr. Nikita C. Gato | N12: 09617626722 09776574788 | O12: idh.batanes@gmail.com | P12: 1, Type 1, C.S. No. K1U940 | R12: 46023 | S12: 46387 | T12: 02-20-26-I-1 | U12: Renewal | V12: Changed Ownership/Mgt | W12: Change of Head of Facility (2nd Quarter) | X12: *
A13: 12 | C13: REGION 2 | D13: Cagayan | E13: Abulug | F13: Maharlika Highway, Pinili, District II | G13: NORTHWESTERN CAGAYAN GENERAL HOSPITAL | H13: Government | I13: DOH RETAINED | J13: 16 | K13: Pharmacy , Dialysis Clinic (12 Stations), Clinical Laboratory - DOH Programs - Special Chemistry (AST, ALT),Electrolytes (NA, K,Cl,iCal, Tcal), | L13: Limited Service | M13: Dr. Jasmin Rose Umblas-Maladrigo, MHA | N13: 9126306613 | O13: northwesterncagayangh@gmail.com | P13: 2, type 1/ SND 3301, Plate No. 130106 & SGA 6280 | R13: 46023 | S13: 46387 | T13: 02-16-26-I-1 | U13: Renewal | V13: N/A | W13: Add ons Service- 02/06/2026- 1st Quarter, Clinical Laboratory - DOH Programs - Special Chemistry (AST, ALT)- 1st Quarter (2/9/2026), Additional Ambulance Unit- 1st Quarter ( 3/16/2026) | X13: *
A14: 13 | C14: REGION 2 | D14: Cagayan | E14: Alcala | F14: Centro Norte | G14: ALCALA MUNICIPAL HOSPITAL | H14: Government | I14: PROVINCE | J14: 10 | K14: Pharmacy, Clinical Laboratory Add ons: Special Serology (S. typhi, Leptospira) | L14: Secondary | M14: Dr. Raymond Q. Ruiz | N14: (078) 3772-224 09955588961 | O14: amhcagayan@gmail.com | P14: 1.Type 1, C.S. No. F5K695 | R14: 46023 | S14: 46387 | T14: 02-19-26-I-1 | U14: Renewal | X14: *
A15: 14 | C15: REGION 2 | D15: Cagayan | E15: Baggao | F15: Tungel | G15: BAGGAO DISTRICT HOSPITAL | H15: Government | I15: PROVINCE | J15: 10 | K15: None | L15: Primary | M15: Dr. Sharon Go | N15: 9171424890 | O15: bdhtungel@gmail.com | P15: 1/Type 1/Plate No. 030110 | R15: 46023 | S15: 46387 | T15: 02-21-26-I-1 | U15: Renewal | X15: *
A16: 15 | C16: REGION 2 | D16: Cagayan | E16: Calayan | F16: A. Escalante Street, Poblacion | G16: CALAYAN INFIRMARY | H16: Government | I16: LGU | J16: 10 | K16: Pharmacy | L16: Secondary | M16: Dr. Christian Clemencia-OIC | N16: 9120296037 | O16: calayaninfirmary@gmail.com | Q16: Aparri Provincial Hospital | R16: 46023 | S16: 46387 | T16: 02-31-26-I-1 | U16: Renewal | W16: Change of COH ( 1st Quarter) | X16: *
A17: 16 | C17: REGION 2 | D17: Cagayan | E17: Gattaran | F17: Centro Sur | G17: DR. TOMAS L. NOLASCO SR. MEMORIAL HOSPITAL - REPRODUCTIVE HEALTH CENTER | H17: Government | I17: LGU | J17: 10 | K17: Diagnostic X-Ray (Level 1), Pharmacy, Dialysis Clinic (4 Stations- B. Braun Avitum Philippines, Inc) | L17: Primary | M17: Dr. Cherry Ann A. Carreon | N17: (078) 395-0734 09275149145 | O17: dtnh_rhc@yahoo.com | R17: 46023 | S17: 46387 | T17: 02-08-26-I-1 | U17: Renewal | W17: Add ons Dialysis Clinic with 4 Stations (5/28/2026- 3rd Quarter) Delisting of Licensed Ambulance (3rd Quarter- 06/11/2026)
A18: 17 | C18: REGION 2 | D18: Cagayan | E18: Gattaran | F18: Calaoagan Dackel | G18: GATTARAN EMERGENCY HOSPITAL | H18: Government | I18: PROVINCE | J18: 10 | K18: Electrolytes (Na, K, Cl) Special Chemistry (AST, ALT)Special Serology (S. Typhi, Lestospira)Pharmacy | L18: Primary | M18: Dr. Cedina E. Bayani- OIC, Chief of Hospital | N18: 09270811967 (078) 377 6035 | O18: gattaranemergencyhospital@yahoo.com | P18: 1, type 1, Plate No. K1U 922 | R18: 46023 | S18: 46387 | T18: 02-23-26-I-1 | U18: Renewal | X18: *
A19: 18 | C19: REGION 2 | D19: Cagayan | E19: Sanchez-Mira | F19: Mahrlika Highway, San Andres | G19: NORTHERN CAGAYAN DISTRICT HOSPITAL | H19: Government | I19: PROVINCE | J19: 17 | K19: Pharmacy, Diagnostic X-ray (Level 1) | L19: Secondary | M19: Dr. Febe Q. Villanueva | N19: (078) 377-2563 09455995241 | O19: ncdh2015ssanchezmira@gmail.com | P19: 1/Type 1, C.S No. F5K 699 | R19: 46023 | S19: 46387 | T19: 02-27-26-I-1 | U19: Renewal | X19: *
A20: 19 | C20: REGION 2 | D20: Cagayan | E20: Sta. Ana | F20: Pines Drive, Centro | G20: STA. ANA COMMUNITY HOSPITAL | H20: Government | I20: PROVINCE | J20: 10 | K20: Pharmacy | L20: Primary | M20: Dr. Jacky O. Caday-OIC | N20: 09065260149 (078) 377 6568 | O20: sachospital@yahoo.com | Q20: Alfonso Ponce Enrile Memorial District Hospital | R20: 46023 | S20: 46387 | T20: 02-24-26-I-1 | U20: Renewal | X20: *
A21: 20 | C21: REGION 2 | D21: Isabela | E21: Alicia | F21: Magsaysay | G21: ALICIA COMMUNITY HOSPITAL | H21: Government | I21: LGU | J21: 8 | K21: Pharmacy, Diagnostic X-Ray (Level 1), Clinical Laboratory (Primary) | L21: Primary | M21: Dr. Ma. Consuelo L. Ricafort | N21: 09175032406 078-323-0903 | O21: aliciacommunityhospital@gmail.com | P21: 1, Type 1, Plate No. NAO 4139 | R21: 46023 | S21: 46387 | T21: 02-12-26-I-1 | U21: Renewal | W21: Change of Chief of Hospital (1st Quarter) | X21: *
A22: 21 | C22: REGION 2 | D22: Isabela | E22: Angadanan | F22: Centro 3 | G22: ANGADANAN INTEGRATED COMMUNITY HOSPITAL | H22: Government | I22: LGU | J22: 22 | M22: Dr. Princes Jeanne M. Cachapero | N22: 9363572513 | O22: aichospital@gmail.com | P22: 1, Type 1 / SNA 8272 | R22: 46023 | S22: 46387 | T22: 02-10-26-I-1 | U22: Renewal | V22: Increase Bed | X22: *
A23: 22 | C23: REGION 2 | D23: Isabela | E23: Delfin Albano | F23: Ragan Sur | G23: DELFIN ALBANO MEMORIAL HOSPITAL | H23: Government | I23: PROVINCE | J23: 10 | K23: Pharmacy, Clinical Laboratory (Primary) - Electrolytes (Na, K, Ca) - Special Chemistry ( HbA1c) - Thyroid Function ( fT3, fT4, TSH), Diagnostic X-ray (Level 2) , Pharmacy | L23: Primary | M23: Dr. Katrene Cay R. Acera | N23: 9171424236 | O23: damh_da@yahoo.com | P23: 1/Type 1/F4G 754 | R23: 46023 | S23: 46387 | T23: 02-34-26-I-1 | U23: Renewal | W23: Add ons: Pharmacy- 3/5/2026- 1st Quarter | X23: *
A24: 23 | C24: REGION 2 | D24: Isabela | E24: Dinapigue | F24: Digumased | G24: DINAPIGUE COMMUNITY HOSPITAL | H24: Government | I24: LGU | J24: 12 | K24: None | L24: None | M24: Dr. Floro M. Binalay | N24: 9082935214 | O24: liasonhospice@gmail.com | R24: 46125 | S24: 46387 | T24: 02-37-26-I-1 | U24: New Facility | W24: Initial LTO(4/13/2026)
A25: 24 | C25: REGION 2 | D25: Isabela | E25: Gamu | F25: Upi | G25: CAMP MELCHOR F. DELA CRUZ STATION HOSPITAL | H25: Government | I25: DND | J25: 30 | K25: Pharmacy, Diagnostic X-Ray (Level 1), Clinical Laboratory (Secondary) - Special Chemistry (HbA1c, cTn-I) - Thyroid Function (TSH, FT3, FT4) - Tumor Markers ( PSA) | L25: Secondary | M25: Col. Encarnita Oliva Perez | N25: 9950694515 | O25: cmfdc.sh@gmail.com | P25: 3/Type 1/Plate No. 130102, 131202 & 023101 | R25: 46023 | S25: 46387 | T25: 02-15-26-I-1 | U25: Renewal | V25: Changed Ownership/Mgt | X25: *
A26: 25 | C26: REGION 2 | D26: Isabela | E26: Ilagan City | F26: P7, Centro, San Antonio | G26: SAN ANTONIO CITY OF ILAGAN HOSPITAL | H26: Government | I26: LGU | J26: 10 | K26: Pharmacy,Diagnostic X-ray (Level 1) Clinical Laboratories Add ons: Special Serology (S. Typhi, HAV, CRP) Electrolytes (Ionized Caclcium) Special Chemistry (HbA1c, Trop-I, NT pro BNP) Thyroid Function Test(TSH, fT3,fT4) Tumor Markers (PSA, Covid-19 Testing Laboratory , Covid-19 Testing Laboratory | L26: Secondary | M26: Dr. Analynn J. Paguirigan | N26: 9552361000 | O26: sanantoniohospitalcityofilagan@gmail.com | Q26: Dr. Victor S. Villaroman Memorial Hospital | R26: 46023 | S26: 46387 | T26: 02-05-26-I-1 | U26: Renewal | V26: N/A | W26: Clinical Laboratory Add ons- ( 2nd Quarter- 4/7/2026) | X26: *
A27: 26 | C27: REGION 2 | D27: Isabela | E27: Jones | F27: Barangay 1 | G27: PROSPERO G. BELLO INTEGRATED COMMUNITY HOSPITAL | H27: Government | I27: LGU | J27: 10 | K27: Pharmacy,Diagnostic X-ray (Level 2), Clinical Laboratory: Special Chemistry (AST, ALT) Special Serology (HAV, S. typhi) | L27: Primary | M27: Dr. Regidor B. Delmas | N27: 9673000762 | O27: pgbich_jones@yahoo.com | P27: 1, Type 1, Plate No. : SBA 4183 | R27: 46023 | S27: 46387 | T27: 02-26-26-I-1 | U27: Renewal | X27: *
A28: 27 | C28: REGION 2 | D28: Isabela | E28: Palanan | F28: Dicabisagan West | G28: PALANAN STATION HOSPITAL | H28: Government | I28: PROVINCE | J28: 10 | K28: Pharmacy, Diagnostic X-ray (Level 1) | L28: Primary | M28: Dr. Gabriel Gonzales | N28: 9678393252 | O28: psh_palisa@yahoo.com | P28: 1, Type 1, Plate No. SCA 9354 | R28: 46023 | S28: 46387 | T28: 02-18-26-I-1 | U28: Renewal | W28: Ambulance Unit ( 2/18/2026- 1st Quarter) | X28: *
A29: 28 | C29: REGION 2 | D29: Isabela | E29: Quezon | F29: Arellano | G29: QUEZON COMMUNITY HOSPITAL | H29: Government | I29: LGU | J29: 15 | K29: Pharmacy, Diagnostic X-Ray (Level 1), Clinical Laboratory (Primary) Electrolytes (Na, K, Cl, iCa) Special Chemistry ( HbA1c, AST, ALT) Special Serology ( S. typhi) | L29: Primary | M29: Dr. Harold D. Rugnao | N29: 9172450034 | O29: qch_1994@yahoo.com | P29: 1/Type 1/F5U634 | R29: 46023 | S29: 46387 | T29: 02-25-26-I-1 | U29: Renewal | X29: *
A30: 29 | C30: REGION 2 | D30: Isabela | E30: Roxas | F30: National Highway, Muñoz East | G30: ROXAS COMMUNITY HOSPITAL | H30: Government | I30: LGU | J30: 17 | K30: Pharmacy | L30: Primary | M30: Dr. John G. Lago | N30: 9393068311 | O30: roxascommunityhospital@gmail.com | Q30: Roxas Rural Health Unit | R30: 46023 | S30: 46387 | T30: 02-28-26-I-1 | U30: Renewal | X30: *
A31: 30 | C31: REGION 2 | D31: Isabela | E31: San Mateo | F31: Roxas Street Corner Aglipay Street, Brgy. 4 | G31: SAN MATEO INTEGRATED COMMUNITY HOSPITAL | H31: Government | I31: LGU | J31: 24 | K31: Diagnostic X-ray (Level 1), Clnical Laboratory: Special Chemistry (HbA1c) Special Serology (HAV) Pharmacy | L31: Secondary | M31: Dr. Fevejoy S. Antalan | N31: 9976430483 | O31: smich0215@gmail.com | Q31: San Mateo Super Health Center | R31: 46023 | S31: 46387 | T31: 02-17-26-I-1 | U31: Renewal | V31: N/A | W31: Clinical Laboratory Add ons- 1st Quarter (2/13/2026) | X31: *
A32: 31 | C32: REGION 2 | D32: Isabela | E32: Sta. Maria | F32: Bliss Site, Poblacion I | G32: ELVIN U. MASIGAN INTEGRATED MEMORIAL HOSPITAL | H32: Government | I32: LGU | J32: 10 | K32: None | L32: Primary | M32: Dr. Bryan Julius T. Panganiban | N32: 9175771316 | O32: eumimh18@gmail.com | Q32: Milagros Albano District Hospital | R32: 46023 | S32: 46387 | T32: 02-22-26-I-1 | U32: Renewal | X32: *
A33: 32 | C33: REGION 2 | D33: Isabela | E33: Tumauini | F33: National Highway, Lingaling, | G33: TUMAUINI COMMUNITY HOSPITAL | H33: Government | I33: LGU | J33: 15 | K33: Dialysis Clinic (4 Stations) | L33: Limited Service | M33: Dr. Janeth J. Bacani | N33: 09178779824 (078) 323-2188 | O33: tumauinicommunityhospital@yahoo.com | P33: 1/Type 1/Plate No. 131209 | R33: 46023 | S33: 46387 | T33: 02-14-26-I-1 | U33: Renewal | X33: *
A34: 33 | C34: REGION 2 | D34: Nueva Vizcaya | E34: Alfonso Castañeda | F34: Purok 2, Lublub | G34: ALFONSO CASTAÑEDA MUNICIPAL HOSPITAL | H34: Government | I34: LGU | J34: 9 | K34: NONE | L34: NONE | M34: Dr. Annie C. Bawayan | N34: 9193295652 | O34: infirmarycastaneda@gmail.com | Q34: RHU Alfonso Castañeda | R34: 46023 | S34: 46387 | T34: 02-04-26-I-2 | U34: Renewal | X34: *
A35: 34 | C35: REGION 2 | D35: Nueva Vizcaya | E35: Diadi | F35: Poblacion | G35: DIADI EMERGENCY HOSPITAL | H35: Government | I35: PROVINCE | J35: 10 | K35: Pharmacy, Diagnostic X-ray (Level 1) | L35: Secondary | M35: Dr. Mary Jane C. Callang | N35: 9175676808 | O35: plgunuevavizcaya.deh@gmail.com | P35: 1/Type 1/POQ534 | R35: 46023 | S35: 46387 | T35: 02-09-26-I-1 | U35: Renewal | V35: N/A | X35: *
A36: 35 | C36: REGION 2 | D36: Nueva Vizcaya | E36: Kasibu | F36: Pimmadek | G36: DIDIPIO COMMUNITY HOSPITAL | H36: Government | I36: LGU | J36: 9 | K36: None | L36: None | M36: Dr. Joash Pio C. Ruiz | N36: 9671156897 | O36: didipiocommunityhospital2021@gmail.com | P36: 1, Type 1, Plate No. NHR 3931 | R36: 46023 | S36: 46387 | T36: 02-35-26-I-1 | U36: Renewal | X36: *
A37: 36 | C37: REGION 2 | D37: Nueva Vizcaya | E37: Kasibu | F37: Pudi | G37: KASIBU MUNICIPAL HOSPITAL | H37: Government | I37: PROVINCE | J37: 10 | K37: Pharmacy, Diagnostic X-ray (Level 2), Clinical Laboratory ( Secondary)- Special Serology ( S. typhi, Covid 19 Antigen Test) | L37: Secondary | M37: Dr. Lucena Larilay P. Caldito | N37: 9778302950 | O37: plgunuevavizcaya.kmh@gmail.com | P37: 1/Type 1/POM 515 | R37: 46023 | S37: 46387 | T37: 02-33-26-I-1 | U37: Renewal | W37: Clinical Laboratory ( Secondary)- Special Serology ( S. typhi, Covid 19 Antigen Test) - 6/16/2025 for 2nd Quarter | X37: *
A38: 37 | C38: REGION 2 | D38: Quirino | E38: Aglipay | F38: Villa Ventura | G38: AGLIPAY DISTRICT HOSPITAL | H38: Government | I38: PROVINCE | J38: 15 | K38: Pharmacy | L38: Secondary | M38: Dr. Sherwin Banan | N38: 9150493845 | O38: aglipaydistricthospital@gmail.com | P38: 1,Type 1/ SND 3303 | R38: 46023 | S38: 46387 | T38: 02-07-26-I-1 | U38: Renewal | X38: *
A39: 38 | C39: REGION 2 | D39: Quirino | E39: Diffun | F39: Andres Bonifacio | G39: DIFFUN DISTRICT HOSPITAL | H39: Government | I39: PROVINCE | J39: 23 | K39: Pharmacy, Diagnostic X-ray (Level 1) | L39: Secondary | M39: Dr. Maria Elizabeth T. Vaquilar | N39: 09973997140 (078) 692 8212 | O39: diffundisthospital@yahoo.com | Q39: Quirino Province Medical Center | R39: 46023 | S39: 46387 | T39: 02-06-26-I-1 | U39: Renewal | W39: Add ons Service( 4/20/2026- 2nd Quarter) | X39: *
A40: 39 | B40: 2983 | C40: REGION 3 | D40: Aurora | E40: Casiguran | F40: Brgy. Marikit, Casiguran | G40: CASIGURAN DISTRICT HOSPITAL | H40: Government | I40: PROVINCE | J40: 29 | K40: Dental Clinic Clinical Laboratory (Primary) ; Diagnostoc X-ray Level 1; Pharmacy | L40: Primary | M40: SWIT TARAH SABAOT, MD, CFP | N40: 9772697791 | O40: records.chd2015@gmail.com | P40: 2, Type I CR# 40432457-2 Conduction Sticker# F4 D063 Conduction Sticker No. F5 U725 | Q40: CASIGURAN DISTRICT HOSPITAL | R40: 46023 | S40: 46387 | T40: 03-0167-26-I-1 | U40: Renewal | V40: N/A
...

Sheet Private
A1: # | B1: NHFR CODE | C1: REGION | D1: PROVINCE | E1: CITY / MUNICIPALITY | F1: BLDG OR HOUSE NO., STREET, BRGY (as applicable) | G1: NAME OF FACILITY | H1: OWNERSHIP | I1: OWNERSHIP CLASSIFICATION (For Government Only) | J1: ABC | K1: ADD-ONS SERVICES | L1: CLINICAL LAB CLASSIFICATION (If Applicable) | M1: MEDICAL DIRECTOR / CHIEF OF HOSPITAL | N1: CONTACT NOS. | O1: E-MAIL ADDRESS | P1: AMBULANCE (No./ TYPE / PLATE NO.) Pls. Seperate if different Type | Q1: NAME OF AMBULANCE SERVICE PROVIDER IF W/ MOA | R1: VALIDITY FROM | S1: VALIDITY UNTIL | T1: LICENSE NO. | U1: APPLICATION STATUS | V1: APPLICATION STATUS (IF WITH CHANGES) | W1: REMARKS
A2: 1 | B2: 32062 | C2: REGION 1 | D2: Ilocos Norte | E2: Batac | F2: #35 Washington Street, Bil-loca | G2: BUMANGLAG SPECIALTY HOSPITAL | H2: Private | I2: N/A | J2: 5 | K2: Clinical Laboratory | L2: Secondary | M2: Castor B. Bumanglag, MD | N2: 077-617-1572/ 09198218626 | O2: bumanglagspecialtyhospital2012@gmail.com | Q2: Gaoat Hospital | R2: 46023 | S2: 46387 | T2: 01-0005-26-I-2 | U2: Renewal | V2: N/A | W2: Decrease ABC (From 11 to 5) | X2: *
A3: 2 | B3: 3297 | C3: REGION 1 | D3: Ilocos Norte | E3: Laoag | F3: Brgy. 7-As-Hernandez Avenue | G3: RANADA MEDICAL AND DIAGNOSTIC CENTER | H3: Private | I3: N/A | J3: 10 | M3: Joni L. Ranada-Camaquin, MD | N3: 077-770-5172/ 09167948718 | O3: ranada_antonio@yahoo.com.ph | Q3: Dr. Bonifacia Albano Memorial Hospital | R3: 46023 | S3: 46387 | T3: 01-0015-26-I-2 | U3: Renewal | V3: N/A | X3: *
A4: 3 | B4: 06746 | C4: REGION 1 | D4: Ilocos Norte | E4: Laoag City | F4: Balintawak St., Brgy. 9 , Sta. Angela | G4: RANADA GENERAL HOSPITAL | H4: Private | I4: N/A | J4: 15 | K4: Clinical Laboratory | L4: Secondary | M4: Vincent R. Bumatay, MD (New appointed OIC Med. Director-08-22-25) | N4: 077(770049-11)/ 09175702192 | O4: ranada_gen_hospital@yahoo.com | Q4: Laoag City General Hospital | R4: 46023 | S4: 46387 | T4: 01-0021-26-I-2 | U4: Renewal | V4: N/A | X4: *
A5: 4 | B5: 32066 | C5: REGION 1 | D5: Ilocos Norte | E5: Laoag City | F5: #64 Gomburza cor. Zacarias Flores Street, Barangay #6 San Agustin | G5: SAINT CAMILLUS DE LELLIS GENERAL HOSPITAL | H5: Private | I5: N/A | J5: 29 | K5: -Pharmacy -Clinical Laboratory Add on (6-16-2025) 1. Clinical Chemistry -HBAIC -Troponin I (Quantitative) -Alkaline Phosphate -Total Protein -Albumin -Ionized Calcium -Magnesium -Lipase -Amylase -UACR 2. Immunology/Serology -Anti-HAV, Anti HCV (Rapid Test Kits) -Ferritin -Estradiol -Anti Treponema Pallidum Rapid Test Kit -Salmonella Typhi Test Kit -NT-pro MBP, CK-MB -Thyroid Function Tests (TSH, FT3, FT4) -CRP, CEA 3. Others: Arterial Blood Gas | L5: Secondary | M5: Alan B. Taylan, MD, FPCP | N5: 077-770-5507/ 09159281605/ (077)-600-1125(Laboratory) | O5: saintcamillus_laoagcity@yahoo.com | Q5: Black Nazarene Hospital | R5: 46023 | S5: 46387 | T5: 01-0020-26-I-2 | U5: Renewal | V5: N/A | X5: *
A6: 5 | B6: 51370 | C6: REGION 1 | D6: Ilocos Norte | E6: Pagudpud | F6: Zamora St., Poblacion | G6: PAGUDPUD ADVENTIST WELLNESS CENTER | H6: Private | I6: N/A | J6: 27 | K6: -Pharmacy -Diagnostic X-Ray (Level 1) -Add-on Clinical Laboratory: 1. Clinical chemistry -CKMB -Troponin-I 2. Immunology/Serology -Thyroid Function Tests (TSH, FT4, FT3) -PSA, CRP | L6: Secondary | M6: Raymond B. Dabalos, MD | N6: 9457260383/ 09457200383 | O6: pagudpudawc@gmail.com | Q6: MOA with Pagudpud RHU | R6: 46023 | S6: 46387 | T6: 01-0011-26-I-2 | U6: Renewal | V6: N/A | X6: *
A7: 6 | B7: 37945 | C7: REGION 1 | D7: Ilocos Norte | E7: Pinili | F7: Manila Road, Barangay Apatut-Lubong | G7: KARMELLI CLINIC & HOSPITAL PINILI INC. | H7: Private | I7: N/A | J7: 10 | K7: -Pharmacy -X-Ray (level 1) -Clinical Laboratory Add on: 1. Clinical Chemistry --HBAIC 2. Immunology/Serology: --Thyroid Function Tests (TSH, FT4, FT3) --Troponin-I (Quantitative) PSA | L7: Secondary | M7: Norman Panfilo G. Rabago, MD, FPCP, MHCA | N7: 077-774-3227/ 09272674233/ 09454710481 (Laboratory) | O7: kchpi2016@gmail.com/ kchpilaboratory@gmail.com | Q7: Mariano Marcos Memorial Hospital and Medical Center | R7: 46023 | S7: 46387 | T7: 01-0001-26-I-2 | U7: Renewal | V7: N/A | X7: *
A8: 7 | B8: 00024 | C8: REGION 1 | D8: Ilocos Norte | E8: San Nicolas | F8: #100 Ventura Street, Barangay 15 San Jose | G8: GERTES CLINIC AND HOSPITAL | H8: Private | I8: N/A | J8: 10 | K8: -Clinical Laboratory Add on (07-29-2025): 1. Clinical Chem.: --HBAIC --Amylase --Troponin I 2. Immunology/Serology: --PSA --Typhi Dot | L8: Secondary | M8: Geminiano G. Gertes, MD | N8: 077-670-6438/ 09392464630 | O8: gertesclinicandhospital@yahoo.com | Q8: Black Nazarene Hospital | R8: 46023 | S8: 46387 | T8: 01-0004--26-I-2 | U8: Renewal | V8: N/A | X8: *
A9: 8 | C9: REGION 1 | D9: Ilocos Sur | E9: Narvacan | F9: Sitio, Limmansangan, Margaay | G9: HOLY NATIVITY MEDICAL CLINIC & INFIRMARY | H9: Private | I9: N/A | J9: 16 | K9: >Clinical Laboratory (05-05-2026) | L9: Secondary | M9: Karen S. Cabigas, MD | N9: 9668177962 | O9: holynativitymcandli@yahoo.com | P9: MOA | Q9: ISDH-Narvacan | R9: 46091 | S9: 46023 | T9: 01-0034-26-I-2 | U9: Initial with Changes | V9: Add-on Service | W9: Add on CL as OSS w/ updated LTO: May 05, 2026
A10: 9 | B10: 3958 | C10: REGION 1 | D10: Ilocos Sur | E10: Santo Domingo | F10: National Highway, San Pablo | G10: TOLENTINO CLINIC AND HOSPITAL | H10: Private | I10: N/A | J10: 10 | K10: -Diagnostic X-Ray (Level 2) -Clinical Laboratory Add on : 1. Clinical Chemistry: HBAIC | L10: Secondary | M10: Benjamin S. Tolentino Jr., MD | N10: 077-674-6122/ 09272710197 | O10: tolentinoclinic@gmail.com | Q10: Suero General Hospital | R10: 46023 | S10: 46387 | T10: 01-0022-26-I-2 | U10: Renewal | V10: N/A | X10: *
A11: 10 | B11: 04267 | C11: REGION 1 | D11: Ilocos Sur | E11: Sta. Maria | F11: Dakota Street, Poblacion Sur | G11: JUDGE CELESTINO GUERRERO MEMORIAL HOSPITAL | H11: Private | I11: N/A | J11: 8 | K11: -Pharmacy -Clinical Laboratory | L11: Secondary | M11: Mila P. Guerrero, MD | N11: 9262574986 | O11: guerrerohospital@yahoo.com.ph | Q11: Reyes - Ulep Hospital | R11: 46023 | S11: 46387 | T11: 01-0028-26-I-2 | U11: Renewal | V11: N/A | X11: *
A12: 11 | B12: 7055 | C12: REGION 1 | D12: Ilocos Sur | E12: Sta. Maria | F12: #4 Baliw Laud | G12: STO. NIÑO HOSPITAL | H12: Private | I12: N/A | J12: 18 | K12: -Diagnostic X-Ray (level 1) -Pharmacy -Clinical Laboratory -HIV Testing Lab | L12: Secondary | M12: Aurea Alicia Dagdag-Matias, MD | N12: 077-604-15-95/ 09454575960 | O12: draumatias@yahoo.com | Q12: Reyes - Ulep Hospital | R12: 46023 | S12: 46387 | T12: 01-0026-26-I-2 | U12: Renewal | V12: N/A | X12: *
A13: 12 | B13: 42881 | C13: REGION 1 | D13: Ilocos Sur | E13: Tagudin | F13: Mac Arthur Hi-way, Brgy. Lacong | G13: LACASANDILE MEDICAL CLINIC AND DIAGNOSTIC CENTER | H13: Private | I13: N/A | J13: 10 | K13: -Diagnostic X-Ray (Level 2) -Add-on Clinical Laboratory: 1. CC-HBAIC 2. Immunology/ Serology -Troponin I, -HAV,HCV, H. Pylori -Leptospira -T3, T4, TSH (08-15-2024) -HIV Testing Lab -RHIVda (02-16-24) | L13: Secondary | M13: Kareen Alna L. Lacasandile-Sanchez, MD | N13: 09062518009 | O13: lacasandilemcdc@gmail.com | R13: 46023 | S13: 46387 | T13: 01-0003-25-I-2 | U13: Renewal | V13: N/A | X13: *
A14: 13 | B14: 06558 | C14: REGION 1 | D14: Ilocos Sur | E14: Vigan City | F14: #59 Rizal Street, Barangay 7 | G14: RABARA CLINIC AND HOSPITAL | H14: Private | I14: N/A | J14: 10 | K14: -Diagnostic X-Ray (level 1) -Clinical Laboratory | L14: Secondary | M14: Charles Hubert R. Rabara, MD | N14: 077-632-0123/ 09176100279 | O14: allotrbr@yahoo.com / rabara.clinic@yahoo.com | Q14: Metro Vigan Hospital | R14: 46023 | S14: 46387 | T14: 01-0023-26-I-2 | U14: Renewal | V14: N/A | X14: *
A15: 14 | B15: 42866 | C15: REGION 1 | D15: La Union | E15: Agoo | F15: #138 Consolacion | G15: KOOP-MEDICAL CLINIC | H15: Private | I15: N/A | J15: 17 | K15: -Clinical Laboratory | L15: Secondary | M15: Allan John V. de Aquino, MD | N15: 072-206-4659/ 09129827211 | O15: koopmedicalcliniclumpc@gmail.com | P15: Type I/ PIate No.: IAE 3599 Cr No.: 453595671 | Q15: N/A | R15: 46023 | S15: 46387 | T15: 01-0019-26-I-2 | U15: Renewal | V15: N/A | X15: *
A16: 15 | B16: 06708 | C16: REGION 1 | D16: Pangasinan | E16: Balungao | F16: National Road, 40 Pugaro | G16: PROCARE MEDICAL CLINIC & INFIRMARY | H16: Private | I16: N/A | J16: 7 | K16: -Clinical Laboratory | L16: Primary | M16: Carmelita L. Ordoñez,MD | N16: 075-633-3650/ 09060218963 | O16: pcmch2015@gmail.com | Q16: Del Carmen Medical Clinic & Hospital | R16: 46023 | S16: 46387 | T16: 01-0013-26-I-2 | U16: Renewal | V16: N/A | X16: *
A17: 16 | B17: 6866 | C17: REGION 1 | D17: Pangasinan | E17: Binalonan | F17: Delos Reyes Street, Poblacion | G17: SABALLA-ROSARIO MEDICAL CLINIC | H17: Private | I17: N/A | J17: 15 | K17: -Clinical Laboratory | L17: Secondary | M17: Audrey Viduya, MD,CFP, MHA / Mr. Angel S. Rosario, Jr. | N17: 075-562-4375/ 09217947676 | O17: saballarosario.hospital@yahoo.com | Q17: Tayug Family Hospital | R17: 46023 | S17: 46387 | T17: 01-0014-26-I-2 | U17: Renewal | V17: N/A | X17: *
A18: 17 | B18: 2767 | C18: REGION 1 | D18: Pangasinan | E18: Bolinao | F18: Arosan Street, Germinal | G18: RILLERA MEDICAL HOSPITAL | H18: Private | I18: N/A | J18: 10 | K18: -Diagnostic X-ray (Level 1) -Clin Lab. Add-on (06-17-2025): 1. Immunology/Serology: --Thyroid Function Test (TSH, FT3, FT4) --PSA | L18: Secondary | M18: Fredelyn B. Rillera, MD | N18: 075-653-4787/ 09189376914 | O18: rmhbolinao@yahoo.com | Q18: Bolinao Community Hospital | R18: 46023 | S18: 46387 | T18: 01-0006-26-I-2 | U18: Renewal | V18: N/A | X18: *
A19: 18 | C19: REGION 1 | D19: Pangasinan | E19: Lingayen | F19: Avenida Rizal West | G19: STO. NIÑO DE CASIPIT GENERAL HOSPITAL | H19: Private | I19: N/A | J19: 18 | K19: >Diagnostic X-ray (Level 1) >Pharmacy | M19: Raymond Norman G. Casipit, MD | N19: 9662154473 | O19: stoninodecasipit81@gmail.com | P19: MOA | Q19: Luzon Medical center | R19: 46023 | S19: 46387 | T19: 01-0036-26-I-2 | U19: Initial with Changes | V19: Changed Ownership/Mgt
A20: 19 | B20: 32268 | C20: REGION 1 | D20: Pangasinan | E20: Manaoag | F20: Barangay Licsi | G20: SAINT CAMILLUS MATERNITY AND POLYCLINIC | H20: Private | I20: N/A | J20: 14 | K20: -Clinical Laboratory | L20: Secondary | M20: Jaime A. Roa, MD | N20: 075-529-1909/ 09491537570 | O20: st.camillusmanaoag@gmail.com | Q20: Medical Centrum Dagupan | R20: 46023 | S20: 46387 | T20: 01-0016-26-I-2 | U20: Renewal | V20: N/A | X20: *
A21: 20 | B21: 6861 | C21: REGION 1 | D21: Pangasinan | E21: Mangatarem | F21: #3 Mabini Street | G21: VELASQUEZ MEDICAL CLINIC AND HOSPITAL | H21: Private | I21: N/A | J21: 11 | K21: -Diagnostic X-Ray (level 1) -Clinical Laboratory | L21: Secondary | M21: Ronald C. Velasquez, MD | N21: 075-632-3316/ 09425755808 | O21: mackay_maricel@yahoo.com | Q21: Señor Sto Niño Hospital Inc. (Camiling Tarlac ) LTO # 03-0002-24-H2-2 | R21: 46023 | S21: 46387 | T21: 01-0024-26-I-2 | U21: Renewal | V21: N/A | X21: *
A22: 21 | B22: 51371 | C22: REGION 1 | D22: Pangasinan | E22: San Carlos City | F22: Binalonan, Pagal | G22: CHRIST-BEARER INFIRMARY | H22: Private | I22: N/A | J22: 18 | K22: -Pharmacy -Diagnostic X-ray (Level 1) -Clinical Laboratory Add-on (06-19-2025): 1. Clinical Chemistry: -HBAIC 2. Immunology/Serology: -Troponin-I -Thyroid Function Tests (FT3, FT4, TSH) | L22: Secondary | M22: Christopher A. Cancino, MD | N22: (075) 529-7181/ 09339161096 | O22: christbearerinfirmary@gmail.com | P22: Type I/ PIate No.: AOA7468 Cr No.: 0003117765 | Q22: N/A | R22: 46023 | S22: 46387 | T22: 01-0002-26-I-2 | U22: Renewal | V22: N/A | X22: *
A23: 22 | B23: 32269 | C23: REGION 1 | D23: Pangasinan | E23: San Quintin | F23: #54 Rizal Street, Zone II, Poblacion | G23: EL CORAZON DE JESUS MEDICAL & DIAGNOSTIC CLINIC | H23: Private | I23: N/A | J23: 6 | K23: -Clinical Laboratory | L23: Primary | M23: Gilda Medenilla, MD | N23: 9464687091 | O23: elcorazondejesus12@gmail.com | R23: 46023 | S23: 46387 | T23: 01-0018-26-I-2 | U23: Renewal | V23: N/A | X23: *
A24: 23 | C24: REGION 1 | D24: Pangasinan | E24: San Quintin | F24: Ramirez St., Pob. Zone I | G24: SAN QUINTIN POLYCLINIC AND LABORATORY | H24: Private | I24: N/A | J24: 8 | K24: >Clin. Lab. Additional services: 1.Clinical Chemistry: --HBAIC (05-28-2026) | L24: Secondary | M24: Roxanne R. Difuntorum, MD | N24: 9064615569 | O24: polyclinicandlaboratory@gmail.com | P24: MOA | Q24: Eastern Pangasinan District Hospital | R24: 46080 | S24: 46023 | T24: 01-0033-26-I-2 | U24: Initial with Changes | V24: Add-on Service | W24: Clin. Lab. Additional services: 1.Clinical Chemistry: --HBAIC w/ updated LTO: May 28, 2026
A25: 24 | B25: 38511 | C25: REGION 1 | D25: Pangasinan | E25: Urbiztondo | F25: 88 Rizal St., Poblacion | G25: JESUS HEALING HANDS INFIRMARY INC. | H25: Private | I25: N/A | J25: 12 | K25: -Diagnostic X-Ray (Level 1) -Clinical Laboratory | L25: Secondary | M25: Francis Therese E. Bachar, MD, FPCP, MHA | N25: 075-632-6085/ 09171940426/ 09989980239 | O25: jhhhospital@yahoo.com | Q25: Pangasinan Doctors Hospital | R25: 46023 | S25: 46387 | T25: 01-0027-26-I-2 | U25: Renewal | V25: N/A | X25: *
A26: 25 | B26: 2811 | C26: REGION 1 | D26: Pangasinan | E26: Villasis | F26: Zone V, Poblacion | G26: ORDOÑEZ MEDICAL HOSPITAL | H26: Private | I26: N/A | J26: 10 | K26: -Diagnostic X-Ray (level 1) -Clinical Laboratory | L26: Secondary | M26: Reynaldo Ordoñez, MD | N26: 075-632-1965/ 09178888323 | O26: ordonez.mike@yahoo.com | Q26: Del Carmen Medical Clinic & Hospital Inc. | R26: 46023 | S26: 46387 | T26: 01-0010-26-I-2 | U26: Renewal | V26: N/A | X26: *
A27: 26 | B27: 351 | C27: REGION 1 | D27: Pangasinan | E27: Villasis | F27: 088 Poblacion zone II, McArthur Highway, | G27: VILLASIS POLYMEDIC HOSPITAL AND TRAUMA HOSPITAL | H27: Private | I27: N/A | J27: 10 | K27: -Diagnostic X-Ray (level 1) | M27: Francisco L. Olivar, MD | N27: 75-564-388 | O27: vphtc@yahoo.com | Q27: Rosales Chua Pun Memorial Hospital | R27: 46023 | S27: 46387 | T27: 01-0025-26-I-2 | U27: Renewal | V27: N/A | X27: *
A28: 27 | C28: REGION 2 | D28: Isabela | E28: Cauayan City | F28: Rosemarie Reyes Street, Prenza | G28: CAUAYAN FAMILY HOSPITAL | H28: Private | I28: N/A | J28: 10 | K28: None | M28: Dr. Marlene C. Aquino | N28: 09328645759 (078) 652-2411 | O28: cfhmay2008@gmail.com | Q28: Isabela United Doctors Medical Center | R28: 46023 | S28: 46387 | T28: 02-03-26-I-2 | U28: Renewal
A29: 28 | C29: REGION 2 | D29: Isabela | E29: Cauayan City | F29: #109 Quezon Street, District 1 | G29: THE ROSS MAURICIO MEMORIAL HOSPITAL | H29: Private | I29: N/A | J29: 15 | K29: None | M29: Dr. Edwin B. Mauricio | N29: 9178971402 | O29: therossmauriciomh@yahoo.com | Q29: Cauayan Medical Specialists Hospital | R29: 46023 | S29: 46387 | T29: 02-02-26-I-2 | U29: Renewal
A30: 29 | C30: REGION 2 | D30: Isabela | E30: Delfin Albano | F30: Zone 6, San Antonio | G30: GAMBALAN HOSPITAL | H30: Private | I30: N/A | J30: 15 | K30: None | M30: Dr. Maximo C. Gambalan | N30: 09452598231 09178881835 | O30: gambalan.hospital@yahoo.com | P30: 1/Type 1/UAI 610 | R30: 46023 | S30: 46387 | T30: 02-30-26-I-2 | U30: Renewal
A31: 30 | C31: REGION 2 | D31: Isabela | E31: Ramon | F31: # 11 Bonifacio Steet, Bugallon Proper | G31: DEMANO'S MEDICAL AND PEDIATRIC CLINIC | H31: Private | I31: N/A | J31: 8 | K31: Pharmacy, Diagnostic X-Ray (Level 1),Clinical Laboratory (Primary) Electrolytes (Na, K, Cl, iCa) Special Chemistry (ALT) | L31: Primary | M31: Dr. Joyce M. Demano | N31: 09772784383 (078) 3253-263 | O31: demanoclinicramon@gmail.com | Q31: Tomas-Cacal Medical Clinic & Hospital | R31: 46023 | S31: 46387 | T31: 02-11-26-I-2 | U31: Renewal | W31: Additional Services (11/5/2025- 4th Quarter)
A32: 31 | C32: REGION 2 | D32: Isabela | E32: San Mateo | F32: National Highway, Barangay 3 | G32: JUVELO FAMILY CLINIC | H32: Private | I32: N/A | J32: 10 | K32: Pharmacy, Clinical Laboratory- Add ons: Electrolytes ( Na, K, Cl) Special Chemistry (AST, ALT, HbA1c) Tumor Markers ( PSA) | L32: Primary | M32: Dr. Melanio V. Lazaro | N32: (078) 323-1683 09266472110 | O32: juvelofamilyclinic@gmail.com | Q32: San Mateo Multicare Hospital, Inc. | R32: 46023 | S32: 46387 | T32: 02-13-26-I-2 | U32: Renewal
A33: 32 | C33: REGION 2 | D33: Isabela | E33: San Mateo | F33: Quirino Street, Barangay 3 | G33: SEVILLEJA MEDICAL CLINIC INC | H33: Private | I33: N/A | J33: 17 | K33: Pharmacy, Clinical Laboratory Add Ons: Special Chemistry (AST, ALT), Diagnostic X-ray (Level 1) | L33: Primary | M33: Dr. Ceasar L. Sevilleja | N33: 9179079027 | O33: sevillejamedicalclinic@gmail.com | P33: 1, Type 1, BAG 9950 | R33: 46023 | S33: 46387 | T33: 02-01-26-I-2 | U33: Renewal | W33: Initial Ambulance Unit (6/15/2026-3rd Quarter)
A34: 33 | C34: REGION 2 | D34: Isabela | E34: Tumauini | F34: #17 Laman Street, District 2 | G34: QUE MEDICAL CLINIC, LYING-IN AND PHARMACY | H34: Private | I34: N/A | J34: 15 | K34: Pharmacy, Electrolytes (Ionized Calcium) Special Serology (Typhidot) Thyroid Function Test (TSH, fT3, fT4) Tumor Markers (CEA, PSA) Special Chemistry (HbA1c, CK-MB) Special Serology (Typhidot, Trop I) | L34: Secondary | M34: Dr. Rizelle Marie A. Que- Daquioag OIC, Medical Director | N34: 09177747674 (078) 323-0309 | O34: quemedicalclinic@yahoo.com | Q34: Tumauini Community Hospital | R34: 46023 | S34: 46387 | T34: 02-32-26-I-2 | U34: Renewal | W34: Clinical Laboratory Add ons- Special Chemistry & Special Serology- 2/6/2026- 1st Quarter
A35: 34 | C35: REGION 2 | D35: Nueva Vizcaya | E35: Aritao | F35: Ozanam Village, Banganan | G35: INDIGENOUS PEOPLES' HOSPITAL FOUNDATION OF THE DIOCESE OF BAYOMBONG, INC. | H35: Private | I35: N/A | J35: 15 | K35: Diagnostic X-ray (Level 2), Pharmacy | L35: Secondary | M35: Dr. Karen Cecille T. Tambuyat | N35: (078) 362 8791 09171698762 | O35: indigenouspeopleshospital17@gmail.com | Q35: Aritao Rural Health Unit | R35: 46023 | S35: 46387 | T35: 02-29-26-I-2 | U35: Renewal
A36: 35 | B36: 4238 | C36: REGION 3 | D36: Bataan | E36: Dinalupihan | F36: #13 Rizal St., Sta. Isabel | G36: STO. ROSARIO MATERNITY AND MEDICAL CLINIC | H36: Private | I36: N/A | J36: 8 | M36: Dr. Graciella Celia A. Roxas | N36: (047) 6361618 (047) 6361379 | O36: storosario_clinic@yahoo.com | Q36: Jose Payumo Memorial Hospital | R36: 46023 | S36: 46387 | T36: 03-0219-26-I-2 | U36: Renewal | V36: N/A
A37: 36 | B37: 1875 | C37: REGION 3 | D37: Bulacan | E37: Balagtas | F37: #255 Burol 2nd, | G37: GUBATAN MEDICAL CLINIC | H37: Private | I37: N/A | J37: 14 | K37: Clinical Laboratory Diagnostic Xray Level 1 | L37: Secondary | M37: Dr. Carlos R. Gubatan, Jr. | N37: (044) 8168648 09177007347 | O37: gubatanmedicalclinic92@yahoo.com | Q37: United Balagtas Doctors Hospital Corporation | R37: 46023 | S37: 46387 | T37: 03-0099-26-I-2 | U37: Renewal | V37: N/A
A38: 37 | B38: 43738 | C38: REGION 3 | D38: Bulacan | E38: Bulakan | F38: #71 Malusak Street, Sta. Ana, | G38: OUR LADY OF THE ASSUMPTION HOSPITAL OPC | H38: Private | I38: N/A | J38: 3 | M38: Dr. Barbara A. Gatiera | N38: (044)792-0084 0917-871-9290 | O38: olahosp2021@gmail.com | Q38: Santos General Hospital of Malolos, Inc. | R38: 46023 | S38: 46387 | T38: 03-0152-26-I-2 | U38: Renewal | V38: N/A
